Workbook

Sheet Guide
B2: DULUX – SALES CHANNEL KPI & INCENTIVE TRACKER 2026
B3: Target → Phasing theo tuần → Actual → Performance tracking → Incentive
B5: 1. BỘ KPI ĐANG ÁP DỤNG
B6: LEAD KPI – 70% – review & trả theo QUÝ | C6: Invoiced Value 50% + Key account approach / Site check 20%. Hai chỉ số đo được thường xuyên để các bạn chạy và review hàng tuần/hàng quý.
B7: FOCUS KPI – 30% – chốt & trả CUỐI NĂM | C7: Spec-in Value 15% + Engaged Architect (Submit Design) 15%.
B8: Spec-in Design – theo dõi, weight 0% | C8: Số design nộp là chỉ số dẫn dắt của Spec-in Value (~50 MVND/design). Vẫn phase & track như 4 KPI kia nhưng chưa tính điểm – nếu quyết định tính điểm thì chỉ cần gõ weight vào KPI_Framework!F10 và chia lại 4 KPI còn lại cho tổng = 100%.
B10: 2. QUY TRÌNH SỬ DỤNG / HOW TO USE
B11: Bước 1 – Parameters | C11: Điền tên kênh, quý đang chốt. Chốt tỷ trọng Lead/Focus, đường trả thưởng (threshold–target–cap), pass gate, danh sách region.
B12: Bước 2 – KPI_Framework | C12: Chốt 5 KPI và weight. Tổng weight phải = 100% (ô kiểm tra sẽ báo đỏ nếu lệch).
B13: Bước 3 – Team_Master | C13: Nhập nhân sự: mã NV, team, region, line manager, area, số tháng hưởng, ATVP (quỹ thưởng mục tiêu cả năm).
B14: Bước 4 – Target_FY | C14: Nhập FY Target chính thức của từng người cho từng KPI (cột G). Ví dụ: Site check 215 roadshow, Engaged architect 80 D&B, Spec-in design 85, Spec-in value 4,250 MVND.
B15: Bước 5 – Weekly_Tracker ⭐ | C15: SHEET NHẬP LIỆU DUY NHẤT. Mỗi người 5 KPI × 3 dòng (Phasing / Actual / % Achieved), 12 tháng × 5 tuần. Phase target xuống từng tuần, hàng tuần điền Actual. Cột 'Check' ở Target_FY báo ngay nếu phasing cộng lại chưa khớp FY target.
B16: Bước 6 – Target_FY & Actual_Monthly | C16: Tự động: gom tuần → tháng → quý → luỹ kế YTD. Không nhập tay.
B17: Bước 7 – Tracking | C17: Tự động: achievement luỹ kế theo quý, payout factor từng KPI, Lead factor, Focus factor, pass gate, trạng thái RAG.
B18: Bước 8 – Incentive_Calc | C18: Tự động: tiền Lead trả từng quý + Focus trả cuối năm + tổng FY của từng người.
B19: Bước 9 – Dashboard | C19: Toàn kênh / theo region / theo từng người tại quý chọn ở Parameters!C7.
B21: 3. QUY TẮC TÍNH / CALCULATION RULES
B22: Lead KPI – 70% | C22: Đo LUỸ KẾ theo quý (Q3 = Jan–Sep). Tiền quý n = Lead pot × n/4 × factor luỹ kế đến quý n − số đã trả các quý trước.
B23: Focus KPI – 30% | C23: Đo luỹ kế cả năm, trả 1 lần sau khi chốt Q4, tối đa 150%.
B24: Payout curve | C24: < 80% → 0%. 80% → 50%. 100% → 100%. ≥ 120% → 150% (trần). Nội suy tuyến tính giữa các mốc. Sửa mốc tại Parameters mục C.
B25: Pass gate | C25: Kết quả Focus KPI khoá tiền Lead KPI: Focus ≥100% mở 100%; ≥90% mở 90%; ≥80% mở 80%; <80% không trả. Bật/tắt tại Parameters!C23.
B26: Prorate | C26: Người vào/ra giữa năm: điền số tháng hưởng ở Team_Master cột K, ATVP tự prorate.
B28: 4. QUY ƯỚC MÀU / COLOR LEGEND
B29: Chữ XANH DƯƠNG trên nền vàng nhạt | C29: Ô NHẬP LIỆU – chỉ gõ vào các ô này (Weekly_Tracker, Target_FY cột G, Team_Master, Parameters).
B30: Chữ ĐEN | C30: Công thức – không sửa.
B31: Chữ XANH LÁ | C31: Lấy từ sheet khác – không sửa.
B32: Nền xanh nhạt / vàng nhạt / xám | C32: Nhóm Lead KPI · nhóm Focus KPI · KPI chỉ theo dõi.
B34: 5. ĐIỂM CẦN CHỐT VỚI HR / BU
B35: a. KPI thứ 5 có tính điểm không? | C35: Hiện Spec-in Design để weight 0%. Nếu chốt tính điểm cho đủ 5 mục thì chia lại weight (VD Focus 30% = Spec-in value 10% + Engaged 10% + Design 10%).
B36: b. Payout tại ngưỡng 80% | C36: Đang giả định 50%. File Product Consultant chỉ ghi performance range 80–120, không ghi mức trả tại 80%.
B37: c. Hai bậc giữa của pass gate | C37: File mẫu chỉ ghi ≥100% trả 100% và <80% trả 0%; mức 90% và 80% đang giả định 90%/80%.
B38: d. Định nghĩa Site check hợp lệ | C38: Cần chốt: thế nào là 1 roadshow/site check được tính (check-in trên app? có biên bản? tối thiểu bao nhiêu phút?).
B39: e. Định nghĩa Engaged Architect | C39: Tính theo tài khoản KTS duy nhất/năm hay theo lượt submit? Điều kiện ghi nhận trên CRM.
B40: f. Spec-in Value | C40: Ghi nhận lúc spec-in hay lúc convert ra đơn? Xử lý thế nào khi dự án rớt?
B41: g. ATVP từng người | C41: Do HR cấp – file đang để số minh hoạ.
B42: h. Clawback | C42: Mặc định KHÔNG thu hồi khi quý sau tụt (Parameters!C31 = N).
B44: 6. DỮ LIỆU MẪU
B45: 6 nhân sự mẫu (SE-001…SE-006) | C45: Phasing cả năm + Actual Jan–Sep là SỐ MINH HOẠ. Xoá trước khi dùng thật: xoá dòng 6–11 ở Team_Master, xoá vùng tuần ở Weekly_Tracker và cột G ở Target_FY.
B46: Không chèn/xoá dòng giữa bảng | C46: Target_FY / Actual_Monthly / Weekly_Tracker / Tracking / Incentive_Calc khớp dòng theo đúng thứ tự Team_Master. Template có sẵn 15 slot nhân sự.
B48: Version 2.0 · 2026-09-17 · bộ KPI: Invoiced Value / Site check / Spec-in Value / Engaged Architect / Spec-in Design

Sheet Parameters
B2: PARAMETERS / THÔNG SỐ ĐIỀU KHIỂN
B3: Tất cả sheet khác lấy thông số từ đây. Chỉ sửa ô màu vàng.
B5: A. THÔNG TIN CHUNG / GENERAL
B6: Sales channel / Tên kênh | C6: Dulux – <điền tên kênh> | D6: VD: Project / Specification channel.
B7: Quý đang chốt (1–4) / Reporting quarter | C7: 3 | D7: Dashboard hiển thị luỹ kế đến quý này.
B8: Đơn vị tiền / Currency unit | C8: MVND | D8: Triệu đồng – giữ nhất quán mọi sheet.
B9: B. CHIA TỶ TRỌNG THƯỞNG / VARIABLE PAY SPLIT
B10: Lead KPI share – trả theo QUÝ | C10: 0.7
B11: Focus KPI share – trả theo NĂM | C11: 0.3
B12: Check = 100% | C12: =C10+C11 | D12: =IF(ROUND(C10+C11,6)=1,"OK","LỖI: tổng phải = 100%")
B13: C. ĐƯỜNG TRẢ THƯỞNG / PAYOUT CURVE
B14: Mốc / Point | C14: Giá trị | D14: Ghi chú
B15: Threshold achievement (dưới mức này = 0đ) | C15: 0.8 | D15: Performance range 80–120 theo file mẫu.
B16: Payout tại threshold | C16: 0.5 | D16: GIẢ ĐỊNH – cần HR xác nhận.
B17: Target achievement | C17: 1
B18: Payout tại target | C18: 1
B19: Max achievement (cap) | C19: 1.2
B20: Payout tại cap | C20: 1.5 | D20: Trần 150% theo ghi chú file mẫu.
B21: Giữa các mốc: nội suy tuyến tính. Trên cap: giữ nguyên mức cap.
B22: D. PASS GATE – Focus KPI khoá tiền Lead KPI
B23: Gate ON / OFF | C23: ON | D23: OFF = trả đủ Lead KPI, bỏ qua gate.
B24: Focus KPI achievement ≥ | C24: % tiền Lead được trả | D24: Ghi chú
B25: 1 | C25: 1 | D25: Theo file mẫu: ≥100% → trả 100%.
B26: 0.9 | C26: 0.9 | D26: GIẢ ĐỊNH – cần chốt.
B27: 0.8 | C27: 0.8 | D27: GIẢ ĐỊNH – cần chốt.
B28: < 80% | C28: 0 | D28: Theo file mẫu: <80% → trả 0%.
B29: E. TRUE-UP / CLAWBACK
B30: Cơ chế luỹ kế: tiền quý = số hưởng luỹ kế − số đã trả.
B31: Cho phép true-up âm (thu hồi) Y/N | C31: N | D31: N = quý tụt thì trả 0, không thu hồi.
B32: F. DANH SÁCH REGION / REGION LIST
B33: HA NOI | D33: Sửa/thêm region tại B33:B40 – Dashboard đọc đúng danh sách này.
B34: HCMC
B35: NORTH
B36: NCENT
B37: SCENT
B38: HCMEX
B39: MEKONG
B41: G. LỊCH QUÝ / THÁNG / TUẦN
B42: Q1 = Jan–Mar · Q2 = Apr–Jun · Q3 = Jul–Sep · Q4 = Oct–Dec | D42: Weekly_Tracker: mỗi tháng có 5 ô tuần (W1–W5); tháng chỉ có 4 tuần thì để trống W5.

Sheet KPI_Framework
B2: 2026 KPIs OF SALES FORCE INCENTIVE – <TÊN KÊNH> – FY2026
B3: Tracking / Incentive đọc weight trực tiếp từ cột Weight bên dưới. Sửa weight ở đây là cả file đổi theo.
B5: KPI code | C5: KPI (EN) | D5: Tên KPI (VN) | E5: Group | F5: Weight | G5: Weight in group | H5: Measurement frequency | I5: Payout | J5: Unit | K5: Data source | L5: Định nghĩa / Definition
B6: K1 | C6: Invoiced Value | D6: Doanh số xuất hoá đơn | E6: Lead | F6: 0.5 | G6: =IFERROR(F6/SUMIF($E$6:$E$10,E6,$F$6:$F$10),0) | H6: Quarterly cumulative | I6: Quarterly | J6: MVND | K6: DERP / Invoice report | L6: Giá trị hoá đơn thực xuất cho khách hàng / dự án thuộc danh sách phụ trách.
B7: K2 | C7: Key account approach / Site check | D7: Site check – tiếp cận key account | E7: Lead | F7: 0.2 | G7: =IFERROR(F7/SUMIF($E$6:$E$10,E7,$F$6:$F$10),0) | H7: Quarterly cumulative | I7: Quarterly | J7: Roadshow | K7: Mini Sales app / CRM | L7: Số lượt roadshow / site check hợp lệ (có check-in, có biên bản trên app).
B8: K3 | C8: Spec-in Value | D8: Giá trị dự án được chỉ định | E8: Focus | F8: 0.15 | G8: =IFERROR(F8/SUMIF($E$6:$E$10,E8,$F$6:$F$10),0) | H8: Yearly cumulative | I8: Annual | J8: MVND | K8: CRM | L8: Giá trị dự án Dulux được spec-in trong năm (chuẩn ~50 MVND / design).
B9: K4 | C9: Engaged Architect (Submit Design) | D9: Kiến trúc sư engaged (nộp design) | E9: Focus | F9: 0.15 | G9: =IFERROR(F9/SUMIF($E$6:$E$10,E9,$F$6:$F$10),0) | H9: Yearly cumulative | I9: Annual | J9: D&B | K9: CRM | L9: Số KTS/nhà thầu D&B engaged – tính theo tài khoản duy nhất có submit design trong năm.
B10: K5 | C10: Spec-in Design (submitted design) | D10: Số design được nộp | E10: Tracking | F10: 0 | G10: =IFERROR(F10/SUMIF($E$6:$E$10,E10,$F$6:$F$10),0) | H10: Yearly cumulative | I10: n/a | J10: Designs | K10: CRM | L10: Chỉ số dẫn dắt của K3 (design x 50 MVND). Weight 0 – chỉ theo dõi, chưa tính điểm.
E11: TOTAL | F11: =SUM(F6:F10) | H11: =IF(ROUND(SUM(F6:F10),6)=1,"OK – tổng weight = 100%","LỖI: tổng weight phải = 100%")
E12: Lead group | F12: =SUMIF($E$6:$E$10,"Lead",$F$6:$F$10) | H12: =IF(ROUND(F12,6)=ROUND(Parameters!$C$10,6),"OK – khớp Parameters","LỆCH so với Parameters!C10")
E13: Focus group | F13: =SUMIF($E$6:$E$10,"Focus",$F$6:$F$10) | H13: =IF(ROUND(F13,6)=ROUND(Parameters!$C$11,6),"OK – khớp Parameters","LỆCH so với Parameters!C11")
B15: */ Lead KPIs: đo luỹ kế theo quý, trả thưởng hàng quý, cap 150%.
B16: */ Focus KPIs: đo luỹ kế cả năm, trả 1 lần cuối năm, tối đa 150%.
B17: */ Pass gate: Focus KPI quyết định % tiền Lead KPI được giải ngân (Parameters mục D).
B18: */ K5 Spec-in Design weight 0% – chỉ theo dõi. Muốn tính điểm: gõ weight vào F10 và chia lại F6:F9 cho tổng = 100%.
B19: */ Điều kiện ghi nhận: tên & mã nhân viên phải khớp giữa DERP / CRM / Mini Sales app.

Sheet Team_Master
B2: TEAM MASTER – DANH SÁCH NHÂN SỰ & QUỸ THƯỞNG
B3: Nhập từ cột Emp Code đến ATVP. Thứ tự dòng ở đây quyết định thứ tự khối của mọi sheet khác – KHÔNG chèn/xoá dòng giữa bảng, chỉ ghi đè hoặc xoá nội dung.
B5: No | C5: Emp Code | D5: Team | E5: Region | F5: Line Manager | G5: Name of Sales Person | H5: Area | I5: Role | J5: Status | K5: Eligible months (0–12) | L5: ATVP full year | M5: ATVP prorated | N5: Lead pot (70%) | O5: Focus pot (30%) | P5: Note
B6: =IF($C6="","",ROW()-5) | C6: SE-001 | D6: SPEC | E6: HA NOI | F6: Nguyen Thi Lan | G6: HUNG | H6: Ha Noi 1 | I6: Sales Executive | J6: Active | K6: 12 | L6: 120 | M6: =IF($C6="","",L6*MIN(K6,12)/12) | N6: =IF($C6="","",M6*Parameters!$C$10) | O6: =IF($C6="","",M6*Parameters!$C$11) | P6: SAMPLE – xoá trước khi dùng thật
B7: =IF($C7="","",ROW()-5) | C7: SE-002 | D7: SPEC | E7: HA NOI | F7: Nguyen Thi Lan | G7: DUY | H7: Ha Noi 2 | I7: Sales Executive | J7: Active | K7: 12 | L7: 120 | M7: =IF($C7="","",L7*MIN(K7,12)/12) | N7: =IF($C7="","",M7*Parameters!$C$10) | O7: =IF($C7="","",M7*Parameters!$C$11) | P7: SAMPLE – xoá trước khi dùng thật
B8: =IF($C8="","",ROW()-5) | C8: SE-003 | D8: SPEC | E8: HCMC | F8: Tran Quang Minh | G8: QUYEN | H8: HCMC 1 | I8: Sales Executive | J8: Active | K8: 12 | L8: 130 | M8: =IF($C8="","",L8*MIN(K8,12)/12) | N8: =IF($C8="","",M8*Parameters!$C$10) | O8: =IF($C8="","",M8*Parameters!$C$11) | P8: SAMPLE – xoá trước khi dùng thật
B9: =IF($C9="","",ROW()-5) | C9: SE-004 | D9: SPEC | E9: HCMC | F9: Tran Quang Minh | G9: Pham Minh Chau | H9: HCMC 2 | I9: Sales Executive | J9: Active | K9: 12 | L9: 130 | M9: =IF($C9="","",L9*MIN(K9,12)/12) | N9: =IF($C9="","",M9*Parameters!$C$10) | O9: =IF($C9="","",M9*Parameters!$C$11) | P9: SAMPLE – xoá trước khi dùng thật
B10: =IF($C10="","",ROW()-5) | C10: SE-005 | D10: SPEC | E10: NORTH | F10: Nguyen Thi Lan | G10: Vo Thi Em | H10: Bac Ninh | I10: Sales Supervisor | J10: Active | K10: 12 | L10: 110 | M10: =IF($C10="","",L10*MIN(K10,12)/12) | N10: =IF($C10="","",M10*Parameters!$C$10) | O10: =IF($C10="","",M10*Parameters!$C$11) | P10: SAMPLE – xoá trước khi dùng thật
B11: =IF($C11="","",ROW()-5) | C11: SE-006 | D11: SPEC | E11: MEKONG | F11: Tran Quang Minh | G11: Ngo Van Phuc | H11: Can Tho | I11: Sales Executive | J11: Active | K11: 12 | L11: 110 | M11: =IF($C11="","",L11*MIN(K11,12)/12) | N11: =IF($C11="","",M11*Parameters!$C$10) | O11: =IF($C11="","",M11*Parameters!$C$11) | P11: SAMPLE – xoá trước khi dùng thật
B12: =IF($C12="","",ROW()-5) | K12: 12 | M12: =IF($C12="","",L12*MIN(K12,12)/12) | N12: =IF($C12="","",M12*Parameters!$C$10) | O12: =IF($C12="","",M12*Parameters!$C$11)
B13: =IF($C13="","",ROW()-5) | K13: 12 | M13: =IF($C13="","",L13*MIN(K13,12)/12) | N13: =IF($C13="","",M13*Parameters!$C$10) | O13: =IF($C13="","",M13*Parameters!$C$11)
B14: =IF($C14="","",ROW()-5) | K14: 12 | M14: =IF($C14="","",L14*MIN(K14,12)/12) | N14: =IF($C14="","",M14*Parameters!$C$10) | O14: =IF($C14="","",M14*Parameters!$C$11)
B15: =IF($C15="","",ROW()-5) | K15: 12 | M15: =IF($C15="","",L15*MIN(K15,12)/12) | N15: =IF($C15="","",M15*Parameters!$C$10) | O15: =IF($C15="","",M15*Parameters!$C$11)
B16: =IF($C16="","",ROW()-5) | K16: 12 | M16: =IF($C16="","",L16*MIN(K16,12)/12) | N16: =IF($C16="","",M16*Parameters!$C$10) | O16: =IF($C16="","",M16*Parameters!$C$11)
B17: =IF($C17="","",ROW()-5) | K17: 12 | M17: =IF($C17="","",L17*MIN(K17,12)/12) | N17: =IF($C17="","",M17*Parameters!$C$10) | O17: =IF($C17="","",M17*Parameters!$C$11)
B18: =IF($C18="","",ROW()-5) | K18: 12 | M18: =IF($C18="","",L18*MIN(K18,12)/12) | N18: =IF($C18="","",M18*Parameters!$C$10) | O18: =IF($C18="","",M18*Parameters!$C$11)
B19: =IF($C19="","",ROW()-5) | K19: 12 | M19: =IF($C19="","",L19*MIN(K19,12)/12) | N19: =IF($C19="","",M19*Parameters!$C$10) | O19: =IF($C19="","",M19*Parameters!$C$11)
B20: =IF($C20="","",ROW()-5) | K20: 12 | M20: =IF($C20="","",L20*MIN(K20,12)/12) | N20: =IF($C20="","",M20*Parameters!$C$10) | O20: =IF($C20="","",M20*Parameters!$C$11)
K21: TOTAL | L21: =SUM(L6:L20) | M21: =SUM(M6:M20) | N21: =SUM(N6:N20) | O21: =SUM(O6:O20)
B23: ATVP = Annual Target Variable Pay (quỹ thưởng mục tiêu cả năm của 1 người, do HR cấp), đơn vị theo Parameters!C8.

Sheet Weekly_Tracker
B2: WEEKLY TRACKER – PHASING / ACTUAL / % ACHIEVED (sheet nhập liệu chính)
A3: Mỗi người 5 KPI × 3 dòng. Gõ Phasing cả năm 1 lần, hàng tuần gõ Actual. Tháng nào chỉ có 4 tuần thì để trống cột W5. Mọi sheet khác tự gom từ đây.
A4: THÔNG TIN / ID | H4: Jan | M4: Feb | R4: Mar | W4: Apr | AB4: May | AG4: Jun | AL4: Jul | AQ4: Aug | AV4: Sep | BA4: Oct | BF4: Nov | BK4: Dec
A5: Emp Code | B5: Name | C5: KPI | D5: KPI name | E5: Unit | F5: Phasing / Actual | G5: FY total | H5: W1 | I5: W2 | J5: W3 | K5: W4 | L5: W5 | M5: W1 | N5: W2 | O5: W3 | P5: W4 | Q5: W5 | R5: W1 | S5: W2 | T5: W3 | U5: W4 | V5: W5 | W5: W1 | X5: W2 | Y5: W3 | Z5: W4 | AA5: W5 | AB5: W1 | AC5: W2 | AD5: W3 | AE5: W4 | AF5: W5 | AG5: W1 | AH5: W2 | AI5: W3 | AJ5: W4 | AK5: W5 | AL5: W1 | AM5: W2 | AN5: W3 | AO5: W4 | AP5: W5 | AQ5: W1 | AR5: W2 | AS5: W3 | AT5: W4 | AU5: W5 | AV5: W1 | AW5: W2 | AX5: W3 | AY5: W4 | AZ5: W5 | BA5: W1 | BB5: W2 | BC5: W3 | BD5: W4 | BE5: W5 | BF5: W1 | BG5: W2 | BH5: W3 | BI5: W4 | BJ5: W5 | BK5: W1 | BL5: W2 | BM5: W3 | BN5: W4 | BO5: W5
A6: =IFERROR(INDEX(Team_Master!$C$6:$C$20,1),"") | B6: =IFERROR(INDEX(Team_Master!$G$6:$G$20,1),"") | C6: K1 | D6: Invoiced Value | E6: MVND | F6: Phasing | G6: =SUM(H6:BO6) | H6: 212 | I6: 212 | J6: 212 | K6: 214 | M6: 155 | N6: 155 | O6: 155 | P6: 155 | R6: 237 | S6: 237 | T6: 237 | U6: 239 | W6: 250 | X6: 250 | Y6: 250 | Z6: 250 | AB6: 255 | AC6: 255 | AD6: 255 | AE6: 255 | AG6: 262 | AH6: 262 | AI6: 262 | AJ6: 264 | AL6: 250 | AM6: 250 | AN6: 250 | AO6: 250 | AQ6: 257 | AR6: 257 | AS6: 257 | AT6: 259 | AV6: 270 | AW6: 270 | AX6: 270 | AY6: 270 | BA6: 280 | BB6: 280 | BC6: 280 | BD6: 280 | BF6: 287 | BG6: 287 | BH6: 287 | BI6: 289 | BK6: 282 | BL6: 282 | BM6: 282 | BN6: 284
F7: Actual | G7: =SUM(H7:BO7) | H7: 215 | I7: 223 | J7: 252 | K7: 218 | M7: 160 | N7: 165 | O7: 142 | P7: 160 | R7: 256 | S7: 270 | T7: 208 | U7: 229 | W7: 220 | X7: 286 | Y7: 275 | Z7: 215 | AB7: 308 | AC7: 307 | AD7: 277 | AE7: 274 | AG7: 237 | AH7: 223 | AI7: 273 | AJ7: 229 | AL7: 229 | AM7: 234 | AN7: 214 | AO7: 254 | AQ7: 259 | AR7: 297 | AS7: 267 | AT7: 280 | AV7: 278 | AW7: 294 | AX7: 274 | AY7: 256
F8: % Achieved | G8: =IFERROR(G7/G6,"") | H8: =IFERROR(H7/H6,"") | I8: =IFERROR(I7/I6,"") | J8: =IFERROR(J7/J6,"") | K8: =IFERROR(K7/K6,"") | L8: =IFERROR(L7/L6,"") | M8: =IFERROR(M7/M6,"") | N8: =IFERROR(N7/N6,"") | ... BO8: =IFERROR(BO7/BO6,"")
C9: K2 | D9: Key account approach / Site check | E9: Roadshow | F9: Phasing | G9: =SUM(H9:BO9) | H9: 3 | I9: 3 | J9: 3 | K9: 6 | M9: 2 | N9: 2 | O9: 2 | P9: 5 | R9: 4 | S9: 4 | T9: 4 | U9: 5 | W9: 4 | X9: 4 | Y9: 4 | Z9: 6 | AB9: 4 | AC9: 4 | AD9: 4 | AE9: 6 | AG9: 4 | AH9: 4 | AI9: 4 | AJ9: 7 | AL9: 4 | AM9: 4 | AN9: 4 | AO9: 6 | AQ9: 4 | AR9: 4 | AS9: 4 | AT9: 6 | AV9: 4 | AW9: 4 | AX9: 4 | AY9: 7 | BA9: 5 | BB9: 5 | BC9: 5 | BD9: 5 | BF9: 5 | BG9: 5 | BH9: 5 | BI9: 6 | BK9: 5 | BL9: 5 | BM9: 5 | BN9: 6
F10: Actual | G10: =SUM(H10:BO10) | H10: 4 | I10: 4 | J10: 3 | K10: 7 | M10: 2 | N10: 2 | O10: 2 | P10: 4 | R10: 5 | S10: 4 | T10: 5 | U10: 5 | W10: 5 | X10: 5 | Y10: 3 | Z10: 6 | AB10: 5 | AC10: 4 | AD10: 5 | AE10: 6 | AG10: 3 | AH10: 4 | AI10: 5 | AJ10: 7 | AL10: 4 | AM10: 4 | AN10: 5 | AO10: 7 | AQ10: 4 | AR10: 4 | AS10: 4 | AT10: 5 | AV10: 5 | AW10: 4 | AX10: 4 | AY10: 7
F11: % Achieved | G11: =IFERROR(G10/G9,"") | H11: =IFERROR(H10/H9,"") | I11: =IFERROR(I10/I9,"") | J11: =IFERROR(J10/J9,"") | K11: =IFERROR(K10/K9,"") | L11: =IFERROR(L10/L9,"") | M11: =IFERROR(M10/M9,"") | N11: =IFERROR(N10/N9,"") | ... BO11: =IFERROR(BO10/BO9,"")
C12: K3 | D12: Spec-in Value | E12: MVND | F12: Phasing | G12: =SUM(H12:BO12) | H12: 75 | I12: 75 | J12: 75 | K12: 76 | M12: 55 | N12: 55 | O12: 55 | P12: 55 | R12: 84 | S12: 84 | T12: 84 | U12: 84 | W12: 88 | X12: 88 | Y12: 88 | Z12: 90 | AB12: 90 | AC12: 90 | AD12: 90 | AE12: 91 | AG12: 93 | AH12: 93 | AI12: 93 | AJ12: 93 | AL12: 88 | AM12: 88 | AN12: 88 | AO12: 90 | AQ12: 91 | AR12: 91 | AS12: 91 | AT12: 92 | AV12: 95 | AW12: 95 | AX12: 95 | AY12: 97 | BA12: 99 | BB12: 99 | BC12: 99 | BD12: 100 | BF12: 101 | BG12: 101 | BH12: 101 | BI12: 104 | BK12: 100 | BL12: 100 | BM12: 100 | BN12: 101
F13: Actual | G13: =SUM(H13:BO13) | H13: 69 | I13: 84 | J13: 67 | K13: 82 | M13: 49 | N13: 55 | O13: 51 | P13: 52 | R13: 101 | S13: 96 | T13: 80 | U13: 99 | W13: 81 | X13: 87 | Y13: 102 | Z13: 97 | AB13: 79 | AC13: 109 | AD13: 83 | AE13: 86 | AG13: 105 | AH13: 90 | AI13: 89 | AJ13: 81 | AL13: 77 | AM13: 93 | AN13: 82 | AO13: 96 | AQ13: 89 | AR13: 92 | AS13: 109 | AT13: 94 | AV13: 100 | AW13: 111 | AX13: 87 | AY13: 87
F14: % Achieved | G14: =IFERROR(G13/G12,"") | H14: =IFERROR(H13/H12,"") | I14: =IFERROR(I13/I12,"") | J14: =IFERROR(J13/J12,"") | K14: =IFERROR(K13/K12,"") | L14: =IFERROR(L13/L12,"") | M14: =IFERROR(M13/M12,"") | N14: =IFERROR(N13/N12,"") | ... BO14: =IFERROR(BO13/BO12,"")
C15: K4 | D15: Engaged Architect (Submit Design) | E15: D&B | F15: Phasing | G15: =SUM(H15:BO15) | H15: 1 | I15: 1 | J15: 1 | K15: 3 | M15: 1 | N15: 1 | O15: 1 | P15: 1 | R15: 1 | S15: 1 | T15: 1 | U15: 3 | W15: 1 | X15: 1 | Y15: 1 | Z15: 4 | AB15: 1 | AC15: 1 | AD15: 1 | AE15: 4 | AG15: 1 | AH15: 1 | AI15: 1 | AJ15: 4 | AL15: 1 | AM15: 1 | AN15: 1 | AO15: 4 | AQ15: 1 | AR15: 1 | AS15: 1 | AT15: 4 | AV15: 1 | AW15: 1 | AX15: 1 | AY15: 4 | BA15: 1 | BB15: 1 | BC15: 1 | BD15: 4 | BF15: 2 | BG15: 2 | BH15: 2 | BI15: 2 | BK15: 1 | BL15: 1 | BM15: 1 | BN15: 4
F16: Actual | G16: =SUM(H16:BO16) | H16: 1 | I16: 1 | J16: 1 | K16: 3 | M16: 1 | N16: 1 | O16: 1 | P16: 1 | R16: 1 | S16: 1 | T16: 1 | U16: 3 | W16: 1 | X16: 1 | Y16: 1 | Z16: 4 | AB16: 1 | AC16: 1 | AD16: 1 | AE16: 4 | AG16: 1 | AH16: 1 | AI16: 1 | AJ16: 4 | AL16: 1 | AM16: 1 | AN16: 1 | AO16: 4 | AQ16: 1 | AR16: 1 | AS16: 1 | AT16: 4 | AV16: 1 | AW16: 1 | AX16: 1 | AY16: 4
F17: % Achieved | G17: =IFERROR(G16/G15,"") | H17: =IFERROR(H16/H15,"") | I17: =IFERROR(I16/I15,"") | J17: =IFERROR(J16/J15,"") | K17: =IFERROR(K16/K15,"") | L17: =IFERROR(L16/L15,"") | M17: =IFERROR(M16/M15,"") | N17: =IFERROR(N16/N15,"") | ... BO17: =IFERROR(BO16/BO15,"")
C18: K5 | D18: Spec-in Design (submitted design) | E18: Designs | F18: Phasing | G18: =SUM(H18:BO18) | H18: 1 | I18: 1 | J18: 1 | K18: 3 | M18: 1 | N18: 1 | O18: 1 | P18: 1 | R18: 1 | S18: 1 | T18: 1 | U18: 4 | W18: 1 | X18: 1 | Y18: 1 | Z18: 4 | AB18: 1 | AC18: 1 | AD18: 1 | AE18: 4 | AG18: 1 | AH18: 1 | AI18: 1 | AJ18: 4 | AL18: 1 | AM18: 1 | AN18: 1 | AO18: 4 | AQ18: 1 | AR18: 1 | AS18: 1 | AT18: 4 | AV18: 2 | AW18: 2 | AX18: 2 | AY18: 2 | BA18: 2 | BB18: 2 | BC18: 2 | BD18: 2 | BF18: 2 | BG18: 2 | BH18: 2 | BI18: 2 | BK18: 2 | BL18: 2 | BM18: 2 | BN18: 3
F19: Actual | G19: =SUM(H19:BO19) | H19: 1 | I19: 1 | J19: 1 | K19: 4 | M19: 1 | N19: 1 | O19: 1 | P19: 1 | R19: 1 | S19: 1 | T19: 1 | U19: 5 | W19: 1 | X19: 1 | Y19: 1 | Z19: 4 | AB19: 1 | AC19: 1 | AD19: 1 | AE19: 5 | AG19: 1 | AH19: 1 | AI19: 1 | AJ19: 5 | AL19: 1 | AM19: 1 | AN19: 1 | AO19: 5 | AQ19: 1 | AR19: 1 | AS19: 1 | AT19: 5 | AV19: 2 | AW19: 2 | AX19: 2 | AY19: 2
F20: % Achieved | G20: =IFERROR(G19/G18,"") | H20: =IFERROR(H19/H18,"") | I20: =IFERROR(I19/I18,"") | J20: =IFERROR(J19/J18,"") | K20: =IFERROR(K19/K18,"") | L20: =IFERROR(L19/L18,"") | M20: =IFERROR(M19/M18,"") | N20: =IFERROR(N19/N18,"") | ... BO20: =IFERROR(BO19/BO18,"")
A21: =IFERROR(INDEX(Team_Master!$C$6:$C$20,2),"") | B21: =IFERROR(INDEX(Team_Master!$G$6:$G$20,2),"") | C21: K1 | D21: Invoiced Value | E21: MVND | F21: Phasing | G21: =SUM(H21:BO21) | H21: 186 | I21: 186 | J21: 186 | K21: 186 | M21: 135 | N21: 135 | O21: 135 | P21: 137 | R21: 207 | S21: 207 | T21: 207 | U21: 210 | W21: 218 | X21: 218 | Y21: 218 | Z21: 221 | AB21: 223 | AC21: 223 | AD21: 223 | AE21: 223 | AG21: 229 | AH21: 229 | AI21: 229 | AJ21: 232 | AL21: 218 | AM21: 218 | AN21: 218 | AO21: 221 | AQ21: 225 | AR21: 225 | AS21: 225 | AT21: 226 | AV21: 236 | AW21: 236 | AX21: 236 | AY21: 237 | BA21: 245 | BB21: 245 | BC21: 245 | BD21: 245 | BF21: 251 | BG21: 251 | BH21: 251 | BI21: 253 | BK21: 247 | BL21: 247 | BM21: 247 | BN21: 249
F22: Actual | G22: =SUM(H22:BO22) | H22: 183 | I22: 167 | J22: 180 | K22: 182 | M22: 108 | N22: 133 | O22: 149 | P22: 146 | R22: 211 | S22: 187 | T22: 211 | U22: 203 | W22: 201 | X22: 230 | Y22: 174 | Z22: 226 | AB22: 174 | AC22: 217 | AD22: 208 | AE22: 189 | AG22: 231 | AH22: 215 | AI22: 224 | AJ22: 251 | AL22: 187 | AM22: 169 | AN22: 190 | AO22: 221 | AQ22: 189 | AR22: 186 | AS22: 242 | AT22: 225 | AV22: 217 | AW22: 253 | AX22: 208 | AY22: 236
F23: % Achieved | G23: =IFERROR(G22/G21,"") | H23: =IFERROR(H22/H21,"") | I23: =IFERROR(I22/I21,"") | J23: =IFERROR(J22/J21,"") | K23: =IFERROR(K22/K21,"") | L23: =IFERROR(L22/L21,"") | M23: =IFERROR(M22/M21,"") | N23: =IFERROR(N22/N21,"") | ... BO23: =IFERROR(BO22/BO21,"")
C24: K2 | D24: Key account approach / Site check | E24: Roadshow | F24: Phasing | G24: =SUM(H24:BO24) | H24: 3 | I24: 3 | J24: 3 | K24: 6 | M24: 2 | N24: 2 | O24: 2 | P24: 5 | R24: 4 | S24: 4 | T24: 4 | U24: 5 | W24: 4 | X24: 4 | Y24: 4 | Z24: 6 | AB24: 4 | AC24: 4 | AD24: 4 | AE24: 6 | AG24: 4 | AH24: 4 | AI24: 4 | AJ24: 7 | AL24: 4 | AM24: 4 | AN24: 4 | AO24: 6 | AQ24: 4 | AR24: 4 | AS24: 4 | AT24: 7 | AV24: 4 | AW24: 4 | AX24: 4 | AY24: 7 | BA24: 5 | BB24: 5 | BC24: 5 | BD24: 5 | BF24: 5 | BG24: 5 | BH24: 5 | BI24: 6 | BK24: 5 | BL24: 5 | BM24: 5 | BN24: 6
F25: Actual | G25: =SUM(H25:BO25) | H25: 3 | I25: 3 | J25: 3 | K25: 6 | M25: 2 | N25: 2 | O25: 2 | P25: 4 | R25: 3 | S25: 4 | T25: 4 | U25: 5 | W25: 4 | X25: 4 | Y25: 3 | Z25: 5 | AB25: 4 | AC25: 3 | AD25: 3 | AE25: 5 | AG25: 4 | AH25: 4 | AI25: 4 | AJ25: 7 | AL25: 4 | AM25: 4 | AN25: 3 | AO25: 5 | AQ25: 4 | AR25: 3 | AS25: 4 | AT25: 7 | AV25: 4 | AW25: 4 | AX25: 3 | AY25: 6
F26: % Achieved | G26: =IFERROR(G25/G24,"") | H26: =IFERROR(H25/H24,"") | I26: =IFERROR(I25/I24,"") | J26: =IFERROR(J25/J24,"") | K26: =IFERROR(K25/K24,"") | L26: =IFERROR(L25/L24,"") | M26: =IFERROR(M25/M24,"") | N26: =IFERROR(N25/N24,"") | ... BO26: =IFERROR(BO25/BO24,"")
C27: K3 | D27: Spec-in Value | E27: MVND | F27: Phasing | G27: =SUM(H27:BO27) | H27: 69 | I27: 69 | J27: 69 | K27: 69 | M27: 50 | N27: 50 | O27: 50 | P27: 52 | R27: 77 | S27: 77 | T27: 77 | U27: 78 | W27: 81 | X27: 81 | Y27: 81 | Z27: 82 | AB27: 83 | AC27: 83 | AD27: 83 | AE27: 83 | AG27: 85 | AH27: 85 | AI27: 85 | AJ27: 86 | AL27: 81 | AM27: 81 | AN27: 81 | AO27: 82 | AQ27: 83 | AR27: 83 | AS27: 83 | AT27: 86 | AV27: 87 | AW27: 87 | AX27: 87 | AY27: 90 | BA27: 91 | BB27: 91 | BC27: 91 | BD27: 91 | BF27: 93 | BG27: 93 | BH27: 93 | BI27: 95 | BK27: 91 | BL27: 91 | BM27: 91 | BN27: 93
F28: Actual | G28: =SUM(H28:BO28) | H28: 64 | I28: 54 | J28: 73 | K28: 59 | M28: 41 | N28: 39 | O28: 49 | P28: 48 | R28: 76 | S28: 76 | T28: 80 | U28: 85 | W28: 81 | X28: 68 | Y28: 75 | Z28: 68 | AB28: 64 | AC28: 77 | AD28: 84 | AE28: 69 | AG28: 73 | AH28: 75 | AI28: 86 | AJ28: 81 | AL28: 79 | AM28: 83 | AN28: 73 | AO28: 85 | AQ28: 89 | AR28: 66 | AS28: 90 | AT28: 87 | AV28: 71 | AW28: 80 | AX28: 85 | AY28: 97
F29: % Achieved | G29: =IFERROR(G28/G27,"") | H29: =IFERROR(H28/H27,"") | I29: =IFERROR(I28/I27,"") | J29: =IFERROR(J28/J27,"") | K29: =IFERROR(K28/K27,"") | L29: =IFERROR(L28/L27,"") | M29: =IFERROR(M28/M27,"") | N29: =IFERROR(N28/N27,"") | ... BO29: =IFERROR(BO28/BO27,"")
C30: K4 | D30: Engaged Architect (Submit Design) | E30: D&B | F30: Phasing | G30: =SUM(H30:BO30) | H30: 1 | I30: 1 | J30: 1 | K30: 2 | M30: 1 | N30: 1 | O30: 1 | P30: 1 | R30: 1 | S30: 1 | T30: 1 | U30: 3 | W30: 1 | X30: 1 | Y30: 1 | Z30: 3 | AB30: 1 | AC30: 1 | AD30: 1 | AE30: 3 | AG30: 1 | AH30: 1 | AI30: 1 | AJ30: 4 | AL30: 1 | AM30: 1 | AN30: 1 | AO30: 3 | AQ30: 1 | AR30: 1 | AS30: 1 | AT30: 3 | AV30: 1 | AW30: 1 | AX30: 1 | AY30: 4 | BA30: 1 | BB30: 1 | BC30: 1 | BD30: 4 | BF30: 1 | BG30: 1 | BH30: 1 | BI30: 4 | BK30: 2 | BL30: 2 | BM30: 2 | BN30: 2
F31: Actual | G31: =SUM(H31:BO31) | H31: 1 | I31: 1 | J31: 1 | K31: 2 | M31: 1 | N31: 1 | O31: 1 | P31: 1 | R31: 1 | S31: 1 | T31: 1 | U31: 3 | W31: 1 | X31: 1 | Y31: 1 | Z31: 3 | AB31: 1 | AC31: 1 | AD31: 1 | AE31: 3 | AG31: 1 | AH31: 1 | AI31: 1 | AJ31: 4 | AL31: 1 | AM31: 1 | AN31: 1 | AO31: 2 | AQ31: 1 | AR31: 1 | AS31: 1 | AT31: 2 | AV31: 1 | AW31: 1 | AX31: 1 | AY31: 3
F32: % Achieved | G32: =IFERROR(G31/G30,"") | H32: =IFERROR(H31/H30,"") | I32: =IFERROR(I31/I30,"") | J32: =IFERROR(J31/J30,"") | K32: =IFERROR(K31/K30,"") | L32: =IFERROR(L31/L30,"") | M32: =IFERROR(M31/M30,"") | N32: =IFERROR(N31/N30,"") | ... BO32: =IFERROR(BO31/BO30,"")
C33: K5 | D33: Spec-in Design (submitted design) | E33: Designs | F33: Phasing | G33: =SUM(H33:BO33) | H33: 1 | I33: 1 | J33: 1 | K33: 3 | M33: 1 | N33: 1 | O33: 1 | P33: 1 | R33: 1 | S33: 1 | T33: 1 | U33: 3 | W33: 1 | X33: 1 | Y33: 1 | Z33: 3 | AB33: 1 | AC33: 1 | AD33: 1 | AE33: 4 | AG33: 1 | AH33: 1 | AI33: 1 | AJ33: 4 | AL33: 1 | AM33: 1 | AN33: 1 | AO33: 3 | AQ33: 1 | AR33: 1 | AS33: 1 | AT33: 4 | AV33: 1 | AW33: 1 | AX33: 1 | AY33: 4 | BA33: 1 | BB33: 1 | BC33: 1 | BD33: 4 | BF33: 1 | BG33: 1 | BH33: 1 | BI33: 4 | BK33: 2 | BL33: 2 | BM33: 2 | BN33: 2
F34: Actual | G34: =SUM(H34:BO34) | H34: 1 | I34: 1 | J34: 1 | K34: 3 | M34: 1 | N34: 1 | O34: 1 | P34: 1 | R34: 1 | S34: 1 | T34: 1 | U34: 3 | W34: 1 | X34: 1 | Y34: 1 | Z34: 3 | AB34: 1 | AC34: 1 | AD34: 1 | AE34: 4 | AG34: 1 | AH34: 1 | AI34: 1 | AJ34: 4 | AL34: 1 | AM34: 1 | AN34: 1 | AO34: 3 | AQ34: 1 | AR34: 1 | AS34: 1 | AT34: 4 | AV34: 1 | AW34: 1 | AX34: 1 | AY34: 4
F35: % Achieved | G35: =IFERROR(G34/G33,"") | H35: =IFERROR(H34/H33,"") | I35: =IFERROR(I34/I33,"") | J35: =IFERROR(J34/J33,"") | K35: =IFERROR(K34/K33,"") | L35: =IFERROR(L34/L33,"") | M35: =IFERROR(M34/M33,"") | N35: =IFERROR(N34/N33,"") | ... BO35: =IFERROR(BO34/BO33,"")
A36: =IFERROR(INDEX(Team_Master!$C$6:$C$20,3),"") | B36: =IFERROR(INDEX(Team_Master!$G$6:$G$20,3),"") | C36: K1 | D36: Invoiced Value | E36: MVND | F36: Phasing | G36: =SUM(H36:BO36) | H36: 244 | I36: 244 | J36: 244 | K36: 246 | M36: 178 | N36: 178 | O36: 178 | P36: 179 | R36: 273 | S36: 273 | T36: 273 | U36: 273 | W36: 287 | X36: 287 | Y36: 287 | Z36: 289 | AB36: 293 | AC36: 293 | AD36: 293 | AE36: 294 | AG36: 302 | AH36: 302 | AI36: 302 | AJ36: 302 | AL36: 287 | AM36: 287 | AN36: 287 | AO36: 289 | AQ36: 296 | AR36: 296 | AS36: 296 | AT36: 296 | AV36: 310 | AW36: 310 | AX36: 310 | AY36: 312 | BA36: 322 | BB36: 322 | BC36: 322 | BD36: 322 | BF36: 330 | BG36: 330 | BH36: 330 | BI36: 332 | BK36: 325 | BL36: 325 | BM36: 325 | BN36: 325
F37: Actual | G37: =SUM(H37:BO37) | H37: 282 | I37: 222 | J37: 267 | K37: 257 | M37: 224 | N37: 222 | O37: 176 | P37: 191 | R37: 255 | S37: 288 | T37: 328 | U37: 337 | W37: 307 | X37: 290 | Y37: 276 | Z37: 325 | AB37: 365 | AC37: 274 | AD37: 348 | AE37: 263 | AG37: 290 | AH37: 294 | AI37: 348 | AJ37: 305 | AL37: 294 | AM37: 323 | AN37: 266 | AO37: 338 | AQ37: 276 | AR37: 321 | AS37: 291 | AT37: 285 | AV37: 338 | AW37: 327 | AX37: 320 | AY37: 326
F38: % Achieved | G38: =IFERROR(G37/G36,"") | H38: =IFERROR(H37/H36,"") | I38: =IFERROR(I37/I36,"") | J38: =IFERROR(J37/J36,"") | K38: =IFERROR(K37/K36,"") | L38: =IFERROR(L37/L36,"") | M38: =IFERROR(M37/M36,"") | N38: =IFERROR(N37/N36,"") | ... BO38: =IFERROR(BO37/BO36,"")
C39: K2 | D39: Key account approach / Site check | E39: Roadshow | F39: Phasing | G39: =SUM(H39:BO39) | H39: 4 | I39: 4 | J39: 4 | K39: 4 | M39: 3 | N39: 3 | O39: 3 | P39: 3 | R39: 4 | S39: 4 | T39: 4 | U39: 6 | W39: 4 | X39: 4 | Y39: 4 | Z39: 7 | AB39: 5 | AC39: 5 | AD39: 5 | AE39: 5 | AG39: 5 | AH39: 5 | AI39: 5 | AJ39: 5 | AL39: 4 | AM39: 4 | AN39: 4 | AO39: 7 | AQ39: 5 | AR39: 5 | AS39: 5 | AT39: 5 | AV39: 5 | AW39: 5 | AX39: 5 | AY39: 6 | BA39: 5 | BB39: 5 | BC39: 5 | BD39: 6 | BF39: 5 | BG39: 5 | BH39: 5 | BI39: 7 | BK39: 5 | BL39: 5 | BM39: 5 | BN39: 7
F40: Actual | G40: =SUM(H40:BO40) | H40: 4 | I40: 4 | J40: 4 | K40: 5 | M40: 3 | N40: 3 | O40: 4 | P40: 3 | R40: 5 | S40: 4 | T40: 5 | U40: 7 | W40: 5 | X40: 4 | Y40: 4 | Z40: 9 | AB40: 5 | AC40: 6 | AD40: 6 | AE40: 5 | AG40: 5 | AH40: 6 | AI40: 5 | AJ40: 5 | AL40: 5 | AM40: 4 | AN40: 5 | AO40: 7 | AQ40: 5 | AR40: 6 | AS40: 4 | AT40: 5 | AV40: 6 | AW40: 6 | AX40: 6 | AY40: 6
F41: % Achieved | G41: =IFERROR(G40/G39,"") | H41: =IFERROR(H40/H39,"") | I41: =IFERROR(I40/I39,"") | J41: =IFERROR(J40/J39,"") | K41: =IFERROR(K40/K39,"") | L41: =IFERROR(L40/L39,"") | M41: =IFERROR(M40/M39,"") | N41: =IFERROR(N40/N39,"") | ... BO41: =IFERROR(BO40/BO39,"")
...

Sheet Target_FY
B2: TARGET / PHASING FY2026 – gom từ Weekly_Tracker
B3: Chỉ nhập cột 'FY Target (nhập)' – các cột còn lại gom từ phasing tuần. Cột 'Check phasing' báo lệch nếu phasing cả năm chưa khớp FY target.
L4: TỰ GOM TỪ WEEKLY_TRACKER →
A5: Key | B5: Emp Code | C5: Name of Sales Person | D5: KPI | E5: KPI name | F5: Unit | G5: FY total | H5: Q1 | I5: Q2 | J5: Q3 | K5: Q4 | L5: Jan | M5: Feb | N5: Mar | O5: Apr | P5: May | Q5: Jun | R5: Jul | S5: Aug | T5: Sep | U5: Oct | V5: Nov | W5: Dec | X5: YTD Q1 | Y5: YTD Q2 | Z5: YTD Q3 | AA5: YTD Q4 | AB5: FY Target (nhập) | AC5: Check phasing
A6: =IF($B6="","",$B6&"|"&$D6) | B6: =IFERROR(INDEX(Team_Master!$C$6:$C$20,1),"") | C6: =IFERROR(INDEX(Team_Master!$G$6:$G$20,1),"") | D6: K1 | E6: Invoiced Value | F6: MVND | G6: =SUM(H6:K6) | H6: =SUM(L6:N6) | I6: =SUM(O6:Q6) | J6: =SUM(R6:T6) | K6: =SUM(U6:W6) | L6: =SUM(Weekly_Tracker!H6:L6) | M6: =SUM(Weekly_Tracker!M6:Q6) | N6: =SUM(Weekly_Tracker!R6:V6) | O6: =SUM(Weekly_Tracker!W6:AA6) | P6: =SUM(Weekly_Tracker!AB6:AF6) | Q6: =SUM(Weekly_Tracker!AG6:AK6) | R6: =SUM(Weekly_Tracker!AL6:AP6) | S6: =SUM(Weekly_Tracker!AQ6:AU6) | T6: =SUM(Weekly_Tracker!AV6:AZ6) | U6: =SUM(Weekly_Tracker!BA6:BE6) | V6: =SUM(Weekly_Tracker!BF6:BJ6) | W6: =SUM(Weekly_Tracker!BK6:BO6) | X6: =H6 | Y6: =X6+I6 | Z6: =Y6+J6 | AA6: =Z6+K6 | AB6: 12000 | AC6: =IF($B6="","",IF(AB6=0,"chưa nhập FY target",IF(ROUND(G6-AB6,2)=0,"OK","Lệch "&TEXT(G6-AB6,"#,##0"))))
A7: =IF($B7="","",$B7&"|"&$D7) | B7: =IFERROR(INDEX(Team_Master!$C$6:$C$20,1),"") | C7: =IFERROR(INDEX(Team_Master!$G$6:$G$20,1),"") | D7: K2 | E7: Key account approach / Site check | F7: Roadshow | G7: =SUM(H7:K7) | H7: =SUM(L7:N7) | I7: =SUM(O7:Q7) | J7: =SUM(R7:T7) | K7: =SUM(U7:W7) | L7: =SUM(Weekly_Tracker!H9:L9) | M7: =SUM(Weekly_Tracker!M9:Q9) | N7: =SUM(Weekly_Tracker!R9:V9) | O7: =SUM(Weekly_Tracker!W9:AA9) | P7: =SUM(Weekly_Tracker!AB9:AF9) | Q7: =SUM(Weekly_Tracker!AG9:AK9) | R7: =SUM(Weekly_Tracker!AL9:AP9) | S7: =SUM(Weekly_Tracker!AQ9:AU9) | T7: =SUM(Weekly_Tracker!AV9:AZ9) | U7: =SUM(Weekly_Tracker!BA9:BE9) | V7: =SUM(Weekly_Tracker!BF9:BJ9) | W7: =SUM(Weekly_Tracker!BK9:BO9) | X7: =H7 | Y7: =X7+I7 | Z7: =Y7+J7 | AA7: =Z7+K7 | AB7: 215 | AC7: =IF($B7="","",IF(AB7=0,"chưa nhập FY target",IF(ROUND(G7-AB7,2)=0,"OK","Lệch "&TEXT(G7-AB7,"#,##0"))))
A8: =IF($B8="","",$B8&"|"&$D8) | B8: =IFERROR(INDEX(Team_Master!$C$6:$C$20,1),"") | C8: =IFERROR(INDEX(Team_Master!$G$6:$G$20,1),"") | D8: K3 | E8: Spec-in Value | F8: MVND | G8: =SUM(H8:K8) | H8: =SUM(L8:N8) | I8: =SUM(O8:Q8) | J8: =SUM(R8:T8) | K8: =SUM(U8:W8) | L8: =SUM(Weekly_Tracker!H12:L12) | M8: =SUM(Weekly_Tracker!M12:Q12) | N8: =SUM(Weekly_Tracker!R12:V12) | O8: =SUM(Weekly_Tracker!W12:AA12) | P8: =SUM(Weekly_Tracker!AB12:AF12) | Q8: =SUM(Weekly_Tracker!AG12:AK12) | R8: =SUM(Weekly_Tracker!AL12:AP12) | S8: =SUM(Weekly_Tracker!AQ12:AU12) | T8: =SUM(Weekly_Tracker!AV12:AZ12) | U8: =SUM(Weekly_Tracker!BA12:BE12) | V8: =SUM(Weekly_Tracker!BF12:BJ12) | W8: =SUM(Weekly_Tracker!BK12:BO12) | X8: =H8 | Y8: =X8+I8 | Z8: =Y8+J8 | AA8: =Z8+K8 | AB8: 4250 | AC8: =IF($B8="","",IF(AB8=0,"chưa nhập FY target",IF(ROUND(G8-AB8,2)=0,"OK","Lệch "&TEXT(G8-AB8,"#,##0"))))
A9: =IF($B9="","",$B9&"|"&$D9) | B9: =IFERROR(INDEX(Team_Master!$C$6:$C$20,1),"") | C9: =IFERROR(INDEX(Team_Master!$G$6:$G$20,1),"") | D9: K4 | E9: Engaged Architect (Submit Design) | F9: D&B | G9: =SUM(H9:K9) | H9: =SUM(L9:N9) | I9: =SUM(O9:Q9) | J9: =SUM(R9:T9) | K9: =SUM(U9:W9) | L9: =SUM(Weekly_Tracker!H15:L15) | M9: =SUM(Weekly_Tracker!M15:Q15) | N9: =SUM(Weekly_Tracker!R15:V15) | O9: =SUM(Weekly_Tracker!W15:AA15) | P9: =SUM(Weekly_Tracker!AB15:AF15) | Q9: =SUM(Weekly_Tracker!AG15:AK15) | R9: =SUM(Weekly_Tracker!AL15:AP15) | S9: =SUM(Weekly_Tracker!AQ15:AU15) | T9: =SUM(Weekly_Tracker!AV15:AZ15) | U9: =SUM(Weekly_Tracker!BA15:BE15) | V9: =SUM(Weekly_Tracker!BF15:BJ15) | W9: =SUM(Weekly_Tracker!BK15:BO15) | X9: =H9 | Y9: =X9+I9 | Z9: =Y9+J9 | AA9: =Z9+K9 | AB9: 80 | AC9: =IF($B9="","",IF(AB9=0,"chưa nhập FY target",IF(ROUND(G9-AB9,2)=0,"OK","Lệch "&TEXT(G9-AB9,"#,##0"))))
A10: =IF($B10="","",$B10&"|"&$D10) | B10: =IFERROR(INDEX(Team_Master!$C$6:$C$20,1),"") | C10: =IFERROR(INDEX(Team_Master!$G$6:$G$20,1),"") | D10: K5 | E10: Spec-in Design (submitted design) | F10: Designs | G10: =SUM(H10:K10) | H10: =SUM(L10:N10) | I10: =SUM(O10:Q10) | J10: =SUM(R10:T10) | K10: =SUM(U10:W10) | L10: =SUM(Weekly_Tracker!H18:L18) | M10: =SUM(Weekly_Tracker!M18:Q18) | N10: =SUM(Weekly_Tracker!R18:V18) | O10: =SUM(Weekly_Tracker!W18:AA18) | P10: =SUM(Weekly_Tracker!AB18:AF18) | Q10: =SUM(Weekly_Tracker!AG18:AK18) | R10: =SUM(Weekly_Tracker!AL18:AP18) | S10: =SUM(Weekly_Tracker!AQ18:AU18) | T10: =SUM(Weekly_Tracker!AV18:AZ18) | U10: =SUM(Weekly_Tracker!BA18:BE18) | V10: =SUM(Weekly_Tracker!BF18:BJ18) | W10: =SUM(Weekly_Tracker!BK18:BO18) | X10: =H10 | Y10: =X10+I10 | Z10: =Y10+J10 | AA10: =Z10+K10 | AB10: 85 | AC10: =IF($B10="","",IF(AB10=0,"chưa nhập FY target",IF(ROUND(G10-AB10,2)=0,"OK","Lệch "&TEXT(G10-AB10,"#,##0"))))
A11: =IF($B11="","",$B11&"|"&$D11) | B11: =IFERROR(INDEX(Team_Master!$C$6:$C$20,2),"") | C11: =IFERROR(INDEX(Team_Master!$G$6:$G$20,2),"") | D11: K1 | E11: Invoiced Value | F11: MVND | G11: =SUM(H11:K11) | H11: =SUM(L11:N11) | I11: =SUM(O11:Q11) | J11: =SUM(R11:T11) | K11: =SUM(U11:W11) | L11: =SUM(Weekly_Tracker!H21:L21) | M11: =SUM(Weekly_Tracker!M21:Q21) | N11: =SUM(Weekly_Tracker!R21:V21) | O11: =SUM(Weekly_Tracker!W21:AA21) | P11: =SUM(Weekly_Tracker!AB21:AF21) | Q11: =SUM(Weekly_Tracker!AG21:AK21) | R11: =SUM(Weekly_Tracker!AL21:AP21) | S11: =SUM(Weekly_Tracker!AQ21:AU21) | T11: =SUM(Weekly_Tracker!AV21:AZ21) | U11: =SUM(Weekly_Tracker!BA21:BE21) | V11: =SUM(Weekly_Tracker!BF21:BJ21) | W11: =SUM(Weekly_Tracker!BK21:BO21) | X11: =H11 | Y11: =X11+I11 | Z11: =Y11+J11 | AA11: =Z11+K11 | AB11: 10500 | AC11: =IF($B11="","",IF(AB11=0,"chưa nhập FY target",IF(ROUND(G11-AB11,2)=0,"OK","Lệch "&TEXT(G11-AB11,"#,##0"))))
A12: =IF($B12="","",$B12&"|"&$D12) | B12: =IFERROR(INDEX(Team_Master!$C$6:$C$20,2),"") | C12: =IFERROR(INDEX(Team_Master!$G$6:$G$20,2),"") | D12: K2 | E12: Key account approach / Site check | F12: Roadshow | G12: =SUM(H12:K12) | H12: =SUM(L12:N12) | I12: =SUM(O12:Q12) | J12: =SUM(R12:T12) | K12: =SUM(U12:W12) | L12: =SUM(Weekly_Tracker!H24:L24) | M12: =SUM(Weekly_Tracker!M24:Q24) | N12: =SUM(Weekly_Tracker!R24:V24) | O12: =SUM(Weekly_Tracker!W24:AA24) | P12: =SUM(Weekly_Tracker!AB24:AF24) | Q12: =SUM(Weekly_Tracker!AG24:AK24) | R12: =SUM(Weekly_Tracker!AL24:AP24) | S12: =SUM(Weekly_Tracker!AQ24:AU24) | T12: =SUM(Weekly_Tracker!AV24:AZ24) | U12: =SUM(Weekly_Tracker!BA24:BE24) | V12: =SUM(Weekly_Tracker!BF24:BJ24) | W12: =SUM(Weekly_Tracker!BK24:BO24) | X12: =H12 | Y12: =X12+I12 | Z12: =Y12+J12 | AA12: =Z12+K12 | AB12: 216 | AC12: =IF($B12="","",IF(AB12=0,"chưa nhập FY target",IF(ROUND(G12-AB12,2)=0,"OK","Lệch "&TEXT(G12-AB12,"#,##0"))))
A13: =IF($B13="","",$B13&"|"&$D13) | B13: =IFERROR(INDEX(Team_Master!$C$6:$C$20,2),"") | C13: =IFERROR(INDEX(Team_Master!$G$6:$G$20,2),"") | D13: K3 | E13: Spec-in Value | F13: MVND | G13: =SUM(H13:K13) | H13: =SUM(L13:N13) | I13: =SUM(O13:Q13) | J13: =SUM(R13:T13) | K13: =SUM(U13:W13) | L13: =SUM(Weekly_Tracker!H27:L27) | M13: =SUM(Weekly_Tracker!M27:Q27) | N13: =SUM(Weekly_Tracker!R27:V27) | O13: =SUM(Weekly_Tracker!W27:AA27) | P13: =SUM(Weekly_Tracker!AB27:AF27) | Q13: =SUM(Weekly_Tracker!AG27:AK27) | R13: =SUM(Weekly_Tracker!AL27:AP27) | S13: =SUM(Weekly_Tracker!AQ27:AU27) | T13: =SUM(Weekly_Tracker!AV27:AZ27) | U13: =SUM(Weekly_Tracker!BA27:BE27) | V13: =SUM(Weekly_Tracker!BF27:BJ27) | W13: =SUM(Weekly_Tracker!BK27:BO27) | X13: =H13 | Y13: =X13+I13 | Z13: =Y13+J13 | AA13: =Z13+K13 | AB13: 3900 | AC13: =IF($B13="","",IF(AB13=0,"chưa nhập FY target",IF(ROUND(G13-AB13,2)=0,"OK","Lệch "&TEXT(G13-AB13,"#,##0"))))
A14: =IF($B14="","",$B14&"|"&$D14) | B14: =IFERROR(INDEX(Team_Master!$C$6:$C$20,2),"") | C14: =IFERROR(INDEX(Team_Master!$G$6:$G$20,2),"") | D14: K4 | E14: Engaged Architect (Submit Design) | F14: D&B | G14: =SUM(H14:K14) | H14: =SUM(L14:N14) | I14: =SUM(O14:Q14) | J14: =SUM(R14:T14) | K14: =SUM(U14:W14) | L14: =SUM(Weekly_Tracker!H30:L30) | M14: =SUM(Weekly_Tracker!M30:Q30) | N14: =SUM(Weekly_Tracker!R30:V30) | O14: =SUM(Weekly_Tracker!W30:AA30) | P14: =SUM(Weekly_Tracker!AB30:AF30) | Q14: =SUM(Weekly_Tracker!AG30:AK30) | R14: =SUM(Weekly_Tracker!AL30:AP30) | S14: =SUM(Weekly_Tracker!AQ30:AU30) | T14: =SUM(Weekly_Tracker!AV30:AZ30) | U14: =SUM(Weekly_Tracker!BA30:BE30) | V14: =SUM(Weekly_Tracker!BF30:BJ30) | W14: =SUM(Weekly_Tracker!BK30:BO30) | X14: =H14 | Y14: =X14+I14 | Z14: =Y14+J14 | AA14: =Z14+K14 | AB14: 75 | AC14: =IF($B14="","",IF(AB14=0,"chưa nhập FY target",IF(ROUND(G14-AB14,2)=0,"OK","Lệch "&TEXT(G14-AB14,"#,##0"))))
A15: =IF($B15="","",$B15&"|"&$D15) | B15: =IFERROR(INDEX(Team_Master!$C$6:$C$20,2),"") | C15: =IFERROR(INDEX(Team_Master!$G$6:$G$20,2),"") | D15: K5 | E15: Spec-in Design (submitted design) | F15: Designs | G15: =SUM(H15:K15) | H15: =SUM(L15:N15) | I15: =SUM(O15:Q15) | J15: =SUM(R15:T15) | K15: =SUM(U15:W15) | L15: =SUM(Weekly_Tracker!H33:L33) | M15: =SUM(Weekly_Tracker!M33:Q33) | N15: =SUM(Weekly_Tracker!R33:V33) | O15: =SUM(Weekly_Tracker!W33:AA33) | P15: =SUM(Weekly_Tracker!AB33:AF33) | Q15: =SUM(Weekly_Tracker!AG33:AK33) | R15: =SUM(Weekly_Tracker!AL33:AP33) | S15: =SUM(Weekly_Tracker!AQ33:AU33) | T15: =SUM(Weekly_Tracker!AV33:AZ33) | U15: =SUM(Weekly_Tracker!BA33:BE33) | V15: =SUM(Weekly_Tracker!BF33:BJ33) | W15: =SUM(Weekly_Tracker!BK33:BO33) | X15: =H15 | Y15: =X15+I15 | Z15: =Y15+J15 | AA15: =Z15+K15 | AB15: 78 | AC15: =IF($B15="","",IF(AB15=0,"chưa nhập FY target",IF(ROUND(G15-AB15,2)=0,"OK","Lệch "&TEXT(G15-AB15,"#,##0"))))
A16: =IF($B16="","",$B16&"|"&$D16) | B16: =IFERROR(INDEX(Team_Master!$C$6:$C$20,3),"") | C16: =IFERROR(INDEX(Team_Master!$G$6:$G$20,3),"") | D16: K1 | E16: Invoiced Value | F16: MVND | G16: =SUM(H16:K16) | H16: =SUM(L16:N16) | I16: =SUM(O16:Q16) | J16: =SUM(R16:T16) | K16: =SUM(U16:W16) | L16: =SUM(Weekly_Tracker!H36:L36) | M16: =SUM(Weekly_Tracker!M36:Q36) | N16: =SUM(Weekly_Tracker!R36:V36) | O16: =SUM(Weekly_Tracker!W36:AA36) | P16: =SUM(Weekly_Tracker!AB36:AF36) | Q16: =SUM(Weekly_Tracker!AG36:AK36) | R16: =SUM(Weekly_Tracker!AL36:AP36) | S16: =SUM(Weekly_Tracker!AQ36:AU36) | T16: =SUM(Weekly_Tracker!AV36:AZ36) | U16: =SUM(Weekly_Tracker!BA36:BE36) | V16: =SUM(Weekly_Tracker!BF36:BJ36) | W16: =SUM(Weekly_Tracker!BK36:BO36) | X16: =H16 | Y16: =X16+I16 | Z16: =Y16+J16 | AA16: =Z16+K16 | AB16: 13800 | AC16: =IF($B16="","",IF(AB16=0,"chưa nhập FY target",IF(ROUND(G16-AB16,2)=0,"OK","Lệch "&TEXT(G16-AB16,"#,##0"))))
A17: =IF($B17="","",$B17&"|"&$D17) | B17: =IFERROR(INDEX(Team_Master!$C$6:$C$20,3),"") | C17: =IFERROR(INDEX(Team_Master!$G$6:$G$20,3),"") | D17: K2 | E17: Key account approach / Site check | F17: Roadshow | G17: =SUM(H17:K17) | H17: =SUM(L17:N17) | I17: =SUM(O17:Q17) | J17: =SUM(R17:T17) | K17: =SUM(U17:W17) | L17: =SUM(Weekly_Tracker!H39:L39) | M17: =SUM(Weekly_Tracker!M39:Q39) | N17: =SUM(Weekly_Tracker!R39:V39) | O17: =SUM(Weekly_Tracker!W39:AA39) | P17: =SUM(Weekly_Tracker!AB39:AF39) | Q17: =SUM(Weekly_Tracker!AG39:AK39) | R17: =SUM(Weekly_Tracker!AL39:AP39) | S17: =SUM(Weekly_Tracker!AQ39:AU39) | T17: =SUM(Weekly_Tracker!AV39:AZ39) | U17: =SUM(Weekly_Tracker!BA39:BE39) | V17: =SUM(Weekly_Tracker!BF39:BJ39) | W17: =SUM(Weekly_Tracker!BK39:BO39) | X17: =H17 | Y17: =X17+I17 | Z17: =Y17+J17 | AA17: =Z17+K17 | AB17: 230 | AC17: =IF($B17="","",IF(AB17=0,"chưa nhập FY target",IF(ROUND(G17-AB17,2)=0,"OK","Lệch "&TEXT(G17-AB17,"#,##0"))))
A18: =IF($B18="","",$B18&"|"&$D18) | B18: =IFERROR(INDEX(Team_Master!$C$6:$C$20,3),"") | C18: =IFERROR(INDEX(Team_Master!$G$6:$G$20,3),"") | D18: K3 | E18: Spec-in Value | F18: MVND | G18: =SUM(H18:K18) | H18: =SUM(L18:N18) | I18: =SUM(O18:Q18) | J18: =SUM(R18:T18) | K18: =SUM(U18:W18) | L18: =SUM(Weekly_Tracker!H42:L42) | M18: =SUM(Weekly_Tracker!M42:Q42) | N18: =SUM(Weekly_Tracker!R42:V42) | O18: =SUM(Weekly_Tracker!W42:AA42) | P18: =SUM(Weekly_Tracker!AB42:AF42) | Q18: =SUM(Weekly_Tracker!AG42:AK42) | R18: =SUM(Weekly_Tracker!AL42:AP42) | S18: =SUM(Weekly_Tracker!AQ42:AU42) | T18: =SUM(Weekly_Tracker!AV42:AZ42) | U18: =SUM(Weekly_Tracker!BA42:BE42) | V18: =SUM(Weekly_Tracker!BF42:BJ42) | W18: =SUM(Weekly_Tracker!BK42:BO42) | X18: =H18 | Y18: =X18+I18 | Z18: =Y18+J18 | AA18: =Z18+K18 | AB18: 4600 | AC18: =IF($B18="","",IF(AB18=0,"chưa nhập FY target",IF(ROUND(G18-AB18,2)=0,"OK","Lệch "&TEXT(G18-AB18,"#,##0"))))
A19: =IF($B19="","",$B19&"|"&$D19) | B19: =IFERROR(INDEX(Team_Master!$C$6:$C$20,3),"") | C19: =IFERROR(INDEX(Team_Master!$G$6:$G$20,3),"") | D19: K4 | E19: Engaged Architect (Submit Design) | F19: D&B | G19: =SUM(H19:K19) | H19: =SUM(L19:N19) | I19: =SUM(O19:Q19) | J19: =SUM(R19:T19) | K19: =SUM(U19:W19) | L19: =SUM(Weekly_Tracker!H45:L45) | M19: =SUM(Weekly_Tracker!M45:Q45) | N19: =SUM(Weekly_Tracker!R45:V45) | O19: =SUM(Weekly_Tracker!W45:AA45) | P19: =SUM(Weekly_Tracker!AB45:AF45) | Q19: =SUM(Weekly_Tracker!AG45:AK45) | R19: =SUM(Weekly_Tracker!AL45:AP45) | S19: =SUM(Weekly_Tracker!AQ45:AU45) | T19: =SUM(Weekly_Tracker!AV45:AZ45) | U19: =SUM(Weekly_Tracker!BA45:BE45) | V19: =SUM(Weekly_Tracker!BF45:BJ45) | W19: =SUM(Weekly_Tracker!BK45:BO45) | X19: =H19 | Y19: =X19+I19 | Z19: =Y19+J19 | AA19: =Z19+K19 | AB19: 88 | AC19: =IF($B19="","",IF(AB19=0,"chưa nhập FY target",IF(ROUND(G19-AB19,2)=0,"OK","Lệch "&TEXT(G19-AB19,"#,##0"))))
A20: =IF($B20="","",$B20&"|"&$D20) | B20: =IFERROR(INDEX(Team_Master!$C$6:$C$20,3),"") | C20: =IFERROR(INDEX(Team_Master!$G$6:$G$20,3),"") | D20: K5 | E20: Spec-in Design (submitted design) | F20: Designs | G20: =SUM(H20:K20) | H20: =SUM(L20:N20) | I20: =SUM(O20:Q20) | J20: =SUM(R20:T20) | K20: =SUM(U20:W20) | L20: =SUM(Weekly_Tracker!H48:L48) | M20: =SUM(Weekly_Tracker!M48:Q48) | N20: =SUM(Weekly_Tracker!R48:V48) | O20: =SUM(Weekly_Tracker!W48:AA48) | P20: =SUM(Weekly_Tracker!AB48:AF48) | Q20: =SUM(Weekly_Tracker!AG48:AK48) | R20: =SUM(Weekly_Tracker!AL48:AP48) | S20: =SUM(Weekly_Tracker!AQ48:AU48) | T20: =SUM(Weekly_Tracker!AV48:AZ48) | U20: =SUM(Weekly_Tracker!BA48:BE48) | V20: =SUM(Weekly_Tracker!BF48:BJ48) | W20: =SUM(Weekly_Tracker!BK48:BO48) | X20: =H20 | Y20: =X20+I20 | Z20: =Y20+J20 | AA20: =Z20+K20 | AB20: 92 | AC20: =IF($B20="","",IF(AB20=0,"chưa nhập FY target",IF(ROUND(G20-AB20,2)=0,"OK","Lệch "&TEXT(G20-AB20,"#,##0"))))
A21: =IF($B21="","",$B21&"|"&$D21) | B21: =IFERROR(INDEX(Team_Master!$C$6:$C$20,4),"") | C21: =IFERROR(INDEX(Team_Master!$G$6:$G$20,4),"") | D21: K1 | E21: Invoiced Value | F21: MVND | G21: =SUM(H21:K21) | H21: =SUM(L21:N21) | I21: =SUM(O21:Q21) | J21: =SUM(R21:T21) | K21: =SUM(U21:W21) | L21: =SUM(Weekly_Tracker!H51:L51) | M21: =SUM(Weekly_Tracker!M51:Q51) | N21: =SUM(Weekly_Tracker!R51:V51) | O21: =SUM(Weekly_Tracker!W51:AA51) | P21: =SUM(Weekly_Tracker!AB51:AF51) | Q21: =SUM(Weekly_Tracker!AG51:AK51) | R21: =SUM(Weekly_Tracker!AL51:AP51) | S21: =SUM(Weekly_Tracker!AQ51:AU51) | T21: =SUM(Weekly_Tracker!AV51:AZ51) | U21: =SUM(Weekly_Tracker!BA51:BE51) | V21: =SUM(Weekly_Tracker!BF51:BJ51) | W21: =SUM(Weekly_Tracker!BK51:BO51) | X21: =H21 | Y21: =X21+I21 | Z21: =Y21+J21 | AA21: =Z21+K21 | AB21: 11200 | AC21: =IF($B21="","",IF(AB21=0,"chưa nhập FY target",IF(ROUND(G21-AB21,2)=0,"OK","Lệch "&TEXT(G21-AB21,"#,##0"))))
A22: =IF($B22="","",$B22&"|"&$D22) | B22: =IFERROR(INDEX(Team_Master!$C$6:$C$20,4),"") | C22: =IFERROR(INDEX(Team_Master!$G$6:$G$20,4),"") | D22: K2 | E22: Key account approach / Site check | F22: Roadshow | G22: =SUM(H22:K22) | H22: =SUM(L22:N22) | I22: =SUM(O22:Q22) | J22: =SUM(R22:T22) | K22: =SUM(U22:W22) | L22: =SUM(Weekly_Tracker!H54:L54) | M22: =SUM(Weekly_Tracker!M54:Q54) | N22: =SUM(Weekly_Tracker!R54:V54) | O22: =SUM(Weekly_Tracker!W54:AA54) | P22: =SUM(Weekly_Tracker!AB54:AF54) | Q22: =SUM(Weekly_Tracker!AG54:AK54) | R22: =SUM(Weekly_Tracker!AL54:AP54) | S22: =SUM(Weekly_Tracker!AQ54:AU54) | T22: =SUM(Weekly_Tracker!AV54:AZ54) | U22: =SUM(Weekly_Tracker!BA54:BE54) | V22: =SUM(Weekly_Tracker!BF54:BJ54) | W22: =SUM(Weekly_Tracker!BK54:BO54) | X22: =H22 | Y22: =X22+I22 | Z22: =Y22+J22 | AA22: =Z22+K22 | AB22: 205 | AC22: =IF($B22="","",IF(AB22=0,"chưa nhập FY target",IF(ROUND(G22-AB22,2)=0,"OK","Lệch "&TEXT(G22-AB22,"#,##0"))))
A23: =IF($B23="","",$B23&"|"&$D23) | B23: =IFERROR(INDEX(Team_Master!$C$6:$C$20,4),"") | C23: =IFERROR(INDEX(Team_Master!$G$6:$G$20,4),"") | D23: K3 | E23: Spec-in Value | F23: MVND | G23: =SUM(H23:K23) | H23: =SUM(L23:N23) | I23: =SUM(O23:Q23) | J23: =SUM(R23:T23) | K23: =SUM(U23:W23) | L23: =SUM(Weekly_Tracker!H57:L57) | M23: =SUM(Weekly_Tracker!M57:Q57) | N23: =SUM(Weekly_Tracker!R57:V57) | O23: =SUM(Weekly_Tracker!W57:AA57) | P23: =SUM(Weekly_Tracker!AB57:AF57) | Q23: =SUM(Weekly_Tracker!AG57:AK57) | R23: =SUM(Weekly_Tracker!AL57:AP57) | S23: =SUM(Weekly_Tracker!AQ57:AU57) | T23: =SUM(Weekly_Tracker!AV57:AZ57) | U23: =SUM(Weekly_Tracker!BA57:BE57) | V23: =SUM(Weekly_Tracker!BF57:BJ57) | W23: =SUM(Weekly_Tracker!BK57:BO57) | X23: =H23 | Y23: =X23+I23 | Z23: =Y23+J23 | AA23: =Z23+K23 | AB23: 4100 | AC23: =IF($B23="","",IF(AB23=0,"chưa nhập FY target",IF(ROUND(G23-AB23,2)=0,"OK","Lệch "&TEXT(G23-AB23,"#,##0"))))
A24: =IF($B24="","",$B24&"|"&$D24) | B24: =IFERROR(INDEX(Team_Master!$C$6:$C$20,4),"") | C24: =IFERROR(INDEX(Team_Master!$G$6:$G$20,4),"") | D24: K4 | E24: Engaged Architect (Submit Design) | F24: D&B | G24: =SUM(H24:K24) | H24: =SUM(L24:N24) | I24: =SUM(O24:Q24) | J24: =SUM(R24:T24) | K24: =SUM(U24:W24) | L24: =SUM(Weekly_Tracker!H60:L60) | M24: =SUM(Weekly_Tracker!M60:Q60) | N24: =SUM(Weekly_Tracker!R60:V60) | O24: =SUM(Weekly_Tracker!W60:AA60) | P24: =SUM(Weekly_Tracker!AB60:AF60) | Q24: =SUM(Weekly_Tracker!AG60:AK60) | R24: =SUM(Weekly_Tracker!AL60:AP60) | S24: =SUM(Weekly_Tracker!AQ60:AU60) | T24: =SUM(Weekly_Tracker!AV60:AZ60) | U24: =SUM(Weekly_Tracker!BA60:BE60) | V24: =SUM(Weekly_Tracker!BF60:BJ60) | W24: =SUM(Weekly_Tracker!BK60:BO60) | X24: =H24 | Y24: =X24+I24 | Z24: =Y24+J24 | AA24: =Z24+K24 | AB24: 78 | AC24: =IF($B24="","",IF(AB24=0,"chưa nhập FY target",IF(ROUND(G24-AB24,2)=0,"OK","Lệch "&TEXT(G24-AB24,"#,##0"))))
A25: =IF($B25="","",$B25&"|"&$D25) | B25: =IFERROR(INDEX(Team_Master!$C$6:$C$20,4),"") | C25: =IFERROR(INDEX(Team_Master!$G$6:$G$20,4),"") | D25: K5 | E25: Spec-in Design (submitted design) | F25: Designs | G25: =SUM(H25:K25) | H25: =SUM(L25:N25) | I25: =SUM(O25:Q25) | J25: =SUM(R25:T25) | K25: =SUM(U25:W25) | L25: =SUM(Weekly_Tracker!H63:L63) | M25: =SUM(Weekly_Tracker!M63:Q63) | N25: =SUM(Weekly_Tracker!R63:V63) | O25: =SUM(Weekly_Tracker!W63:AA63) | P25: =SUM(Weekly_Tracker!AB63:AF63) | Q25: =SUM(Weekly_Tracker!AG63:AK63) | R25: =SUM(Weekly_Tracker!AL63:AP63) | S25: =SUM(Weekly_Tracker!AQ63:AU63) | T25: =SUM(Weekly_Tracker!AV63:AZ63) | U25: =SUM(Weekly_Tracker!BA63:BE63) | V25: =SUM(Weekly_Tracker!BF63:BJ63) | W25: =SUM(Weekly_Tracker!BK63:BO63) | X25: =H25 | Y25: =X25+I25 | Z25: =Y25+J25 | AA25: =Z25+K25 | AB25: 82 | AC25: =IF($B25="","",IF(AB25=0,"chưa nhập FY target",IF(ROUND(G25-AB25,2)=0,"OK","Lệch "&TEXT(G25-AB25,"#,##0"))))
A26: =IF($B26="","",$B26&"|"&$D26) | B26: =IFERROR(INDEX(Team_Master!$C$6:$C$20,5),"") | C26: =IFERROR(INDEX(Team_Master!$G$6:$G$20,5),"") | D26: K1 | E26: Invoiced Value | F26: MVND | G26: =SUM(H26:K26) | H26: =SUM(L26:N26) | I26: =SUM(O26:Q26) | J26: =SUM(R26:T26) | K26: =SUM(U26:W26) | L26: =SUM(Weekly_Tracker!H66:L66) | M26: =SUM(Weekly_Tracker!M66:Q66) | N26: =SUM(Weekly_Tracker!R66:V66) | O26: =SUM(Weekly_Tracker!W66:AA66) | P26: =SUM(Weekly_Tracker!AB66:AF66) | Q26: =SUM(Weekly_Tracker!AG66:AK66) | R26: =SUM(Weekly_Tracker!AL66:AP66) | S26: =SUM(Weekly_Tracker!AQ66:AU66) | T26: =SUM(Weekly_Tracker!AV66:AZ66) | U26: =SUM(Weekly_Tracker!BA66:BE66) | V26: =SUM(Weekly_Tracker!BF66:BJ66) | W26: =SUM(Weekly_Tracker!BK66:BO66) | X26: =H26 | Y26: =X26+I26 | Z26: =Y26+J26 | AA26: =Z26+K26 | AB26: 8600 | AC26: =IF($B26="","",IF(AB26=0,"chưa nhập FY target",IF(ROUND(G26-AB26,2)=0,"OK","Lệch "&TEXT(G26-AB26,"#,##0"))))
A27: =IF($B27="","",$B27&"|"&$D27) | B27: =IFERROR(INDEX(Team_Master!$C$6:$C$20,5),"") | C27: =IFERROR(INDEX(Team_Master!$G$6:$G$20,5),"") | D27: K2 | E27: Key account approach / Site check | F27: Roadshow | G27: =SUM(H27:K27) | H27: =SUM(L27:N27) | I27: =SUM(O27:Q27) | J27: =SUM(R27:T27) | K27: =SUM(U27:W27) | L27: =SUM(Weekly_Tracker!H69:L69) | M27: =SUM(Weekly_Tracker!M69:Q69) | N27: =SUM(Weekly_Tracker!R69:V69) | O27: =SUM(Weekly_Tracker!W69:AA69) | P27: =SUM(Weekly_Tracker!AB69:AF69) | Q27: =SUM(Weekly_Tracker!AG69:AK69) | R27: =SUM(Weekly_Tracker!AL69:AP69) | S27: =SUM(Weekly_Tracker!AQ69:AU69) | T27: =SUM(Weekly_Tracker!AV69:AZ69) | U27: =SUM(Weekly_Tracker!BA69:BE69) | V27: =SUM(Weekly_Tracker!BF69:BJ69) | W27: =SUM(Weekly_Tracker!BK69:BO69) | X27: =H27 | Y27: =X27+I27 | Z27: =Y27+J27 | AA27: =Z27+K27 | AB27: 190 | AC27: =IF($B27="","",IF(AB27=0,"chưa nhập FY target",IF(ROUND(G27-AB27,2)=0,"OK","Lệch "&TEXT(G27-AB27,"#,##0"))))
A28: =IF($B28="","",$B28&"|"&$D28) | B28: =IFERROR(INDEX(Team_Master!$C$6:$C$20,5),"") | C28: =IFERROR(INDEX(Team_Master!$G$6:$G$20,5),"") | D28: K3 | E28: Spec-in Value | F28: MVND | G28: =SUM(H28:K28) | H28: =SUM(L28:N28) | I28: =SUM(O28:Q28) | J28: =SUM(R28:T28) | K28: =SUM(U28:W28) | L28: =SUM(Weekly_Tracker!H72:L72) | M28: =SUM(Weekly_Tracker!M72:Q72) | N28: =SUM(Weekly_Tracker!R72:V72) | O28: =SUM(Weekly_Tracker!W72:AA72) | P28: =SUM(Weekly_Tracker!AB72:AF72) | Q28: =SUM(Weekly_Tracker!AG72:AK72) | R28: =SUM(Weekly_Tracker!AL72:AP72) | S28: =SUM(Weekly_Tracker!AQ72:AU72) | T28: =SUM(Weekly_Tracker!AV72:AZ72) | U28: =SUM(Weekly_Tracker!BA72:BE72) | V28: =SUM(Weekly_Tracker!BF72:BJ72) | W28: =SUM(Weekly_Tracker!BK72:BO72) | X28: =H28 | Y28: =X28+I28 | Z28: =Y28+J28 | AA28: =Z28+K28 | AB28: 3400 | AC28: =IF($B28="","",IF(AB28=0,"chưa nhập FY target",IF(ROUND(G28-AB28,2)=0,"OK","Lệch "&TEXT(G28-AB28,"#,##0"))))
A29: =IF($B29="","",$B29&"|"&$D29) | B29: =IFERROR(INDEX(Team_Master!$C$6:$C$20,5),"") | C29: =IFERROR(INDEX(Team_Master!$G$6:$G$20,5),"") | D29: K4 | E29: Engaged Architect (Submit Design) | F29: D&B | G29: =SUM(H29:K29) | H29: =SUM(L29:N29) | I29: =SUM(O29:Q29) | J29: =SUM(R29:T29) | K29: =SUM(U29:W29) | L29: =SUM(Weekly_Tracker!H75:L75) | M29: =SUM(Weekly_Tracker!M75:Q75) | N29: =SUM(Weekly_Tracker!R75:V75) | O29: =SUM(Weekly_Tracker!W75:AA75) | P29: =SUM(Weekly_Tracker!AB75:AF75) | Q29: =SUM(Weekly_Tracker!AG75:AK75) | R29: =SUM(Weekly_Tracker!AL75:AP75) | S29: =SUM(Weekly_Tracker!AQ75:AU75) | T29: =SUM(Weekly_Tracker!AV75:AZ75) | U29: =SUM(Weekly_Tracker!BA75:BE75) | V29: =SUM(Weekly_Tracker!BF75:BJ75) | W29: =SUM(Weekly_Tracker!BK75:BO75) | X29: =H29 | Y29: =X29+I29 | Z29: =Y29+J29 | AA29: =Z29+K29 | AB29: 65 | AC29: =IF($B29="","",IF(AB29=0,"chưa nhập FY target",IF(ROUND(G29-AB29,2)=0,"OK","Lệch "&TEXT(G29-AB29,"#,##0"))))
A30: =IF($B30="","",$B30&"|"&$D30) | B30: =IFERROR(INDEX(Team_Master!$C$6:$C$20,5),"") | C30: =IFERROR(INDEX(Team_Master!$G$6:$G$20,5),"") | D30: K5 | E30: Spec-in Design (submitted design) | F30: Designs | G30: =SUM(H30:K30) | H30: =SUM(L30:N30) | I30: =SUM(O30:Q30) | J30: =SUM(R30:T30) | K30: =SUM(U30:W30) | L30: =SUM(Weekly_Tracker!H78:L78) | M30: =SUM(Weekly_Tracker!M78:Q78) | N30: =SUM(Weekly_Tracker!R78:V78) | O30: =SUM(Weekly_Tracker!W78:AA78) | P30: =SUM(Weekly_Tracker!AB78:AF78) | Q30: =SUM(Weekly_Tracker!AG78:AK78) | R30: =SUM(Weekly_Tracker!AL78:AP78) | S30: =SUM(Weekly_Tracker!AQ78:AU78) | T30: =SUM(Weekly_Tracker!AV78:AZ78) | U30: =SUM(Weekly_Tracker!BA78:BE78) | V30: =SUM(Weekly_Tracker!BF78:BJ78) | W30: =SUM(Weekly_Tracker!BK78:BO78) | X30: =H30 | Y30: =X30+I30 | Z30: =Y30+J30 | AA30: =Z30+K30 | AB30: 68 | AC30: =IF($B30="","",IF(AB30=0,"chưa nhập FY target",IF(ROUND(G30-AB30,2)=0,"OK","Lệch "&TEXT(G30-AB30,"#,##0"))))
A31: =IF($B31="","",$B31&"|"&$D31) | B31: =IFERROR(INDEX(Team_Master!$C$6:$C$20,6),"") | C31: =IFERROR(INDEX(Team_Master!$G$6:$G$20,6),"") | D31: K1 | E31: Invoiced Value | F31: MVND | G31: =SUM(H31:K31) | H31: =SUM(L31:N31) | I31: =SUM(O31:Q31) | J31: =SUM(R31:T31) | K31: =SUM(U31:W31) | L31: =SUM(Weekly_Tracker!H81:L81) | M31: =SUM(Weekly_Tracker!M81:Q81) | N31: =SUM(Weekly_Tracker!R81:V81) | O31: =SUM(Weekly_Tracker!W81:AA81) | P31: =SUM(Weekly_Tracker!AB81:AF81) | Q31: =SUM(Weekly_Tracker!AG81:AK81) | R31: =SUM(Weekly_Tracker!AL81:AP81) | S31: =SUM(Weekly_Tracker!AQ81:AU81) | T31: =SUM(Weekly_Tracker!AV81:AZ81) | U31: =SUM(Weekly_Tracker!BA81:BE81) | V31: =SUM(Weekly_Tracker!BF81:BJ81) | W31: =SUM(Weekly_Tracker!BK81:BO81) | X31: =H31 | Y31: =X31+I31 | Z31: =Y31+J31 | AA31: =Z31+K31 | AB31: 7900 | AC31: =IF($B31="","",IF(AB31=0,"chưa nhập FY target",IF(ROUND(G31-AB31,2)=0,"OK","Lệch "&TEXT(G31-AB31,"#,##0"))))
A32: =IF($B32="","",$B32&"|"&$D32) | B32: =IFERROR(INDEX(Team_Master!$C$6:$C$20,6),"") | C32: =IFERROR(INDEX(Team_Master!$G$6:$G$20,6),"") | D32: K2 | E32: Key account approach / Site check | F32: Roadshow | G32: =SUM(H32:K32) | H32: =SUM(L32:N32) | I32: =SUM(O32:Q32) | J32: =SUM(R32:T32) | K32: =SUM(U32:W32) | L32: =SUM(Weekly_Tracker!H84:L84) | M32: =SUM(Weekly_Tracker!M84:Q84) | N32: =SUM(Weekly_Tracker!R84:V84) | O32: =SUM(Weekly_Tracker!W84:AA84) | P32: =SUM(Weekly_Tracker!AB84:AF84) | Q32: =SUM(Weekly_Tracker!AG84:AK84) | R32: =SUM(Weekly_Tracker!AL84:AP84) | S32: =SUM(Weekly_Tracker!AQ84:AU84) | T32: =SUM(Weekly_Tracker!AV84:AZ84) | U32: =SUM(Weekly_Tracker!BA84:BE84) | V32: =SUM(Weekly_Tracker!BF84:BJ84) | W32: =SUM(Weekly_Tracker!BK84:BO84) | X32: =H32 | Y32: =X32+I32 | Z32: =Y32+J32 | AA32: =Z32+K32 | AB32: 180 | AC32: =IF($B32="","",IF(AB32=0,"chưa nhập FY target",IF(ROUND(G32-AB32,2)=0,"OK","Lệch "&TEXT(G32-AB32,"#,##0"))))
A33: =IF($B33="","",$B33&"|"&$D33) | B33: =IFERROR(INDEX(Team_Master!$C$6:$C$20,6),"") | C33: =IFERROR(INDEX(Team_Master!$G$6:$G$20,6),"") | D33: K3 | E33: Spec-in Value | F33: MVND | G33: =SUM(H33:K33) | H33: =SUM(L33:N33) | I33: =SUM(O33:Q33) | J33: =SUM(R33:T33) | K33: =SUM(U33:W33) | L33: =SUM(Weekly_Tracker!H87:L87) | M33: =SUM(Weekly_Tracker!M87:Q87) | N33: =SUM(Weekly_Tracker!R87:V87) | O33: =SUM(Weekly_Tracker!W87:AA87) | P33: =SUM(Weekly_Tracker!AB87:AF87) | Q33: =SUM(Weekly_Tracker!AG87:AK87) | R33: =SUM(Weekly_Tracker!AL87:AP87) | S33: =SUM(Weekly_Tracker!AQ87:AU87) | T33: =SUM(Weekly_Tracker!AV87:AZ87) | U33: =SUM(Weekly_Tracker!BA87:BE87) | V33: =SUM(Weekly_Tracker!BF87:BJ87) | W33: =SUM(Weekly_Tracker!BK87:BO87) | X33: =H33 | Y33: =X33+I33 | Z33: =Y33+J33 | AA33: =Z33+K33 | AB33: 3100 | AC33: =IF($B33="","",IF(AB33=0,"chưa nhập FY target",IF(ROUND(G33-AB33,2)=0,"OK","Lệch "&TEXT(G33-AB33,"#,##0"))))
A34: =IF($B34="","",$B34&"|"&$D34) | B34: =IFERROR(INDEX(Team_Master!$C$6:$C$20,6),"") | C34: =IFERROR(INDEX(Team_Master!$G$6:$G$20,6),"") | D34: K4 | E34: Engaged Architect (Submit Design) | F34: D&B | G34: =SUM(H34:K34) | H34: =SUM(L34:N34) | I34: =SUM(O34:Q34) | J34: =SUM(R34:T34) | K34: =SUM(U34:W34) | L34: =SUM(Weekly_Tracker!H90:L90) | M34: =SUM(Weekly_Tracker!M90:Q90) | N34: =SUM(Weekly_Tracker!R90:V90) | O34: =SUM(Weekly_Tracker!W90:AA90) | P34: =SUM(Weekly_Tracker!AB90:AF90) | Q34: =SUM(Weekly_Tracker!AG90:AK90) | R34: =SUM(Weekly_Tracker!AL90:AP90) | S34: =SUM(Weekly_Tracker!AQ90:AU90) | T34: =SUM(Weekly_Tracker!AV90:AZ90) | U34: =SUM(Weekly_Tracker!BA90:BE90) | V34: =SUM(Weekly_Tracker!BF90:BJ90) | W34: =SUM(Weekly_Tracker!BK90:BO90) | X34: =H34 | Y34: =X34+I34 | Z34: =Y34+J34 | AA34: =Z34+K34 | AB34: 60 | AC34: =IF($B34="","",IF(AB34=0,"chưa nhập FY target",IF(ROUND(G34-AB34,2)=0,"OK","Lệch "&TEXT(G34-AB34,"#,##0"))))
A35: =IF($B35="","",$B35&"|"&$D35) | B35: =IFERROR(INDEX(Team_Master!$C$6:$C$20,6),"") | C35: =IFERROR(INDEX(Team_Master!$G$6:$G$20,6),"") | D35: K5 | E35: Spec-in Design (submitted design) | F35: Designs | G35: =SUM(H35:K35) | H35: =SUM(L35:N35) | I35: =SUM(O35:Q35) | J35: =SUM(R35:T35) | K35: =SUM(U35:W35) | L35: =SUM(Weekly_Tracker!H93:L93) | M35: =SUM(Weekly_Tracker!M93:Q93) | N35: =SUM(Weekly_Tracker!R93:V93) | O35: =SUM(Weekly_Tracker!W93:AA93) | P35: =SUM(Weekly_Tracker!AB93:AF93) | Q35: =SUM(Weekly_Tracker!AG93:AK93) | R35: =SUM(Weekly_Tracker!AL93:AP93) | S35: =SUM(Weekly_Tracker!AQ93:AU93) | T35: =SUM(Weekly_Tracker!AV93:AZ93) | U35: =SUM(Weekly_Tracker!BA93:BE93) | V35: =SUM(Weekly_Tracker!BF93:BJ93) | W35: =SUM(Weekly_Tracker!BK93:BO93) | X35: =H35 | Y35: =X35+I35 | Z35: =Y35+J35 | AA35: =Z35+K35 | AB35: 62 | AC35: =IF($B35="","",IF(AB35=0,"chưa nhập FY target",IF(ROUND(G35-AB35,2)=0,"OK","Lệch "&TEXT(G35-AB35,"#,##0"))))
A36: =IF($B36="","",$B36&"|"&$D36) | B36: =IFERROR(INDEX(Team_Master!$C$6:$C$20,7),"") | C36: =IFERROR(INDEX(Team_Master!$G$6:$G$20,7),"") | D36: K1 | E36: Invoiced Value | F36: MVND | G36: =SUM(H36:K36) | H36: =SUM(L36:N36) | I36: =SUM(O36:Q36) | J36: =SUM(R36:T36) | K36: =SUM(U36:W36) | L36: =SUM(Weekly_Tracker!H96:L96) | M36: =SUM(Weekly_Tracker!M96:Q96) | N36: =SUM(Weekly_Tracker!R96:V96) | O36: =SUM(Weekly_Tracker!W96:AA96) | P36: =SUM(Weekly_Tracker!AB96:AF96) | Q36: =SUM(Weekly_Tracker!AG96:AK96) | R36: =SUM(Weekly_Tracker!AL96:AP96) | S36: =SUM(Weekly_Tracker!AQ96:AU96) | T36: =SUM(Weekly_Tracker!AV96:AZ96) | U36: =SUM(Weekly_Tracker!BA96:BE96) | V36: =SUM(Weekly_Tracker!BF96:BJ96) | W36: =SUM(Weekly_Tracker!BK96:BO96) | X36: =H36 | Y36: =X36+I36 | Z36: =Y36+J36 | AA36: =Z36+K36 | AC36: =IF($B36="","",IF(AB36=0,"chưa nhập FY target",IF(ROUND(G36-AB36,2)=0,"OK","Lệch "&TEXT(G36-AB36,"#,##0"))))
