Workbook

Sheet Huong_dan
B1: BẢN DỰ TOÁN TÀI CHÍNH MCN — 36 THÁNG
B4: Mục đích | C4: Bản dự toán phục vụ gọi vốn cho mô hình MCN: (1) build và grow IP người thật, (2) dùng IP bán hàng livestream ăn chia sẻ doanh thu, (3) scale bằng IP AI.
B5: Đơn vị tiền tệ | C5: TRIỆU VND ở mọi sheet. 1.000 = 1 tỷ đồng.
B6: Kỳ dự báo | C6: 36 thang, bat dau tu thang dat o Gia_dinh!B5 (mac dinh 01/2027).
B7: Cách dùng | C7: Chỉ sửa các ô màu vàng ở sheet Gia_dinh. Đổi kịch bản tại Gia_dinh!B4 (Downside / Base / Upside) — toàn bộ mô hình tự tính lại.
B9: CÁC SHEET
B10: Gia_dinh | C10: Toàn bộ tham số, ba cột giá trị cho ba kịch bản, cột ĐANG ÁP DỤNG là giá trị mô hình đang dùng. Cột cuối ghi căn cứ của từng giả định.
B11: Don_vi_IP | C11: Unit economics của MỘT IP người thật theo tuổi 0-36 tháng: doanh thu, từng dòng chi phí, lãi gộp, lãi gộp luỹ kế, đỉnh vốn và tháng hoà vốn của một IP.
B12: Don_vi_IP_AI | C12: Unit economics của MỘT IP AI, cùng cấu trúc.
B13: Doi_hinh | C13: Mô hình cohort: số IP ở từng tuổi trong từng tháng = số IP ký mới của tháng tương ứng nhân tỷ lệ sống sót. Đây là nơi cơ chế sàng lọc (cửa T3, cửa T9, rời bỏ hàng năm) chạy.
B14: Doanh_thu | C14: GMV gộp, GMV ròng, và ba dòng doanh thu: hoa hồng affiliate IP người thật, phí booking, hoa hồng affiliate IP AI.
B15: Chi_phi | C15: Chi phí trực tiếp (lấy từ unit economics nhân đội hình) và chi phí tầng công ty.
B16: PnL | C16: Kết quả kinh doanh theo tháng và bảng tổng hợp theo năm 1/2/3.
B17: Dong_tien | C17: Dòng tiền theo tháng, có độ trễ thu tiền (DSO) và trả talent (DPO), nhu cầu vốn luỹ kế và runway.
B18: Kich_ban | C18: Tóm tắt năm kịch bản, gồm hai bài kiểm định rủi ro.
B20: BA ĐIỀU CẦN ĐỌC KỸ
B21: 1. Phí nền tảng | C21: Phí TikTok Shop 12,5% (Marketplace) / 15,5% (Mall) do NGƯỜI BÁN chịu, không phải chi phí của MCN, nên không xuất hiện trong bảng này. Chỉ đưa vào nếu MCN tự bán hàng của mình.
B22: 2. Doanh thu ghi nhận | C22: Doanh thu MCN = hoa hồng nhãn hàng trả, ghi nhận TRƯỚC khi chia cho talent. Phần chia cho talent nằm trong giá vốn. GMV không phải doanh thu.
B23: 3. Kịch bản downside | C23: Một IP chạy dưới ~35tr GMV/phiên ở trạng thái ổn định thì không bao giờ hoàn vốn: càng nuôi lâu càng lỗ. Vì vậy mô hình có hai cửa sàng lọc (tuổi 3 và tuổi 9) và một kịch bản 'Downside + cơ chế cắt' cho thấy việc dừng tuyển sớm giảm thiệt hại thế nào.
B25: GIỚI HẠN CỦA BẢN DỰ TOÁN
B26: Giả định, không phải số thực | C26: Mọi con số là giả định làm việc, chưa có số liệu vận hành thực tế. Cột 'Căn cứ / nguồn' ở sheet Gia_dinh ghi rõ từng dòng đến từ đâu: 'Unit econ' là bộ giả định đơn vị đã chốt, 'Dự toán' là giả định bổ sung của bản dự toán này.
B27: Tham số nhạy nhất | C27: Theo thứ tự ảnh hưởng: GMV/phiên ổn định, tỷ lệ huỷ & hoàn hàng, hoa hồng affiliate, tỷ lệ chia cho talent, tỷ lệ rơi rụng tại cửa sàng lọc, GMV/giờ của IP AI. Có số liệu thực dòng nào thì thay dòng đó trước.
B28: Kịch bản Upside | C28: Upside giả định MỌI IP đều đạt 110tr GMV/phiên — mức của nhóm creator đầu bảng. Đây là trần lý thuyết để đo độ nhạy, không nên dùng làm cam kết với nhà đầu tư.
B29: Chưa mô hình hoá | C29: Lãi vay, biến động tỷ giá, thuế TNCN của talent, dự phòng công nợ khó đòi, và chi phí pháp lý cho tranh chấp hợp đồng độc quyền.
B30: Thuế TNDN | C30: Tính 20% trên thu nhập chịu thuế sau khi bù hết lỗ luỹ kế, nộp trong chính tháng phát sinh. Thực tế tạm nộp theo quý — chênh lệch này không đổi kết luận.
B32: Tạo từ finance/build_model.py + finance/params.py. Sửa tham số trong params.py rồi chạy lại script để sinh bản mới, hoặc sửa trực tiếp ở Gia_dinh.

Sheet Kich_ban
A1: TÓM TẮT KỊCH BẢN (triệu VND)
A2: Bảng này là ảnh chụp tính sẵn cho cả năm kịch bản. Các sheet còn lại chạy theo kịch bản chọn ở Gia_dinh!B4 — đổi ô đó sẽ thấy số ở đây KHÔNG đổi, đây là chủ ý.
B4: Chỉ tiêu | C4: Downside | D4: Base | E4: Upside | F4: Base + sốc tầng AI | G4: Downside + cơ chế cắt
C5: GMV/phiên ổn định 30tr, huỷ/hoàn 25%, hoa hồng 15% | D5: GMV/phiên ổn định 60tr, huỷ/hoàn 18%, hoa hồng 20% | E5: GMV/phiên ổn định 110tr, huỷ/hoàn 13%, hoa hồng 24% | F5: Kiểm định: nền tảng siết nội dung AI, tầng AI mất 60% GMV trong 1 quý từ T25 | G5: Dừng tuyển IP mới từ T7 và không triển khai tầng AI khi thấy unit economics âm
B6: Doanh thu Nam 1 | C6: 1599.5915 | D6: 6157.121 | E6: 28331.724 | F6: 6157.121 | G6: 1363.3415
B7: Doanh thu Nam 2 | C7: 9486.5247 | D7: 60472.994 | E7: 342845.49 | F7: 60472.994 | G7: 2995.2116
B8: Doanh thu Nam 3 | C8: 24101.22 | D8: 162790.08 | E8: 875699.15 | F8: 155640.52 | G8: 2266.6493
B9: GMV gop Nam 3 | C9: 196599.33 | D9: 1017232.4 | E9: 3782691.2 | F9: 971401.82 | G9: 20147.993
B10: Doanh thu tu IP AI — Nam 3 | C10: 11902.771 | D10: 78702.43 | E10: 373592.23 | F10: 71552.865 | G10: 0
B11: Loi nhuan gop Nam 3 | C11: -13289.677 | D11: 41258.605 | E11: 499715.05 | F11: 35896.431 | G11: -579.25481
B12: EBITDA Nam 1 | C12: -13062.892 | D12: -12473.98 | E12: -5228.4454 | F12: -12473.98 | G12: -10717.23
B13: EBITDA Nam 2 | C13: -20245.005 | D13: -6537.1163 | E13: 155388.24 | F13: -6537.1163 | G13: -7712.7593
B14: EBITDA Nam 3 | C14: -24317.714 | D14: 23157.402 | E14: 455770.32 | F14: 18009.716 | G14: -7352.2543
B15: Bien EBITDA Nam 3 | C15: -1.0089827 | D15: 0.14225315 | E15: 0.5204645 | F15: 0.11571354 | G15: -3.2436665
B16: Loi nhuan sau thue luy ke 3 nam | C16: -57761.611 | D16: 3178.3782 | E16: 484560.63 | F16: -1174.7138 | G16: -25878.243
B17: Thang EBITDA duong dau tien | C17: Không đạt trong 36 tháng | D17: 22 | E17: 11 | F17: 22 | G17: Không đạt trong 36 tháng
B18: Thang dong tien duong dau tien | C18: Không đạt trong 36 tháng | D18: 29 | E18: 13 | F18: 25 | G18: Không đạt trong 36 tháng
B19: Nhu cau von dinh diem | C19: 62812.072 | D19: 31799.756 | E19: 12982.421 | F19: 36765.643 | G19: 26187.475
B20: Tien cuoi ky thang 36 | C20: -20812.072 | D20: 19612.419 | E20: 439317.31 | F20: 15259.327 | G20: 15812.525
B21: So IP nguoi that hoat dong cuoi ky | C21: 26.268496 | D21: 57.857367 | E21: 97.847322 | F21: 57.857367 | G21: 2.444272
B22: So IP AI hoat dong cuoi ky | C22: 62.289824 | D22: 141.50653 | E22: 266.81829 | F22: 141.50653 | G22: 0
B23: Tong nhan su tang cong ty cuoi ky | C23: 16 | D23: 24 | E23: 35 | F23: 24 | G23: 8
B25: ĐỐI CHIẾU VỚI MÔ HÌNH ĐANG CHẠY (công thức sống)
B26: Kịch bản đang chạy ở Gia_dinh!B4 | C26: =Gia_dinh!$B$4
B27: Doanh thu Năm 1 | C27: =PnL!C49
B28: Doanh thu Năm 2 | C28: =PnL!D49
B29: Doanh thu Năm 3 | C29: =PnL!E49
B30: EBITDA Năm 3 | C30: =PnL!E55
B31: Nhu cầu vốn đỉnh điểm | C31: =MAX(Dong_tien!D25:AM25)
B32: Tiền cuối kỳ tháng 36 | C32: =Dong_tien!AM21
B34: Nếu cột này không trùng với cột kịch bản tương ứng ở trên thì một giả định đã bị sửa tay.

Sheet Gia_dinh
A1: MÔ HÌNH TÀI CHÍNH MCN — BẢNG GIẢ ĐỊNH
A2: Mọi ô màu vàng là ô nhập liệu. Đổi kịch bản ở B4, toàn bộ mô hình tự tính lại.
A3: Đơn vị tiền tệ | B3: triệu VND
A4: KỊCH BẢN ĐANG CHẠY | B4: Base | C4: <- chọn Downside / Base / Upside
A5: Tháng bắt đầu dự báo | B5: 46388
A6: Chỉ số kịch bản | B6: =MATCH($B$4,$C$8:$E$8,0)
A8: Tham số | B8: Đơn vị | C8: Downside | D8: Base | E8: Upside | F8: ĐANG ÁP DỤNG | G8: Căn cứ / nguồn
A9: A. KẾ HOẠCH ĐỘI HÌNH IP (quyết định của công ty)
A10: Số IP người thật ký mới / tháng — T1-T6 | B10: IP/tháng | C10: 2 | D10: 2 | E10: 3 | F10: =INDEX($C10:$E10,1,$B$6) | G10: Dự toán: năng lực casting + ươm tạo giai đoạn đầu
A11: Số IP người thật ký mới / tháng — T7-T18 | B11: IP/tháng | C11: 2 | D11: 3 | E11: 4 | F11: =INDEX($C11:$E11,1,$B$6) | G11: Dự toán: tăng khi quy trình ươm tạo chạy ổn định
A12: Số IP người thật ký mới / tháng — T19-T36 | B12: IP/tháng | C12: 2 | D12: 3 | E12: 4 | F12: =INDEX($C12:$E12,1,$B$6) | G12: Dự toán
A13: Tháng bắt đầu ra mắt IP AI | B13: tháng | C13: 15 | D13: 13 | E13: 11 | F13: =INDEX($C13:$E13,1,$B$6) | G13: Dự toán: sau khi có đủ dữ liệu bán hàng từ IP người thật
A14: Số IP AI ra mắt / tháng — 12 tháng đầu | B14: IP/tháng | C14: 3 | D14: 5 | E14: 8 | F14: =INDEX($C14:$E14,1,$B$6) | G14: Dự toán
A15: Số IP AI ra mắt / tháng — giai đoạn sau | B15: IP/tháng | C15: 5 | D15: 10 | E15: 16 | F15: =INDEX($C15:$E15,1,$B$6) | G15: Dự toán
A17: B. CƠ CHẾ SÀNG LỌC & RƠI RỤNG IP NGƯỜI THẬT
A18: Cửa sàng lọc 1 — tuổi IP (tháng) | B18: tháng | C18: 3 | D18: 3 | E18: 3 | F18: =INDEX($C18:$E18,1,$B$6) | G18: Unit econ: chuyển cửa về T2 tiết kiệm ~126tr mỗi 10 IP tuyển
A19: % IP bị loại tại cửa 1 | B19: % | C19: 0.45 | D19: 0.3 | E19: 0.2 | F19: =INDEX($C19:$E19,1,$B$6) | G19: Unit econ mục 6: 30% IP bị loại ở cửa tháng 3 (base)
A20: Cửa sàng lọc 2 — tuổi IP (tháng) | B20: tháng | C20: 9 | D20: 9 | E20: 9 | F20: =INDEX($C20:$E20,1,$B$6) | G20: Dự toán: cắt IP chưa đạt lãi gộp dương trước khi vào ổn định
A21: % IP bị loại tại cửa 2 | B21: % | C21: 0.35 | D21: 0.15 | E21: 0.05 | F21: =INDEX($C21:$E21,1,$B$6) | G21: Dự toán: cơ chế cắt bắt buộc vì IP dưới ~35tr GMV/phiên không bao giờ hoàn vốn
A22: Tỷ lệ IP rời bỏ / năm sau khi ổn định | B22: %/năm | C22: 0.25 | D22: 0.15 | E22: 0.1 | F22: =INDEX($C22:$E22,1,$B$6) | G22: Unit econ: 15%/năm (base)
A23: Tỷ lệ IP AI ngừng hoạt động / năm | B23: %/năm | C23: 0.4 | D23: 0.25 | E23: 0.15 | F23: =INDEX($C23:$E23,1,$B$6) | G23: Dự toán: rủi ro nền tảng siết nội dung AI
A25: C. DOANH THU CHUNG
A26: Tỷ lệ huỷ & hoàn hàng — IP người thật | B26: % GMV gộp | C26: 0.25 | D26: 0.18 | E26: 0.13 | F26: =INDEX($C26:$E26,1,$B$6) | G26: Unit econ mục 4: base 18% (10% huỷ + 8% hoàn)
A27: Hoa hồng affiliate từ nhãn hàng | B27: % GMV ròng | C27: 0.15 | D27: 0.2 | E27: 0.24 | F27: =INDEX($C27:$E27,1,$B$6) | G27: Unit econ mục 1: dải 12-30%, tuỳ ngành hàng
A28: Phí booking cố định mỗi phiên | B28: triệu/phiên | C28: 0 | D28: 0 | E28: 10 | F28: =INDEX($C28:$E28,1,$B$6) | G28: Unit econ: 5-15tr/phiên với IP đã có tên tuổi; base để 0
A29: Tuổi IP bắt đầu thu phí booking | B29: tháng | C29: 10 | D29: 10 | E29: 10 | F29: =INDEX($C29:$E29,1,$B$6) | G29: Unit econ mục 1
A30: Thưởng đạt target của nhãn hàng/sàn | B30: % GMV ròng | C30: 0 | D30: 0 | E30: 0.02 | F30: =INDEX($C30:$E30,1,$B$6) | G30: Unit econ: 1-3% theo chiến dịch; base để 0
A32: D. VÒNG ĐỜI 1 IP NGƯỜI THẬT
A33: Chi phí dựng IP một lần (tuổi 0) | B33: triệu/IP | C33: 80 | D33: 60 | E33: 55 | F33: =INDEX($C33:$E33,1,$B$6) | G33: Unit econ mục 3: casting 8 + đào tạo 15 + nhận diện 20 + thưởng ký 15 + pháp lý 2
A34: GMV/phiên — ươm (tuổi 1-3) | B34: triệu | C34: 5 | D34: 10 | E34: 18 | F34: =INDEX($C34:$E34,1,$B$6) | G34: Unit econ mục 2
A35: Số phiên/tháng — ươm | B35: phiên | C35: 12 | D35: 12 | E35: 12 | F35: =INDEX($C35:$E35,1,$B$6) | G35: Unit econ mục 2
A36: GMV/phiên — tăng trưởng sớm (tuổi 4-6) | B36: triệu | C36: 12.5 | D36: 25 | E36: 46 | F36: =INDEX($C36:$E36,1,$B$6) | G36: Unit econ mục 2
A37: Số phiên/tháng — tăng trưởng sớm | B37: phiên | C37: 16 | D37: 16 | E37: 16 | F37: =INDEX($C37:$E37,1,$B$6) | G37: Unit econ mục 2
A38: GMV/phiên — tăng trưởng (tuổi 7-9) | B38: triệu | C38: 20 | D38: 40 | E38: 73 | F38: =INDEX($C38:$E38,1,$B$6) | G38: Unit econ mục 2
A39: Số phiên/tháng — tăng trưởng | B39: phiên | C39: 18 | D39: 18 | E39: 18 | F39: =INDEX($C39:$E39,1,$B$6) | G39: Unit econ mục 2
A40: GMV/phiên — ổn định (tuổi 10+) | B40: triệu | C40: 30 | D40: 60 | E40: 110 | F40: =INDEX($C40:$E40,1,$B$6) | G40: Unit econ mục 8: biến quyết định sống còn, dưới 35tr không hoàn vốn
A41: Số phiên/tháng — ổn định | B41: phiên | C41: 20 | D41: 20 | E41: 20 | F41: =INDEX($C41:$E41,1,$B$6) | G41: Unit econ mục 2: 4 giờ/phiên
A43: E. CHI PHÍ 1 IP NGƯỜI THẬT / THÁNG
A44: Lương cứng talent — ươm (tuổi 1-3) | B44: triệu/tháng | C44: 12 | D44: 12 | E44: 12 | F44: =INDEX($C44:$E44,1,$B$6) | G44: Unit econ mục 3
A45: Lương cứng talent — từ tuổi 4 | B45: triệu/tháng | C45: 15 | D45: 15 | E45: 15 | F45: =INDEX($C45:$E45,1,$B$6) | G45: Unit econ mục 3: thị trường thuê ngoài 15-50tr
...

Sheet Don_vi_IP
A1: UNIT ECONOMICS — MỘT IP NGƯỜI THẬT THEO TUỔI (triệu VND)
A2: Tuổi 0 = tháng casting/dựng IP. Mỗi dòng dưới đây là kết quả của MỘT IP sống sót đến tuổi đó.
B4: Tuổi (tháng) | C4: Giai đoạn | D4: Tỷ lệ sống sót | E4: GMV/phiên | F4: Số phiên | G4: GMV gộp | H4: GMV ròng | I4: Hoa hồng affiliate | J4: Phí booking | K4: Thưởng target | L4: DOANH THU MCN | M4: Chia hoa hồng talent | N4: Lương cứng talent | O4: Ê-kíp | P4: Studio | Q4: Quảng cáo kéo view | R4: Mẫu SP & khác | S4: Chi phí dựng IP | T4: TỔNG CHI PHÍ TRỰC TIẾP | U4: LÃI GỘP | V4: Lãi gộp luỹ kế / IP
B5: 0 | C5: Dựng IP | D5: 1 | E5: =IF(0=0,0,IF(0<=3,Gia_dinh!$F$34,IF(0<=6,Gia_dinh!$F$36,IF(0<=9,Gia_dinh!$F$38,Gia_dinh!$F$40)))) | F5: =IF(0=0,0,IF(0<=3,Gia_dinh!$F$35,IF(0<=6,Gia_dinh!$F$37,IF(0<=9,Gia_dinh!$F$39,Gia_dinh!$F$41)))) | G5: =E5*F5 | H5: =G5*(1-Gia_dinh!$F$26) | I5: =H5*Gia_dinh!$F$27 | J5: =IF(0>=Gia_dinh!$F$29,Gia_dinh!$F$28*F5,0) | K5: =H5*Gia_dinh!$F$30 | L5: =SUM(I5:K5) | M5: =L5*Gia_dinh!$F$46 | N5: =IF(0=0,0,IF(0<=3,Gia_dinh!$F$44,Gia_dinh!$F$45)) | O5: =IF(0=0,0,Gia_dinh!$F$47) | P5: =IF(0=0,0,Gia_dinh!$F$48) | Q5: =H5*IF(0=0,0,IF(0<=3,Gia_dinh!$F$49,IF(0<=6,Gia_dinh!$F$50,IF(0<=9,Gia_dinh!$F$51,Gia_dinh!$F$52)))) | R5: =IF(0=0,0,Gia_dinh!$F$53) | S5: =IF(0=0,Gia_dinh!$F$33,0) | T5: =SUM(M5:S5) | U5: =L5-T5 | V5: =U5
B6: 1 | C6: Ươm | D6: =IF(1>Gia_dinh!$F$18,1-Gia_dinh!$F$19,1)*IF(1>Gia_dinh!$F$20,1-Gia_dinh!$F$21,1)*(1-Gia_dinh!$F$107)^MAX(0,1-9) | E6: =IF(1=0,0,IF(1<=3,Gia_dinh!$F$34,IF(1<=6,Gia_dinh!$F$36,IF(1<=9,Gia_dinh!$F$38,Gia_dinh!$F$40)))) | F6: =IF(1=0,0,IF(1<=3,Gia_dinh!$F$35,IF(1<=6,Gia_dinh!$F$37,IF(1<=9,Gia_dinh!$F$39,Gia_dinh!$F$41)))) | G6: =E6*F6 | H6: =G6*(1-Gia_dinh!$F$26) | I6: =H6*Gia_dinh!$F$27 | J6: =IF(1>=Gia_dinh!$F$29,Gia_dinh!$F$28*F6,0) | K6: =H6*Gia_dinh!$F$30 | L6: =SUM(I6:K6) | M6: =L6*Gia_dinh!$F$46 | N6: =IF(1=0,0,IF(1<=3,Gia_dinh!$F$44,Gia_dinh!$F$45)) | O6: =IF(1=0,0,Gia_dinh!$F$47) | P6: =IF(1=0,0,Gia_dinh!$F$48) | Q6: =H6*IF(1=0,0,IF(1<=3,Gia_dinh!$F$49,IF(1<=6,Gia_dinh!$F$50,IF(1<=9,Gia_dinh!$F$51,Gia_dinh!$F$52)))) | R6: =IF(1=0,0,Gia_dinh!$F$53) | S6: =IF(1=0,Gia_dinh!$F$33,0) | T6: =SUM(M6:S6) | U6: =L6-T6 | V6: =V5+U6
B7: 2 | C7: Ươm | D7: =IF(2>Gia_dinh!$F$18,1-Gia_dinh!$F$19,1)*IF(2>Gia_dinh!$F$20,1-Gia_dinh!$F$21,1)*(1-Gia_dinh!$F$107)^MAX(0,2-9) | E7: =IF(2=0,0,IF(2<=3,Gia_dinh!$F$34,IF(2<=6,Gia_dinh!$F$36,IF(2<=9,Gia_dinh!$F$38,Gia_dinh!$F$40)))) | F7: =IF(2=0,0,IF(2<=3,Gia_dinh!$F$35,IF(2<=6,Gia_dinh!$F$37,IF(2<=9,Gia_dinh!$F$39,Gia_dinh!$F$41)))) | G7: =E7*F7 | H7: =G7*(1-Gia_dinh!$F$26) | I7: =H7*Gia_dinh!$F$27 | J7: =IF(2>=Gia_dinh!$F$29,Gia_dinh!$F$28*F7,0) | K7: =H7*Gia_dinh!$F$30 | L7: =SUM(I7:K7) | M7: =L7*Gia_dinh!$F$46 | N7: =IF(2=0,0,IF(2<=3,Gia_dinh!$F$44,Gia_dinh!$F$45)) | O7: =IF(2=0,0,Gia_dinh!$F$47) | P7: =IF(2=0,0,Gia_dinh!$F$48) | Q7: =H7*IF(2=0,0,IF(2<=3,Gia_dinh!$F$49,IF(2<=6,Gia_dinh!$F$50,IF(2<=9,Gia_dinh!$F$51,Gia_dinh!$F$52)))) | R7: =IF(2=0,0,Gia_dinh!$F$53) | S7: =IF(2=0,Gia_dinh!$F$33,0) | T7: =SUM(M7:S7) | U7: =L7-T7 | V7: =V6+U7
B8: 3 | C8: Ươm | D8: =IF(3>Gia_dinh!$F$18,1-Gia_dinh!$F$19,1)*IF(3>Gia_dinh!$F$20,1-Gia_dinh!$F$21,1)*(1-Gia_dinh!$F$107)^MAX(0,3-9) | E8: =IF(3=0,0,IF(3<=3,Gia_dinh!$F$34,IF(3<=6,Gia_dinh!$F$36,IF(3<=9,Gia_dinh!$F$38,Gia_dinh!$F$40)))) | F8: =IF(3=0,0,IF(3<=3,Gia_dinh!$F$35,IF(3<=6,Gia_dinh!$F$37,IF(3<=9,Gia_dinh!$F$39,Gia_dinh!$F$41)))) | G8: =E8*F8 | H8: =G8*(1-Gia_dinh!$F$26) | I8: =H8*Gia_dinh!$F$27 | J8: =IF(3>=Gia_dinh!$F$29,Gia_dinh!$F$28*F8,0) | K8: =H8*Gia_dinh!$F$30 | L8: =SUM(I8:K8) | M8: =L8*Gia_dinh!$F$46 | N8: =IF(3=0,0,IF(3<=3,Gia_dinh!$F$44,Gia_dinh!$F$45)) | O8: =IF(3=0,0,Gia_dinh!$F$47) | P8: =IF(3=0,0,Gia_dinh!$F$48) | Q8: =H8*IF(3=0,0,IF(3<=3,Gia_dinh!$F$49,IF(3<=6,Gia_dinh!$F$50,IF(3<=9,Gia_dinh!$F$51,Gia_dinh!$F$52)))) | R8: =IF(3=0,0,Gia_dinh!$F$53) | S8: =IF(3=0,Gia_dinh!$F$33,0) | T8: =SUM(M8:S8) | U8: =L8-T8 | V8: =V7+U8
B9: 4 | C9: Tăng trưởng sớm | D9: =IF(4>Gia_dinh!$F$18,1-Gia_dinh!$F$19,1)*IF(4>Gia_dinh!$F$20,1-Gia_dinh!$F$21,1)*(1-Gia_dinh!$F$107)^MAX(0,4-9) | E9: =IF(4=0,0,IF(4<=3,Gia_dinh!$F$34,IF(4<=6,Gia_dinh!$F$36,IF(4<=9,Gia_dinh!$F$38,Gia_dinh!$F$40)))) | F9: =IF(4=0,0,IF(4<=3,Gia_dinh!$F$35,IF(4<=6,Gia_dinh!$F$37,IF(4<=9,Gia_dinh!$F$39,Gia_dinh!$F$41)))) | G9: =E9*F9 | H9: =G9*(1-Gia_dinh!$F$26) | I9: =H9*Gia_dinh!$F$27 | J9: =IF(4>=Gia_dinh!$F$29,Gia_dinh!$F$28*F9,0) | K9: =H9*Gia_dinh!$F$30 | L9: =SUM(I9:K9) | M9: =L9*Gia_dinh!$F$46 | N9: =IF(4=0,0,IF(4<=3,Gia_dinh!$F$44,Gia_dinh!$F$45)) | O9: =IF(4=0,0,Gia_dinh!$F$47) | P9: =IF(4=0,0,Gia_dinh!$F$48) | Q9: =H9*IF(4=0,0,IF(4<=3,Gia_dinh!$F$49,IF(4<=6,Gia_dinh!$F$50,IF(4<=9,Gia_dinh!$F$51,Gia_dinh!$F$52)))) | R9: =IF(4=0,0,Gia_dinh!$F$53) | S9: =IF(4=0,Gia_dinh!$F$33,0) | T9: =SUM(M9:S9) | U9: =L9-T9 | V9: =V8+U9
B10: 5 | C10: Tăng trưởng sớm | D10: =IF(5>Gia_dinh!$F$18,1-Gia_dinh!$F$19,1)*IF(5>Gia_dinh!$F$20,1-Gia_dinh!$F$21,1)*(1-Gia_dinh!$F$107)^MAX(0,5-9) | E10: =IF(5=0,0,IF(5<=3,Gia_dinh!$F$34,IF(5<=6,Gia_dinh!$F$36,IF(5<=9,Gia_dinh!$F$38,Gia_dinh!$F$40)))) | F10: =IF(5=0,0,IF(5<=3,Gia_dinh!$F$35,IF(5<=6,Gia_dinh!$F$37,IF(5<=9,Gia_dinh!$F$39,Gia_dinh!$F$41)))) | G10: =E10*F10 | H10: =G10*(1-Gia_dinh!$F$26) | I10: =H10*Gia_dinh!$F$27 | J10: =IF(5>=Gia_dinh!$F$29,Gia_dinh!$F$28*F10,0) | K10: =H10*Gia_dinh!$F$30 | L10: =SUM(I10:K10) | M10: =L10*Gia_dinh!$F$46 | N10: =IF(5=0,0,IF(5<=3,Gia_dinh!$F$44,Gia_dinh!$F$45)) | O10: =IF(5=0,0,Gia_dinh!$F$47) | P10: =IF(5=0,0,Gia_dinh!$F$48) | Q10: =H10*IF(5=0,0,IF(5<=3,Gia_dinh!$F$49,IF(5<=6,Gia_dinh!$F$50,IF(5<=9,Gia_dinh!$F$51,Gia_dinh!$F$52)))) | R10: =IF(5=0,0,Gia_dinh!$F$53) | S10: =IF(5=0,Gia_dinh!$F$33,0) | T10: =SUM(M10:S10) | U10: =L10-T10 | V10: =V9+U10
B11: 6 | C11: Tăng trưởng sớm | D11: =IF(6>Gia_dinh!$F$18,1-Gia_dinh!$F$19,1)*IF(6>Gia_dinh!$F$20,1-Gia_dinh!$F$21,1)*(1-Gia_dinh!$F$107)^MAX(0,6-9) | E11: =IF(6=0,0,IF(6<=3,Gia_dinh!$F$34,IF(6<=6,Gia_dinh!$F$36,IF(6<=9,Gia_dinh!$F$38,Gia_dinh!$F$40)))) | F11: =IF(6=0,0,IF(6<=3,Gia_dinh!$F$35,IF(6<=6,Gia_dinh!$F$37,IF(6<=9,Gia_dinh!$F$39,Gia_dinh!$F$41)))) | G11: =E11*F11 | H11: =G11*(1-Gia_dinh!$F$26) | I11: =H11*Gia_dinh!$F$27 | J11: =IF(6>=Gia_dinh!$F$29,Gia_dinh!$F$28*F11,0) | K11: =H11*Gia_dinh!$F$30 | L11: =SUM(I11:K11) | M11: =L11*Gia_dinh!$F$46 | N11: =IF(6=0,0,IF(6<=3,Gia_dinh!$F$44,Gia_dinh!$F$45)) | O11: =IF(6=0,0,Gia_dinh!$F$47) | P11: =IF(6=0,0,Gia_dinh!$F$48) | Q11: =H11*IF(6=0,0,IF(6<=3,Gia_dinh!$F$49,IF(6<=6,Gia_dinh!$F$50,IF(6<=9,Gia_dinh!$F$51,Gia_dinh!$F$52)))) | R11: =IF(6=0,0,Gia_dinh!$F$53) | S11: =IF(6=0,Gia_dinh!$F$33,0) | T11: =SUM(M11:S11) | U11: =L11-T11 | V11: =V10+U11
B12: 7 | C12: Tăng trưởng | D12: =IF(7>Gia_dinh!$F$18,1-Gia_dinh!$F$19,1)*IF(7>Gia_dinh!$F$20,1-Gia_dinh!$F$21,1)*(1-Gia_dinh!$F$107)^MAX(0,7-9) | E12: =IF(7=0,0,IF(7<=3,Gia_dinh!$F$34,IF(7<=6,Gia_dinh!$F$36,IF(7<=9,Gia_dinh!$F$38,Gia_dinh!$F$40)))) | F12: =IF(7=0,0,IF(7<=3,Gia_dinh!$F$35,IF(7<=6,Gia_dinh!$F$37,IF(7<=9,Gia_dinh!$F$39,Gia_dinh!$F$41)))) | G12: =E12*F12 | H12: =G12*(1-Gia_dinh!$F$26) | I12: =H12*Gia_dinh!$F$27 | J12: =IF(7>=Gia_dinh!$F$29,Gia_dinh!$F$28*F12,0) | K12: =H12*Gia_dinh!$F$30 | L12: =SUM(I12:K12) | M12: =L12*Gia_dinh!$F$46 | N12: =IF(7=0,0,IF(7<=3,Gia_dinh!$F$44,Gia_dinh!$F$45)) | O12: =IF(7=0,0,Gia_dinh!$F$47) | P12: =IF(7=0,0,Gia_dinh!$F$48) | Q12: =H12*IF(7=0,0,IF(7<=3,Gia_dinh!$F$49,IF(7<=6,Gia_dinh!$F$50,IF(7<=9,Gia_dinh!$F$51,Gia_dinh!$F$52)))) | R12: =IF(7=0,0,Gia_dinh!$F$53) | S12: =IF(7=0,Gia_dinh!$F$33,0) | T12: =SUM(M12:S12) | U12: =L12-T12 | V12: =V11+U12
B13: 8 | C13: Tăng trưởng | D13: =IF(8>Gia_dinh!$F$18,1-Gia_dinh!$F$19,1)*IF(8>Gia_dinh!$F$20,1-Gia_dinh!$F$21,1)*(1-Gia_dinh!$F$107)^MAX(0,8-9) | E13: =IF(8=0,0,IF(8<=3,Gia_dinh!$F$34,IF(8<=6,Gia_dinh!$F$36,IF(8<=9,Gia_dinh!$F$38,Gia_dinh!$F$40)))) | F13: =IF(8=0,0,IF(8<=3,Gia_dinh!$F$35,IF(8<=6,Gia_dinh!$F$37,IF(8<=9,Gia_dinh!$F$39,Gia_dinh!$F$41)))) | G13: =E13*F13 | H13: =G13*(1-Gia_dinh!$F$26) | I13: =H13*Gia_dinh!$F$27 | J13: =IF(8>=Gia_dinh!$F$29,Gia_dinh!$F$28*F13,0) | K13: =H13*Gia_dinh!$F$30 | L13: =SUM(I13:K13) | M13: =L13*Gia_dinh!$F$46 | N13: =IF(8=0,0,IF(8<=3,Gia_dinh!$F$44,Gia_dinh!$F$45)) | O13: =IF(8=0,0,Gia_dinh!$F$47) | P13: =IF(8=0,0,Gia_dinh!$F$48) | Q13: =H13*IF(8=0,0,IF(8<=3,Gia_dinh!$F$49,IF(8<=6,Gia_dinh!$F$50,IF(8<=9,Gia_dinh!$F$51,Gia_dinh!$F$52)))) | R13: =IF(8=0,0,Gia_dinh!$F$53) | S13: =IF(8=0,Gia_dinh!$F$33,0) | T13: =SUM(M13:S13) | U13: =L13-T13 | V13: =V12+U13
B14: 9 | C14: Tăng trưởng | D14: =IF(9>Gia_dinh!$F$18,1-Gia_dinh!$F$19,1)*IF(9>Gia_dinh!$F$20,1-Gia_dinh!$F$21,1)*(1-Gia_dinh!$F$107)^MAX(0,9-9) | E14: =IF(9=0,0,IF(9<=3,Gia_dinh!$F$34,IF(9<=6,Gia_dinh!$F$36,IF(9<=9,Gia_dinh!$F$38,Gia_dinh!$F$40)))) | F14: =IF(9=0,0,IF(9<=3,Gia_dinh!$F$35,IF(9<=6,Gia_dinh!$F$37,IF(9<=9,Gia_dinh!$F$39,Gia_dinh!$F$41)))) | G14: =E14*F14 | H14: =G14*(1-Gia_dinh!$F$26) | I14: =H14*Gia_dinh!$F$27 | J14: =IF(9>=Gia_dinh!$F$29,Gia_dinh!$F$28*F14,0) | K14: =H14*Gia_dinh!$F$30 | L14: =SUM(I14:K14) | M14: =L14*Gia_dinh!$F$46 | N14: =IF(9=0,0,IF(9<=3,Gia_dinh!$F$44,Gia_dinh!$F$45)) | O14: =IF(9=0,0,Gia_dinh!$F$47) | P14: =IF(9=0,0,Gia_dinh!$F$48) | Q14: =H14*IF(9=0,0,IF(9<=3,Gia_dinh!$F$49,IF(9<=6,Gia_dinh!$F$50,IF(9<=9,Gia_dinh!$F$51,Gia_dinh!$F$52)))) | R14: =IF(9=0,0,Gia_dinh!$F$53) | S14: =IF(9=0,Gia_dinh!$F$33,0) | T14: =SUM(M14:S14) | U14: =L14-T14 | V14: =V13+U14
B15: 10 | C15: Ổn định | D15: =IF(10>Gia_dinh!$F$18,1-Gia_dinh!$F$19,1)*IF(10>Gia_dinh!$F$20,1-Gia_dinh!$F$21,1)*(1-Gia_dinh!$F$107)^MAX(0,10-9) | E15: =IF(10=0,0,IF(10<=3,Gia_dinh!$F$34,IF(10<=6,Gia_dinh!$F$36,IF(10<=9,Gia_dinh!$F$38,Gia_dinh!$F$40)))) | F15: =IF(10=0,0,IF(10<=3,Gia_dinh!$F$35,IF(10<=6,Gia_dinh!$F$37,IF(10<=9,Gia_dinh!$F$39,Gia_dinh!$F$41)))) | G15: =E15*F15 | H15: =G15*(1-Gia_dinh!$F$26) | I15: =H15*Gia_dinh!$F$27 | J15: =IF(10>=Gia_dinh!$F$29,Gia_dinh!$F$28*F15,0) | K15: =H15*Gia_dinh!$F$30 | L15: =SUM(I15:K15) | M15: =L15*Gia_dinh!$F$46 | N15: =IF(10=0,0,IF(10<=3,Gia_dinh!$F$44,Gia_dinh!$F$45)) | O15: =IF(10=0,0,Gia_dinh!$F$47) | P15: =IF(10=0,0,Gia_dinh!$F$48) | Q15: =H15*IF(10=0,0,IF(10<=3,Gia_dinh!$F$49,IF(10<=6,Gia_dinh!$F$50,IF(10<=9,Gia_dinh!$F$51,Gia_dinh!$F$52)))) | R15: =IF(10=0,0,Gia_dinh!$F$53) | S15: =IF(10=0,Gia_dinh!$F$33,0) | T15: =SUM(M15:S15) | U15: =L15-T15 | V15: =V14+U15
B16: 11 | C16: Ổn định | D16: =IF(11>Gia_dinh!$F$18,1-Gia_dinh!$F$19,1)*IF(11>Gia_dinh!$F$20,1-Gia_dinh!$F$21,1)*(1-Gia_dinh!$F$107)^MAX(0,11-9) | E16: =IF(11=0,0,IF(11<=3,Gia_dinh!$F$34,IF(11<=6,Gia_dinh!$F$36,IF(11<=9,Gia_dinh!$F$38,Gia_dinh!$F$40)))) | F16: =IF(11=0,0,IF(11<=3,Gia_dinh!$F$35,IF(11<=6,Gia_dinh!$F$37,IF(11<=9,Gia_dinh!$F$39,Gia_dinh!$F$41)))) | G16: =E16*F16 | H16: =G16*(1-Gia_dinh!$F$26) | I16: =H16*Gia_dinh!$F$27 | J16: =IF(11>=Gia_dinh!$F$29,Gia_dinh!$F$28*F16,0) | K16: =H16*Gia_dinh!$F$30 | L16: =SUM(I16:K16) | M16: =L16*Gia_dinh!$F$46 | N16: =IF(11=0,0,IF(11<=3,Gia_dinh!$F$44,Gia_dinh!$F$45)) | O16: =IF(11=0,0,Gia_dinh!$F$47) | P16: =IF(11=0,0,Gia_dinh!$F$48) | Q16: =H16*IF(11=0,0,IF(11<=3,Gia_dinh!$F$49,IF(11<=6,Gia_dinh!$F$50,IF(11<=9,Gia_dinh!$F$51,Gia_dinh!$F$52)))) | R16: =IF(11=0,0,Gia_dinh!$F$53) | S16: =IF(11=0,Gia_dinh!$F$33,0) | T16: =SUM(M16:S16) | U16: =L16-T16 | V16: =V15+U16
B17: 12 | C17: Ổn định | D17: =IF(12>Gia_dinh!$F$18,1-Gia_dinh!$F$19,1)*IF(12>Gia_dinh!$F$20,1-Gia_dinh!$F$21,1)*(1-Gia_dinh!$F$107)^MAX(0,12-9) | E17: =IF(12=0,0,IF(12<=3,Gia_dinh!$F$34,IF(12<=6,Gia_dinh!$F$36,IF(12<=9,Gia_dinh!$F$38,Gia_dinh!$F$40)))) | F17: =IF(12=0,0,IF(12<=3,Gia_dinh!$F$35,IF(12<=6,Gia_dinh!$F$37,IF(12<=9,Gia_dinh!$F$39,Gia_dinh!$F$41)))) | G17: =E17*F17 | H17: =G17*(1-Gia_dinh!$F$26) | I17: =H17*Gia_dinh!$F$27 | J17: =IF(12>=Gia_dinh!$F$29,Gia_dinh!$F$28*F17,0) | K17: =H17*Gia_dinh!$F$30 | L17: =SUM(I17:K17) | M17: =L17*Gia_dinh!$F$46 | N17: =IF(12=0,0,IF(12<=3,Gia_dinh!$F$44,Gia_dinh!$F$45)) | O17: =IF(12=0,0,Gia_dinh!$F$47) | P17: =IF(12=0,0,Gia_dinh!$F$48) | Q17: =H17*IF(12=0,0,IF(12<=3,Gia_dinh!$F$49,IF(12<=6,Gia_dinh!$F$50,IF(12<=9,Gia_dinh!$F$51,Gia_dinh!$F$52)))) | R17: =IF(12=0,0,Gia_dinh!$F$53) | S17: =IF(12=0,Gia_dinh!$F$33,0) | T17: =SUM(M17:S17) | U17: =L17-T17 | V17: =V16+U17
B18: 13 | C18: Ổn định | D18: =IF(13>Gia_dinh!$F$18,1-Gia_dinh!$F$19,1)*IF(13>Gia_dinh!$F$20,1-Gia_dinh!$F$21,1)*(1-Gia_dinh!$F$107)^MAX(0,13-9) | E18: =IF(13=0,0,IF(13<=3,Gia_dinh!$F$34,IF(13<=6,Gia_dinh!$F$36,IF(13<=9,Gia_dinh!$F$38,Gia_dinh!$F$40)))) | F18: =IF(13=0,0,IF(13<=3,Gia_dinh!$F$35,IF(13<=6,Gia_dinh!$F$37,IF(13<=9,Gia_dinh!$F$39,Gia_dinh!$F$41)))) | G18: =E18*F18 | H18: =G18*(1-Gia_dinh!$F$26) | I18: =H18*Gia_dinh!$F$27 | J18: =IF(13>=Gia_dinh!$F$29,Gia_dinh!$F$28*F18,0) | K18: =H18*Gia_dinh!$F$30 | L18: =SUM(I18:K18) | M18: =L18*Gia_dinh!$F$46 | N18: =IF(13=0,0,IF(13<=3,Gia_dinh!$F$44,Gia_dinh!$F$45)) | O18: =IF(13=0,0,Gia_dinh!$F$47) | P18: =IF(13=0,0,Gia_dinh!$F$48) | Q18: =H18*IF(13=0,0,IF(13<=3,Gia_dinh!$F$49,IF(13<=6,Gia_dinh!$F$50,IF(13<=9,Gia_dinh!$F$51,Gia_dinh!$F$52)))) | R18: =IF(13=0,0,Gia_dinh!$F$53) | S18: =IF(13=0,Gia_dinh!$F$33,0) | T18: =SUM(M18:S18) | U18: =L18-T18 | V18: =V17+U18
B19: 14 | C19: Ổn định | D19: =IF(14>Gia_dinh!$F$18,1-Gia_dinh!$F$19,1)*IF(14>Gia_dinh!$F$20,1-Gia_dinh!$F$21,1)*(1-Gia_dinh!$F$107)^MAX(0,14-9) | E19: =IF(14=0,0,IF(14<=3,Gia_dinh!$F$34,IF(14<=6,Gia_dinh!$F$36,IF(14<=9,Gia_dinh!$F$38,Gia_dinh!$F$40)))) | F19: =IF(14=0,0,IF(14<=3,Gia_dinh!$F$35,IF(14<=6,Gia_dinh!$F$37,IF(14<=9,Gia_dinh!$F$39,Gia_dinh!$F$41)))) | G19: =E19*F19 | H19: =G19*(1-Gia_dinh!$F$26) | I19: =H19*Gia_dinh!$F$27 | J19: =IF(14>=Gia_dinh!$F$29,Gia_dinh!$F$28*F19,0) | K19: =H19*Gia_dinh!$F$30 | L19: =SUM(I19:K19) | M19: =L19*Gia_dinh!$F$46 | N19: =IF(14=0,0,IF(14<=3,Gia_dinh!$F$44,Gia_dinh!$F$45)) | O19: =IF(14=0,0,Gia_dinh!$F$47) | P19: =IF(14=0,0,Gia_dinh!$F$48) | Q19: =H19*IF(14=0,0,IF(14<=3,Gia_dinh!$F$49,IF(14<=6,Gia_dinh!$F$50,IF(14<=9,Gia_dinh!$F$51,Gia_dinh!$F$52)))) | R19: =IF(14=0,0,Gia_dinh!$F$53) | S19: =IF(14=0,Gia_dinh!$F$33,0) | T19: =SUM(M19:S19) | U19: =L19-T19 | V19: =V18+U19
B20: 15 | C20: Ổn định | D20: =IF(15>Gia_dinh!$F$18,1-Gia_dinh!$F$19,1)*IF(15>Gia_dinh!$F$20,1-Gia_dinh!$F$21,1)*(1-Gia_dinh!$F$107)^MAX(0,15-9) | E20: =IF(15=0,0,IF(15<=3,Gia_dinh!$F$34,IF(15<=6,Gia_dinh!$F$36,IF(15<=9,Gia_dinh!$F$38,Gia_dinh!$F$40)))) | F20: =IF(15=0,0,IF(15<=3,Gia_dinh!$F$35,IF(15<=6,Gia_dinh!$F$37,IF(15<=9,Gia_dinh!$F$39,Gia_dinh!$F$41)))) | G20: =E20*F20 | H20: =G20*(1-Gia_dinh!$F$26) | I20: =H20*Gia_dinh!$F$27 | J20: =IF(15>=Gia_dinh!$F$29,Gia_dinh!$F$28*F20,0) | K20: =H20*Gia_dinh!$F$30 | L20: =SUM(I20:K20) | M20: =L20*Gia_dinh!$F$46 | N20: =IF(15=0,0,IF(15<=3,Gia_dinh!$F$44,Gia_dinh!$F$45)) | O20: =IF(15=0,0,Gia_dinh!$F$47) | P20: =IF(15=0,0,Gia_dinh!$F$48) | Q20: =H20*IF(15=0,0,IF(15<=3,Gia_dinh!$F$49,IF(15<=6,Gia_dinh!$F$50,IF(15<=9,Gia_dinh!$F$51,Gia_dinh!$F$52)))) | R20: =IF(15=0,0,Gia_dinh!$F$53) | S20: =IF(15=0,Gia_dinh!$F$33,0) | T20: =SUM(M20:S20) | U20: =L20-T20 | V20: =V19+U20
B21: 16 | C21: Ổn định | D21: =IF(16>Gia_dinh!$F$18,1-Gia_dinh!$F$19,1)*IF(16>Gia_dinh!$F$20,1-Gia_dinh!$F$21,1)*(1-Gia_dinh!$F$107)^MAX(0,16-9) | E21: =IF(16=0,0,IF(16<=3,Gia_dinh!$F$34,IF(16<=6,Gia_dinh!$F$36,IF(16<=9,Gia_dinh!$F$38,Gia_dinh!$F$40)))) | F21: =IF(16=0,0,IF(16<=3,Gia_dinh!$F$35,IF(16<=6,Gia_dinh!$F$37,IF(16<=9,Gia_dinh!$F$39,Gia_dinh!$F$41)))) | G21: =E21*F21 | H21: =G21*(1-Gia_dinh!$F$26) | I21: =H21*Gia_dinh!$F$27 | J21: =IF(16>=Gia_dinh!$F$29,Gia_dinh!$F$28*F21,0) | K21: =H21*Gia_dinh!$F$30 | L21: =SUM(I21:K21) | M21: =L21*Gia_dinh!$F$46 | N21: =IF(16=0,0,IF(16<=3,Gia_dinh!$F$44,Gia_dinh!$F$45)) | O21: =IF(16=0,0,Gia_dinh!$F$47) | P21: =IF(16=0,0,Gia_dinh!$F$48) | Q21: =H21*IF(16=0,0,IF(16<=3,Gia_dinh!$F$49,IF(16<=6,Gia_dinh!$F$50,IF(16<=9,Gia_dinh!$F$51,Gia_dinh!$F$52)))) | R21: =IF(16=0,0,Gia_dinh!$F$53) | S21: =IF(16=0,Gia_dinh!$F$33,0) | T21: =SUM(M21:S21) | U21: =L21-T21 | V21: =V20+U21
B22: 17 | C22: Ổn định | D22: =IF(17>Gia_dinh!$F$18,1-Gia_dinh!$F$19,1)*IF(17>Gia_dinh!$F$20,1-Gia_dinh!$F$21,1)*(1-Gia_dinh!$F$107)^MAX(0,17-9) | E22: =IF(17=0,0,IF(17<=3,Gia_dinh!$F$34,IF(17<=6,Gia_dinh!$F$36,IF(17<=9,Gia_dinh!$F$38,Gia_dinh!$F$40)))) | F22: =IF(17=0,0,IF(17<=3,Gia_dinh!$F$35,IF(17<=6,Gia_dinh!$F$37,IF(17<=9,Gia_dinh!$F$39,Gia_dinh!$F$41)))) | G22: =E22*F22 | H22: =G22*(1-Gia_dinh!$F$26) | I22: =H22*Gia_dinh!$F$27 | J22: =IF(17>=Gia_dinh!$F$29,Gia_dinh!$F$28*F22,0) | K22: =H22*Gia_dinh!$F$30 | L22: =SUM(I22:K22) | M22: =L22*Gia_dinh!$F$46 | N22: =IF(17=0,0,IF(17<=3,Gia_dinh!$F$44,Gia_dinh!$F$45)) | O22: =IF(17=0,0,Gia_dinh!$F$47) | P22: =IF(17=0,0,Gia_dinh!$F$48) | Q22: =H22*IF(17=0,0,IF(17<=3,Gia_dinh!$F$49,IF(17<=6,Gia_dinh!$F$50,IF(17<=9,Gia_dinh!$F$51,Gia_dinh!$F$52)))) | R22: =IF(17=0,0,Gia_dinh!$F$53) | S22: =IF(17=0,Gia_dinh!$F$33,0) | T22: =SUM(M22:S22) | U22: =L22-T22 | V22: =V21+U22
B23: 18 | C23: Ổn định | D23: =IF(18>Gia_dinh!$F$18,1-Gia_dinh!$F$19,1)*IF(18>Gia_dinh!$F$20,1-Gia_dinh!$F$21,1)*(1-Gia_dinh!$F$107)^MAX(0,18-9) | E23: =IF(18=0,0,IF(18<=3,Gia_dinh!$F$34,IF(18<=6,Gia_dinh!$F$36,IF(18<=9,Gia_dinh!$F$38,Gia_dinh!$F$40)))) | F23: =IF(18=0,0,IF(18<=3,Gia_dinh!$F$35,IF(18<=6,Gia_dinh!$F$37,IF(18<=9,Gia_dinh!$F$39,Gia_dinh!$F$41)))) | G23: =E23*F23 | H23: =G23*(1-Gia_dinh!$F$26) | I23: =H23*Gia_dinh!$F$27 | J23: =IF(18>=Gia_dinh!$F$29,Gia_dinh!$F$28*F23,0) | K23: =H23*Gia_dinh!$F$30 | L23: =SUM(I23:K23) | M23: =L23*Gia_dinh!$F$46 | N23: =IF(18=0,0,IF(18<=3,Gia_dinh!$F$44,Gia_dinh!$F$45)) | O23: =IF(18=0,0,Gia_dinh!$F$47) | P23: =IF(18=0,0,Gia_dinh!$F$48) | Q23: =H23*IF(18=0,0,IF(18<=3,Gia_dinh!$F$49,IF(18<=6,Gia_dinh!$F$50,IF(18<=9,Gia_dinh!$F$51,Gia_dinh!$F$52)))) | R23: =IF(18=0,0,Gia_dinh!$F$53) | S23: =IF(18=0,Gia_dinh!$F$33,0) | T23: =SUM(M23:S23) | U23: =L23-T23 | V23: =V22+U23
B24: 19 | C24: Ổn định | D24: =IF(19>Gia_dinh!$F$18,1-Gia_dinh!$F$19,1)*IF(19>Gia_dinh!$F$20,1-Gia_dinh!$F$21,1)*(1-Gia_dinh!$F$107)^MAX(0,19-9) | E24: =IF(19=0,0,IF(19<=3,Gia_dinh!$F$34,IF(19<=6,Gia_dinh!$F$36,IF(19<=9,Gia_dinh!$F$38,Gia_dinh!$F$40)))) | F24: =IF(19=0,0,IF(19<=3,Gia_dinh!$F$35,IF(19<=6,Gia_dinh!$F$37,IF(19<=9,Gia_dinh!$F$39,Gia_dinh!$F$41)))) | G24: =E24*F24 | H24: =G24*(1-Gia_dinh!$F$26) | I24: =H24*Gia_dinh!$F$27 | J24: =IF(19>=Gia_dinh!$F$29,Gia_dinh!$F$28*F24,0) | K24: =H24*Gia_dinh!$F$30 | L24: =SUM(I24:K24) | M24: =L24*Gia_dinh!$F$46 | N24: =IF(19=0,0,IF(19<=3,Gia_dinh!$F$44,Gia_dinh!$F$45)) | O24: =IF(19=0,0,Gia_dinh!$F$47) | P24: =IF(19=0,0,Gia_dinh!$F$48) | Q24: =H24*IF(19=0,0,IF(19<=3,Gia_dinh!$F$49,IF(19<=6,Gia_dinh!$F$50,IF(19<=9,Gia_dinh!$F$51,Gia_dinh!$F$52)))) | R24: =IF(19=0,0,Gia_dinh!$F$53) | S24: =IF(19=0,Gia_dinh!$F$33,0) | T24: =SUM(M24:S24) | U24: =L24-T24 | V24: =V23+U24
B25: 20 | C25: Ổn định | D25: =IF(20>Gia_dinh!$F$18,1-Gia_dinh!$F$19,1)*IF(20>Gia_dinh!$F$20,1-Gia_dinh!$F$21,1)*(1-Gia_dinh!$F$107)^MAX(0,20-9) | E25: =IF(20=0,0,IF(20<=3,Gia_dinh!$F$34,IF(20<=6,Gia_dinh!$F$36,IF(20<=9,Gia_dinh!$F$38,Gia_dinh!$F$40)))) | F25: =IF(20=0,0,IF(20<=3,Gia_dinh!$F$35,IF(20<=6,Gia_dinh!$F$37,IF(20<=9,Gia_dinh!$F$39,Gia_dinh!$F$41)))) | G25: =E25*F25 | H25: =G25*(1-Gia_dinh!$F$26) | I25: =H25*Gia_dinh!$F$27 | J25: =IF(20>=Gia_dinh!$F$29,Gia_dinh!$F$28*F25,0) | K25: =H25*Gia_dinh!$F$30 | L25: =SUM(I25:K25) | M25: =L25*Gia_dinh!$F$46 | N25: =IF(20=0,0,IF(20<=3,Gia_dinh!$F$44,Gia_dinh!$F$45)) | O25: =IF(20=0,0,Gia_dinh!$F$47) | P25: =IF(20=0,0,Gia_dinh!$F$48) | Q25: =H25*IF(20=0,0,IF(20<=3,Gia_dinh!$F$49,IF(20<=6,Gia_dinh!$F$50,IF(20<=9,Gia_dinh!$F$51,Gia_dinh!$F$52)))) | R25: =IF(20=0,0,Gia_dinh!$F$53) | S25: =IF(20=0,Gia_dinh!$F$33,0) | T25: =SUM(M25:S25) | U25: =L25-T25 | V25: =V24+U25
B26: 21 | C26: Ổn định | D26: =IF(21>Gia_dinh!$F$18,1-Gia_dinh!$F$19,1)*IF(21>Gia_dinh!$F$20,1-Gia_dinh!$F$21,1)*(1-Gia_dinh!$F$107)^MAX(0,21-9) | E26: =IF(21=0,0,IF(21<=3,Gia_dinh!$F$34,IF(21<=6,Gia_dinh!$F$36,IF(21<=9,Gia_dinh!$F$38,Gia_dinh!$F$40)))) | F26: =IF(21=0,0,IF(21<=3,Gia_dinh!$F$35,IF(21<=6,Gia_dinh!$F$37,IF(21<=9,Gia_dinh!$F$39,Gia_dinh!$F$41)))) | G26: =E26*F26 | H26: =G26*(1-Gia_dinh!$F$26) | I26: =H26*Gia_dinh!$F$27 | J26: =IF(21>=Gia_dinh!$F$29,Gia_dinh!$F$28*F26,0) | K26: =H26*Gia_dinh!$F$30 | L26: =SUM(I26:K26) | M26: =L26*Gia_dinh!$F$46 | N26: =IF(21=0,0,IF(21<=3,Gia_dinh!$F$44,Gia_dinh!$F$45)) | O26: =IF(21=0,0,Gia_dinh!$F$47) | P26: =IF(21=0,0,Gia_dinh!$F$48) | Q26: =H26*IF(21=0,0,IF(21<=3,Gia_dinh!$F$49,IF(21<=6,Gia_dinh!$F$50,IF(21<=9,Gia_dinh!$F$51,Gia_dinh!$F$52)))) | R26: =IF(21=0,0,Gia_dinh!$F$53) | S26: =IF(21=0,Gia_dinh!$F$33,0) | T26: =SUM(M26:S26) | U26: =L26-T26 | V26: =V25+U26
B27: 22 | C27: Ổn định | D27: =IF(22>Gia_dinh!$F$18,1-Gia_dinh!$F$19,1)*IF(22>Gia_dinh!$F$20,1-Gia_dinh!$F$21,1)*(1-Gia_dinh!$F$107)^MAX(0,22-9) | E27: =IF(22=0,0,IF(22<=3,Gia_dinh!$F$34,IF(22<=6,Gia_dinh!$F$36,IF(22<=9,Gia_dinh!$F$38,Gia_dinh!$F$40)))) | F27: =IF(22=0,0,IF(22<=3,Gia_dinh!$F$35,IF(22<=6,Gia_dinh!$F$37,IF(22<=9,Gia_dinh!$F$39,Gia_dinh!$F$41)))) | G27: =E27*F27 | H27: =G27*(1-Gia_dinh!$F$26) | I27: =H27*Gia_dinh!$F$27 | J27: =IF(22>=Gia_dinh!$F$29,Gia_dinh!$F$28*F27,0) | K27: =H27*Gia_dinh!$F$30 | L27: =SUM(I27:K27) | M27: =L27*Gia_dinh!$F$46 | N27: =IF(22=0,0,IF(22<=3,Gia_dinh!$F$44,Gia_dinh!$F$45)) | O27: =IF(22=0,0,Gia_dinh!$F$47) | P27: =IF(22=0,0,Gia_dinh!$F$48) | Q27: =H27*IF(22=0,0,IF(22<=3,Gia_dinh!$F$49,IF(22<=6,Gia_dinh!$F$50,IF(22<=9,Gia_dinh!$F$51,Gia_dinh!$F$52)))) | R27: =IF(22=0,0,Gia_dinh!$F$53) | S27: =IF(22=0,Gia_dinh!$F$33,0) | T27: =SUM(M27:S27) | U27: =L27-T27 | V27: =V26+U27
B28: 23 | C28: Ổn định | D28: =IF(23>Gia_dinh!$F$18,1-Gia_dinh!$F$19,1)*IF(23>Gia_dinh!$F$20,1-Gia_dinh!$F$21,1)*(1-Gia_dinh!$F$107)^MAX(0,23-9) | E28: =IF(23=0,0,IF(23<=3,Gia_dinh!$F$34,IF(23<=6,Gia_dinh!$F$36,IF(23<=9,Gia_dinh!$F$38,Gia_dinh!$F$40)))) | F28: =IF(23=0,0,IF(23<=3,Gia_dinh!$F$35,IF(23<=6,Gia_dinh!$F$37,IF(23<=9,Gia_dinh!$F$39,Gia_dinh!$F$41)))) | G28: =E28*F28 | H28: =G28*(1-Gia_dinh!$F$26) | I28: =H28*Gia_dinh!$F$27 | J28: =IF(23>=Gia_dinh!$F$29,Gia_dinh!$F$28*F28,0) | K28: =H28*Gia_dinh!$F$30 | L28: =SUM(I28:K28) | M28: =L28*Gia_dinh!$F$46 | N28: =IF(23=0,0,IF(23<=3,Gia_dinh!$F$44,Gia_dinh!$F$45)) | O28: =IF(23=0,0,Gia_dinh!$F$47) | P28: =IF(23=0,0,Gia_dinh!$F$48) | Q28: =H28*IF(23=0,0,IF(23<=3,Gia_dinh!$F$49,IF(23<=6,Gia_dinh!$F$50,IF(23<=9,Gia_dinh!$F$51,Gia_dinh!$F$52)))) | R28: =IF(23=0,0,Gia_dinh!$F$53) | S28: =IF(23=0,Gia_dinh!$F$33,0) | T28: =SUM(M28:S28) | U28: =L28-T28 | V28: =V27+U28
B29: 24 | C29: Ổn định | D29: =IF(24>Gia_dinh!$F$18,1-Gia_dinh!$F$19,1)*IF(24>Gia_dinh!$F$20,1-Gia_dinh!$F$21,1)*(1-Gia_dinh!$F$107)^MAX(0,24-9) | E29: =IF(24=0,0,IF(24<=3,Gia_dinh!$F$34,IF(24<=6,Gia_dinh!$F$36,IF(24<=9,Gia_dinh!$F$38,Gia_dinh!$F$40)))) | F29: =IF(24=0,0,IF(24<=3,Gia_dinh!$F$35,IF(24<=6,Gia_dinh!$F$37,IF(24<=9,Gia_dinh!$F$39,Gia_dinh!$F$41)))) | G29: =E29*F29 | H29: =G29*(1-Gia_dinh!$F$26) | I29: =H29*Gia_dinh!$F$27 | J29: =IF(24>=Gia_dinh!$F$29,Gia_dinh!$F$28*F29,0) | K29: =H29*Gia_dinh!$F$30 | L29: =SUM(I29:K29) | M29: =L29*Gia_dinh!$F$46 | N29: =IF(24=0,0,IF(24<=3,Gia_dinh!$F$44,Gia_dinh!$F$45)) | O29: =IF(24=0,0,Gia_dinh!$F$47) | P29: =IF(24=0,0,Gia_dinh!$F$48) | Q29: =H29*IF(24=0,0,IF(24<=3,Gia_dinh!$F$49,IF(24<=6,Gia_dinh!$F$50,IF(24<=9,Gia_dinh!$F$51,Gia_dinh!$F$52)))) | R29: =IF(24=0,0,Gia_dinh!$F$53) | S29: =IF(24=0,Gia_dinh!$F$33,0) | T29: =SUM(M29:S29) | U29: =L29-T29 | V29: =V28+U29
B30: 25 | C30: Ổn định | D30: =IF(25>Gia_dinh!$F$18,1-Gia_dinh!$F$19,1)*IF(25>Gia_dinh!$F$20,1-Gia_dinh!$F$21,1)*(1-Gia_dinh!$F$107)^MAX(0,25-9) | E30: =IF(25=0,0,IF(25<=3,Gia_dinh!$F$34,IF(25<=6,Gia_dinh!$F$36,IF(25<=9,Gia_dinh!$F$38,Gia_dinh!$F$40)))) | F30: =IF(25=0,0,IF(25<=3,Gia_dinh!$F$35,IF(25<=6,Gia_dinh!$F$37,IF(25<=9,Gia_dinh!$F$39,Gia_dinh!$F$41)))) | G30: =E30*F30 | H30: =G30*(1-Gia_dinh!$F$26) | I30: =H30*Gia_dinh!$F$27 | J30: =IF(25>=Gia_dinh!$F$29,Gia_dinh!$F$28*F30,0) | K30: =H30*Gia_dinh!$F$30 | L30: =SUM(I30:K30) | M30: =L30*Gia_dinh!$F$46 | N30: =IF(25=0,0,IF(25<=3,Gia_dinh!$F$44,Gia_dinh!$F$45)) | O30: =IF(25=0,0,Gia_dinh!$F$47) | P30: =IF(25=0,0,Gia_dinh!$F$48) | Q30: =H30*IF(25=0,0,IF(25<=3,Gia_dinh!$F$49,IF(25<=6,Gia_dinh!$F$50,IF(25<=9,Gia_dinh!$F$51,Gia_dinh!$F$52)))) | R30: =IF(25=0,0,Gia_dinh!$F$53) | S30: =IF(25=0,Gia_dinh!$F$33,0) | T30: =SUM(M30:S30) | U30: =L30-T30 | V30: =V29+U30
B31: 26 | C31: Ổn định | D31: =IF(26>Gia_dinh!$F$18,1-Gia_dinh!$F$19,1)*IF(26>Gia_dinh!$F$20,1-Gia_dinh!$F$21,1)*(1-Gia_dinh!$F$107)^MAX(0,26-9) | E31: =IF(26=0,0,IF(26<=3,Gia_dinh!$F$34,IF(26<=6,Gia_dinh!$F$36,IF(26<=9,Gia_dinh!$F$38,Gia_dinh!$F$40)))) | F31: =IF(26=0,0,IF(26<=3,Gia_dinh!$F$35,IF(26<=6,Gia_dinh!$F$37,IF(26<=9,Gia_dinh!$F$39,Gia_dinh!$F$41)))) | G31: =E31*F31 | H31: =G31*(1-Gia_dinh!$F$26) | I31: =H31*Gia_dinh!$F$27 | J31: =IF(26>=Gia_dinh!$F$29,Gia_dinh!$F$28*F31,0) | K31: =H31*Gia_dinh!$F$30 | L31: =SUM(I31:K31) | M31: =L31*Gia_dinh!$F$46 | N31: =IF(26=0,0,IF(26<=3,Gia_dinh!$F$44,Gia_dinh!$F$45)) | O31: =IF(26=0,0,Gia_dinh!$F$47) | P31: =IF(26=0,0,Gia_dinh!$F$48) | Q31: =H31*IF(26=0,0,IF(26<=3,Gia_dinh!$F$49,IF(26<=6,Gia_dinh!$F$50,IF(26<=9,Gia_dinh!$F$51,Gia_dinh!$F$52)))) | R31: =IF(26=0,0,Gia_dinh!$F$53) | S31: =IF(26=0,Gia_dinh!$F$33,0) | T31: =SUM(M31:S31) | U31: =L31-T31 | V31: =V30+U31
B32: 27 | C32: Ổn định | D32: =IF(27>Gia_dinh!$F$18,1-Gia_dinh!$F$19,1)*IF(27>Gia_dinh!$F$20,1-Gia_dinh!$F$21,1)*(1-Gia_dinh!$F$107)^MAX(0,27-9) | E32: =IF(27=0,0,IF(27<=3,Gia_dinh!$F$34,IF(27<=6,Gia_dinh!$F$36,IF(27<=9,Gia_dinh!$F$38,Gia_dinh!$F$40)))) | F32: =IF(27=0,0,IF(27<=3,Gia_dinh!$F$35,IF(27<=6,Gia_dinh!$F$37,IF(27<=9,Gia_dinh!$F$39,Gia_dinh!$F$41)))) | G32: =E32*F32 | H32: =G32*(1-Gia_dinh!$F$26) | I32: =H32*Gia_dinh!$F$27 | J32: =IF(27>=Gia_dinh!$F$29,Gia_dinh!$F$28*F32,0) | K32: =H32*Gia_dinh!$F$30 | L32: =SUM(I32:K32) | M32: =L32*Gia_dinh!$F$46 | N32: =IF(27=0,0,IF(27<=3,Gia_dinh!$F$44,Gia_dinh!$F$45)) | O32: =IF(27=0,0,Gia_dinh!$F$47) | P32: =IF(27=0,0,Gia_dinh!$F$48) | Q32: =H32*IF(27=0,0,IF(27<=3,Gia_dinh!$F$49,IF(27<=6,Gia_dinh!$F$50,IF(27<=9,Gia_dinh!$F$51,Gia_dinh!$F$52)))) | R32: =IF(27=0,0,Gia_dinh!$F$53) | S32: =IF(27=0,Gia_dinh!$F$33,0) | T32: =SUM(M32:S32) | U32: =L32-T32 | V32: =V31+U32
B33: 28 | C33: Ổn định | D33: =IF(28>Gia_dinh!$F$18,1-Gia_dinh!$F$19,1)*IF(28>Gia_dinh!$F$20,1-Gia_dinh!$F$21,1)*(1-Gia_dinh!$F$107)^MAX(0,28-9) | E33: =IF(28=0,0,IF(28<=3,Gia_dinh!$F$34,IF(28<=6,Gia_dinh!$F$36,IF(28<=9,Gia_dinh!$F$38,Gia_dinh!$F$40)))) | F33: =IF(28=0,0,IF(28<=3,Gia_dinh!$F$35,IF(28<=6,Gia_dinh!$F$37,IF(28<=9,Gia_dinh!$F$39,Gia_dinh!$F$41)))) | G33: =E33*F33 | H33: =G33*(1-Gia_dinh!$F$26) | I33: =H33*Gia_dinh!$F$27 | J33: =IF(28>=Gia_dinh!$F$29,Gia_dinh!$F$28*F33,0) | K33: =H33*Gia_dinh!$F$30 | L33: =SUM(I33:K33) | M33: =L33*Gia_dinh!$F$46 | N33: =IF(28=0,0,IF(28<=3,Gia_dinh!$F$44,Gia_dinh!$F$45)) | O33: =IF(28=0,0,Gia_dinh!$F$47) | P33: =IF(28=0,0,Gia_dinh!$F$48) | Q33: =H33*IF(28=0,0,IF(28<=3,Gia_dinh!$F$49,IF(28<=6,Gia_dinh!$F$50,IF(28<=9,Gia_dinh!$F$51,Gia_dinh!$F$52)))) | R33: =IF(28=0,0,Gia_dinh!$F$53) | S33: =IF(28=0,Gia_dinh!$F$33,0) | T33: =SUM(M33:S33) | U33: =L33-T33 | V33: =V32+U33
B34: 29 | C34: Ổn định | D34: =IF(29>Gia_dinh!$F$18,1-Gia_dinh!$F$19,1)*IF(29>Gia_dinh!$F$20,1-Gia_dinh!$F$21,1)*(1-Gia_dinh!$F$107)^MAX(0,29-9) | E34: =IF(29=0,0,IF(29<=3,Gia_dinh!$F$34,IF(29<=6,Gia_dinh!$F$36,IF(29<=9,Gia_dinh!$F$38,Gia_dinh!$F$40)))) | F34: =IF(29=0,0,IF(29<=3,Gia_dinh!$F$35,IF(29<=6,Gia_dinh!$F$37,IF(29<=9,Gia_dinh!$F$39,Gia_dinh!$F$41)))) | G34: =E34*F34 | H34: =G34*(1-Gia_dinh!$F$26) | I34: =H34*Gia_dinh!$F$27 | J34: =IF(29>=Gia_dinh!$F$29,Gia_dinh!$F$28*F34,0) | K34: =H34*Gia_dinh!$F$30 | L34: =SUM(I34:K34) | M34: =L34*Gia_dinh!$F$46 | N34: =IF(29=0,0,IF(29<=3,Gia_dinh!$F$44,Gia_dinh!$F$45)) | O34: =IF(29=0,0,Gia_dinh!$F$47) | P34: =IF(29=0,0,Gia_dinh!$F$48) | Q34: =H34*IF(29=0,0,IF(29<=3,Gia_dinh!$F$49,IF(29<=6,Gia_dinh!$F$50,IF(29<=9,Gia_dinh!$F$51,Gia_dinh!$F$52)))) | R34: =IF(29=0,0,Gia_dinh!$F$53) | S34: =IF(29=0,Gia_dinh!$F$33,0) | T34: =SUM(M34:S34) | U34: =L34-T34 | V34: =V33+U34
B35: 30 | C35: Ổn định | D35: =IF(30>Gia_dinh!$F$18,1-Gia_dinh!$F$19,1)*IF(30>Gia_dinh!$F$20,1-Gia_dinh!$F$21,1)*(1-Gia_dinh!$F$107)^MAX(0,30-9) | E35: =IF(30=0,0,IF(30<=3,Gia_dinh!$F$34,IF(30<=6,Gia_dinh!$F$36,IF(30<=9,Gia_dinh!$F$38,Gia_dinh!$F$40)))) | F35: =IF(30=0,0,IF(30<=3,Gia_dinh!$F$35,IF(30<=6,Gia_dinh!$F$37,IF(30<=9,Gia_dinh!$F$39,Gia_dinh!$F$41)))) | G35: =E35*F35 | H35: =G35*(1-Gia_dinh!$F$26) | I35: =H35*Gia_dinh!$F$27 | J35: =IF(30>=Gia_dinh!$F$29,Gia_dinh!$F$28*F35,0) | K35: =H35*Gia_dinh!$F$30 | L35: =SUM(I35:K35) | M35: =L35*Gia_dinh!$F$46 | N35: =IF(30=0,0,IF(30<=3,Gia_dinh!$F$44,Gia_dinh!$F$45)) | O35: =IF(30=0,0,Gia_dinh!$F$47) | P35: =IF(30=0,0,Gia_dinh!$F$48) | Q35: =H35*IF(30=0,0,IF(30<=3,Gia_dinh!$F$49,IF(30<=6,Gia_dinh!$F$50,IF(30<=9,Gia_dinh!$F$51,Gia_dinh!$F$52)))) | R35: =IF(30=0,0,Gia_dinh!$F$53) | S35: =IF(30=0,Gia_dinh!$F$33,0) | T35: =SUM(M35:S35) | U35: =L35-T35 | V35: =V34+U35
B36: 31 | C36: Ổn định | D36: =IF(31>Gia_dinh!$F$18,1-Gia_dinh!$F$19,1)*IF(31>Gia_dinh!$F$20,1-Gia_dinh!$F$21,1)*(1-Gia_dinh!$F$107)^MAX(0,31-9) | E36: =IF(31=0,0,IF(31<=3,Gia_dinh!$F$34,IF(31<=6,Gia_dinh!$F$36,IF(31<=9,Gia_dinh!$F$38,Gia_dinh!$F$40)))) | F36: =IF(31=0,0,IF(31<=3,Gia_dinh!$F$35,IF(31<=6,Gia_dinh!$F$37,IF(31<=9,Gia_dinh!$F$39,Gia_dinh!$F$41)))) | G36: =E36*F36 | H36: =G36*(1-Gia_dinh!$F$26) | I36: =H36*Gia_dinh!$F$27 | J36: =IF(31>=Gia_dinh!$F$29,Gia_dinh!$F$28*F36,0) | K36: =H36*Gia_dinh!$F$30 | L36: =SUM(I36:K36) | M36: =L36*Gia_dinh!$F$46 | N36: =IF(31=0,0,IF(31<=3,Gia_dinh!$F$44,Gia_dinh!$F$45)) | O36: =IF(31=0,0,Gia_dinh!$F$47) | P36: =IF(31=0,0,Gia_dinh!$F$48) | Q36: =H36*IF(31=0,0,IF(31<=3,Gia_dinh!$F$49,IF(31<=6,Gia_dinh!$F$50,IF(31<=9,Gia_dinh!$F$51,Gia_dinh!$F$52)))) | R36: =IF(31=0,0,Gia_dinh!$F$53) | S36: =IF(31=0,Gia_dinh!$F$33,0) | T36: =SUM(M36:S36) | U36: =L36-T36 | V36: =V35+U36
B37: 32 | C37: Ổn định | D37: =IF(32>Gia_dinh!$F$18,1-Gia_dinh!$F$19,1)*IF(32>Gia_dinh!$F$20,1-Gia_dinh!$F$21,1)*(1-Gia_dinh!$F$107)^MAX(0,32-9) | E37: =IF(32=0,0,IF(32<=3,Gia_dinh!$F$34,IF(32<=6,Gia_dinh!$F$36,IF(32<=9,Gia_dinh!$F$38,Gia_dinh!$F$40)))) | F37: =IF(32=0,0,IF(32<=3,Gia_dinh!$F$35,IF(32<=6,Gia_dinh!$F$37,IF(32<=9,Gia_dinh!$F$39,Gia_dinh!$F$41)))) | G37: =E37*F37 | H37: =G37*(1-Gia_dinh!$F$26) | I37: =H37*Gia_dinh!$F$27 | J37: =IF(32>=Gia_dinh!$F$29,Gia_dinh!$F$28*F37,0) | K37: =H37*Gia_dinh!$F$30 | L37: =SUM(I37:K37) | M37: =L37*Gia_dinh!$F$46 | N37: =IF(32=0,0,IF(32<=3,Gia_dinh!$F$44,Gia_dinh!$F$45)) | O37: =IF(32=0,0,Gia_dinh!$F$47) | P37: =IF(32=0,0,Gia_dinh!$F$48) | Q37: =H37*IF(32=0,0,IF(32<=3,Gia_dinh!$F$49,IF(32<=6,Gia_dinh!$F$50,IF(32<=9,Gia_dinh!$F$51,Gia_dinh!$F$52)))) | R37: =IF(32=0,0,Gia_dinh!$F$53) | S37: =IF(32=0,Gia_dinh!$F$33,0) | T37: =SUM(M37:S37) | U37: =L37-T37 | V37: =V36+U37
B38: 33 | C38: Ổn định | D38: =IF(33>Gia_dinh!$F$18,1-Gia_dinh!$F$19,1)*IF(33>Gia_dinh!$F$20,1-Gia_dinh!$F$21,1)*(1-Gia_dinh!$F$107)^MAX(0,33-9) | E38: =IF(33=0,0,IF(33<=3,Gia_dinh!$F$34,IF(33<=6,Gia_dinh!$F$36,IF(33<=9,Gia_dinh!$F$38,Gia_dinh!$F$40)))) | F38: =IF(33=0,0,IF(33<=3,Gia_dinh!$F$35,IF(33<=6,Gia_dinh!$F$37,IF(33<=9,Gia_dinh!$F$39,Gia_dinh!$F$41)))) | G38: =E38*F38 | H38: =G38*(1-Gia_dinh!$F$26) | I38: =H38*Gia_dinh!$F$27 | J38: =IF(33>=Gia_dinh!$F$29,Gia_dinh!$F$28*F38,0) | K38: =H38*Gia_dinh!$F$30 | L38: =SUM(I38:K38) | M38: =L38*Gia_dinh!$F$46 | N38: =IF(33=0,0,IF(33<=3,Gia_dinh!$F$44,Gia_dinh!$F$45)) | O38: =IF(33=0,0,Gia_dinh!$F$47) | P38: =IF(33=0,0,Gia_dinh!$F$48) | Q38: =H38*IF(33=0,0,IF(33<=3,Gia_dinh!$F$49,IF(33<=6,Gia_dinh!$F$50,IF(33<=9,Gia_dinh!$F$51,Gia_dinh!$F$52)))) | R38: =IF(33=0,0,Gia_dinh!$F$53) | S38: =IF(33=0,Gia_dinh!$F$33,0) | T38: =SUM(M38:S38) | U38: =L38-T38 | V38: =V37+U38
B39: 34 | C39: Ổn định | D39: =IF(34>Gia_dinh!$F$18,1-Gia_dinh!$F$19,1)*IF(34>Gia_dinh!$F$20,1-Gia_dinh!$F$21,1)*(1-Gia_dinh!$F$107)^MAX(0,34-9) | E39: =IF(34=0,0,IF(34<=3,Gia_dinh!$F$34,IF(34<=6,Gia_dinh!$F$36,IF(34<=9,Gia_dinh!$F$38,Gia_dinh!$F$40)))) | F39: =IF(34=0,0,IF(34<=3,Gia_dinh!$F$35,IF(34<=6,Gia_dinh!$F$37,IF(34<=9,Gia_dinh!$F$39,Gia_dinh!$F$41)))) | G39: =E39*F39 | H39: =G39*(1-Gia_dinh!$F$26) | I39: =H39*Gia_dinh!$F$27 | J39: =IF(34>=Gia_dinh!$F$29,Gia_dinh!$F$28*F39,0) | K39: =H39*Gia_dinh!$F$30 | L39: =SUM(I39:K39) | M39: =L39*Gia_dinh!$F$46 | N39: =IF(34=0,0,IF(34<=3,Gia_dinh!$F$44,Gia_dinh!$F$45)) | O39: =IF(34=0,0,Gia_dinh!$F$47) | P39: =IF(34=0,0,Gia_dinh!$F$48) | Q39: =H39*IF(34=0,0,IF(34<=3,Gia_dinh!$F$49,IF(34<=6,Gia_dinh!$F$50,IF(34<=9,Gia_dinh!$F$51,Gia_dinh!$F$52)))) | R39: =IF(34=0,0,Gia_dinh!$F$53) | S39: =IF(34=0,Gia_dinh!$F$33,0) | T39: =SUM(M39:S39) | U39: =L39-T39 | V39: =V38+U39
B40: 35 | C40: Ổn định | D40: =IF(35>Gia_dinh!$F$18,1-Gia_dinh!$F$19,1)*IF(35>Gia_dinh!$F$20,1-Gia_dinh!$F$21,1)*(1-Gia_dinh!$F$107)^MAX(0,35-9) | E40: =IF(35=0,0,IF(35<=3,Gia_dinh!$F$34,IF(35<=6,Gia_dinh!$F$36,IF(35<=9,Gia_dinh!$F$38,Gia_dinh!$F$40)))) | F40: =IF(35=0,0,IF(35<=3,Gia_dinh!$F$35,IF(35<=6,Gia_dinh!$F$37,IF(35<=9,Gia_dinh!$F$39,Gia_dinh!$F$41)))) | G40: =E40*F40 | H40: =G40*(1-Gia_dinh!$F$26) | I40: =H40*Gia_dinh!$F$27 | J40: =IF(35>=Gia_dinh!$F$29,Gia_dinh!$F$28*F40,0) | K40: =H40*Gia_dinh!$F$30 | L40: =SUM(I40:K40) | M40: =L40*Gia_dinh!$F$46 | N40: =IF(35=0,0,IF(35<=3,Gia_dinh!$F$44,Gia_dinh!$F$45)) | O40: =IF(35=0,0,Gia_dinh!$F$47) | P40: =IF(35=0,0,Gia_dinh!$F$48) | Q40: =H40*IF(35=0,0,IF(35<=3,Gia_dinh!$F$49,IF(35<=6,Gia_dinh!$F$50,IF(35<=9,Gia_dinh!$F$51,Gia_dinh!$F$52)))) | R40: =IF(35=0,0,Gia_dinh!$F$53) | S40: =IF(35=0,Gia_dinh!$F$33,0) | T40: =SUM(M40:S40) | U40: =L40-T40 | V40: =V39+U40
B41: 36 | C41: Ổn định | D41: =IF(36>Gia_dinh!$F$18,1-Gia_dinh!$F$19,1)*IF(36>Gia_dinh!$F$20,1-Gia_dinh!$F$21,1)*(1-Gia_dinh!$F$107)^MAX(0,36-9) | E41: =IF(36=0,0,IF(36<=3,Gia_dinh!$F$34,IF(36<=6,Gia_dinh!$F$36,IF(36<=9,Gia_dinh!$F$38,Gia_dinh!$F$40)))) | F41: =IF(36=0,0,IF(36<=3,Gia_dinh!$F$35,IF(36<=6,Gia_dinh!$F$37,IF(36<=9,Gia_dinh!$F$39,Gia_dinh!$F$41)))) | G41: =E41*F41 | H41: =G41*(1-Gia_dinh!$F$26) | I41: =H41*Gia_dinh!$F$27 | J41: =IF(36>=Gia_dinh!$F$29,Gia_dinh!$F$28*F41,0) | K41: =H41*Gia_dinh!$F$30 | L41: =SUM(I41:K41) | M41: =L41*Gia_dinh!$F$46 | N41: =IF(36=0,0,IF(36<=3,Gia_dinh!$F$44,Gia_dinh!$F$45)) | O41: =IF(36=0,0,Gia_dinh!$F$47) | P41: =IF(36=0,0,Gia_dinh!$F$48) | Q41: =H41*IF(36=0,0,IF(36<=3,Gia_dinh!$F$49,IF(36<=6,Gia_dinh!$F$50,IF(36<=9,Gia_dinh!$F$51,Gia_dinh!$F$52)))) | R41: =IF(36=0,0,Gia_dinh!$F$53) | S41: =IF(36=0,Gia_dinh!$F$33,0) | T41: =SUM(M41:S41) | U41: =L41-T41 | V41: =V40+U41
...

Sheet Don_vi_IP_AI
A1: UNIT ECONOMICS — MỘT IP AI THEO TUỔI (triệu VND)
A2: Tuổi 0 = tháng dựng nhân vật. Bán được từ tuổi > số tháng ramp.
B4: Tuổi (tháng) | C4: Giai đoạn | D4: Tỷ lệ sống sót | E4: GMV/giờ | F4: Số giờ/tháng | G4: GMV gộp | H4: GMV ròng | I4: DOANH THU MCN | J4: License & compute | K4: Vận hành & trực chat | L4: Quảng cáo kéo view | M4: Chi phí khác | N4: Chi phí dựng IP AI | O4: TỔNG CHI PHÍ TRỰC TIẾP | P4: LÃI GỘP | Q4: Lãi gộp luỹ kế / IP
B5: 0 | C5: =IF(0=0,"Dựng IP AI",IF(0<=Gia_dinh!$F$57,"Ramp","Bán hàng")) | D5: 1 | E5: =IF(0<=Gia_dinh!$F$57,0,Gia_dinh!$F$58) | F5: =IF(0<=Gia_dinh!$F$57,0,Gia_dinh!$F$59*Gia_dinh!$F$60) | G5: =E5*F5 | H5: =G5*(1-Gia_dinh!$F$61) | I5: =H5*Gia_dinh!$F$62 | J5: =IF(0=0,0,Gia_dinh!$F$63) | K5: =IF(0=0,0,Gia_dinh!$F$64) | L5: =H5*Gia_dinh!$F$65 | M5: =IF(0=0,0,Gia_dinh!$F$66) | N5: =IF(0=0,Gia_dinh!$F$56,0) | O5: =SUM(J5:N5) | P5: =I5-O5 | Q5: =P5
B6: 1 | C6: =IF(1=0,"Dựng IP AI",IF(1<=Gia_dinh!$F$57,"Ramp","Bán hàng")) | D6: =(1-Gia_dinh!$F$108)^MAX(0,1-Gia_dinh!$F$57-1) | E6: =IF(1<=Gia_dinh!$F$57,0,Gia_dinh!$F$58) | F6: =IF(1<=Gia_dinh!$F$57,0,Gia_dinh!$F$59*Gia_dinh!$F$60) | G6: =E6*F6 | H6: =G6*(1-Gia_dinh!$F$61) | I6: =H6*Gia_dinh!$F$62 | J6: =IF(1=0,0,Gia_dinh!$F$63) | K6: =IF(1=0,0,Gia_dinh!$F$64) | L6: =H6*Gia_dinh!$F$65 | M6: =IF(1=0,0,Gia_dinh!$F$66) | N6: =IF(1=0,Gia_dinh!$F$56,0) | O6: =SUM(J6:N6) | P6: =I6-O6 | Q6: =Q5+P6
B7: 2 | C7: =IF(2=0,"Dựng IP AI",IF(2<=Gia_dinh!$F$57,"Ramp","Bán hàng")) | D7: =(1-Gia_dinh!$F$108)^MAX(0,2-Gia_dinh!$F$57-1) | E7: =IF(2<=Gia_dinh!$F$57,0,Gia_dinh!$F$58) | F7: =IF(2<=Gia_dinh!$F$57,0,Gia_dinh!$F$59*Gia_dinh!$F$60) | G7: =E7*F7 | H7: =G7*(1-Gia_dinh!$F$61) | I7: =H7*Gia_dinh!$F$62 | J7: =IF(2=0,0,Gia_dinh!$F$63) | K7: =IF(2=0,0,Gia_dinh!$F$64) | L7: =H7*Gia_dinh!$F$65 | M7: =IF(2=0,0,Gia_dinh!$F$66) | N7: =IF(2=0,Gia_dinh!$F$56,0) | O7: =SUM(J7:N7) | P7: =I7-O7 | Q7: =Q6+P7
B8: 3 | C8: =IF(3=0,"Dựng IP AI",IF(3<=Gia_dinh!$F$57,"Ramp","Bán hàng")) | D8: =(1-Gia_dinh!$F$108)^MAX(0,3-Gia_dinh!$F$57-1) | E8: =IF(3<=Gia_dinh!$F$57,0,Gia_dinh!$F$58) | F8: =IF(3<=Gia_dinh!$F$57,0,Gia_dinh!$F$59*Gia_dinh!$F$60) | G8: =E8*F8 | H8: =G8*(1-Gia_dinh!$F$61) | I8: =H8*Gia_dinh!$F$62 | J8: =IF(3=0,0,Gia_dinh!$F$63) | K8: =IF(3=0,0,Gia_dinh!$F$64) | L8: =H8*Gia_dinh!$F$65 | M8: =IF(3=0,0,Gia_dinh!$F$66) | N8: =IF(3=0,Gia_dinh!$F$56,0) | O8: =SUM(J8:N8) | P8: =I8-O8 | Q8: =Q7+P8
B9: 4 | C9: =IF(4=0,"Dựng IP AI",IF(4<=Gia_dinh!$F$57,"Ramp","Bán hàng")) | D9: =(1-Gia_dinh!$F$108)^MAX(0,4-Gia_dinh!$F$57-1) | E9: =IF(4<=Gia_dinh!$F$57,0,Gia_dinh!$F$58) | F9: =IF(4<=Gia_dinh!$F$57,0,Gia_dinh!$F$59*Gia_dinh!$F$60) | G9: =E9*F9 | H9: =G9*(1-Gia_dinh!$F$61) | I9: =H9*Gia_dinh!$F$62 | J9: =IF(4=0,0,Gia_dinh!$F$63) | K9: =IF(4=0,0,Gia_dinh!$F$64) | L9: =H9*Gia_dinh!$F$65 | M9: =IF(4=0,0,Gia_dinh!$F$66) | N9: =IF(4=0,Gia_dinh!$F$56,0) | O9: =SUM(J9:N9) | P9: =I9-O9 | Q9: =Q8+P9
B10: 5 | C10: =IF(5=0,"Dựng IP AI",IF(5<=Gia_dinh!$F$57,"Ramp","Bán hàng")) | D10: =(1-Gia_dinh!$F$108)^MAX(0,5-Gia_dinh!$F$57-1) | E10: =IF(5<=Gia_dinh!$F$57,0,Gia_dinh!$F$58) | F10: =IF(5<=Gia_dinh!$F$57,0,Gia_dinh!$F$59*Gia_dinh!$F$60) | G10: =E10*F10 | H10: =G10*(1-Gia_dinh!$F$61) | I10: =H10*Gia_dinh!$F$62 | J10: =IF(5=0,0,Gia_dinh!$F$63) | K10: =IF(5=0,0,Gia_dinh!$F$64) | L10: =H10*Gia_dinh!$F$65 | M10: =IF(5=0,0,Gia_dinh!$F$66) | N10: =IF(5=0,Gia_dinh!$F$56,0) | O10: =SUM(J10:N10) | P10: =I10-O10 | Q10: =Q9+P10
B11: 6 | C11: =IF(6=0,"Dựng IP AI",IF(6<=Gia_dinh!$F$57,"Ramp","Bán hàng")) | D11: =(1-Gia_dinh!$F$108)^MAX(0,6-Gia_dinh!$F$57-1) | E11: =IF(6<=Gia_dinh!$F$57,0,Gia_dinh!$F$58) | F11: =IF(6<=Gia_dinh!$F$57,0,Gia_dinh!$F$59*Gia_dinh!$F$60) | G11: =E11*F11 | H11: =G11*(1-Gia_dinh!$F$61) | I11: =H11*Gia_dinh!$F$62 | J11: =IF(6=0,0,Gia_dinh!$F$63) | K11: =IF(6=0,0,Gia_dinh!$F$64) | L11: =H11*Gia_dinh!$F$65 | M11: =IF(6=0,0,Gia_dinh!$F$66) | N11: =IF(6=0,Gia_dinh!$F$56,0) | O11: =SUM(J11:N11) | P11: =I11-O11 | Q11: =Q10+P11
B12: 7 | C12: =IF(7=0,"Dựng IP AI",IF(7<=Gia_dinh!$F$57,"Ramp","Bán hàng")) | D12: =(1-Gia_dinh!$F$108)^MAX(0,7-Gia_dinh!$F$57-1) | E12: =IF(7<=Gia_dinh!$F$57,0,Gia_dinh!$F$58) | F12: =IF(7<=Gia_dinh!$F$57,0,Gia_dinh!$F$59*Gia_dinh!$F$60) | G12: =E12*F12 | H12: =G12*(1-Gia_dinh!$F$61) | I12: =H12*Gia_dinh!$F$62 | J12: =IF(7=0,0,Gia_dinh!$F$63) | K12: =IF(7=0,0,Gia_dinh!$F$64) | L12: =H12*Gia_dinh!$F$65 | M12: =IF(7=0,0,Gia_dinh!$F$66) | N12: =IF(7=0,Gia_dinh!$F$56,0) | O12: =SUM(J12:N12) | P12: =I12-O12 | Q12: =Q11+P12
B13: 8 | C13: =IF(8=0,"Dựng IP AI",IF(8<=Gia_dinh!$F$57,"Ramp","Bán hàng")) | D13: =(1-Gia_dinh!$F$108)^MAX(0,8-Gia_dinh!$F$57-1) | E13: =IF(8<=Gia_dinh!$F$57,0,Gia_dinh!$F$58) | F13: =IF(8<=Gia_dinh!$F$57,0,Gia_dinh!$F$59*Gia_dinh!$F$60) | G13: =E13*F13 | H13: =G13*(1-Gia_dinh!$F$61) | I13: =H13*Gia_dinh!$F$62 | J13: =IF(8=0,0,Gia_dinh!$F$63) | K13: =IF(8=0,0,Gia_dinh!$F$64) | L13: =H13*Gia_dinh!$F$65 | M13: =IF(8=0,0,Gia_dinh!$F$66) | N13: =IF(8=0,Gia_dinh!$F$56,0) | O13: =SUM(J13:N13) | P13: =I13-O13 | Q13: =Q12+P13
B14: 9 | C14: =IF(9=0,"Dựng IP AI",IF(9<=Gia_dinh!$F$57,"Ramp","Bán hàng")) | D14: =(1-Gia_dinh!$F$108)^MAX(0,9-Gia_dinh!$F$57-1) | E14: =IF(9<=Gia_dinh!$F$57,0,Gia_dinh!$F$58) | F14: =IF(9<=Gia_dinh!$F$57,0,Gia_dinh!$F$59*Gia_dinh!$F$60) | G14: =E14*F14 | H14: =G14*(1-Gia_dinh!$F$61) | I14: =H14*Gia_dinh!$F$62 | J14: =IF(9=0,0,Gia_dinh!$F$63) | K14: =IF(9=0,0,Gia_dinh!$F$64) | L14: =H14*Gia_dinh!$F$65 | M14: =IF(9=0,0,Gia_dinh!$F$66) | N14: =IF(9=0,Gia_dinh!$F$56,0) | O14: =SUM(J14:N14) | P14: =I14-O14 | Q14: =Q13+P14
B15: 10 | C15: =IF(10=0,"Dựng IP AI",IF(10<=Gia_dinh!$F$57,"Ramp","Bán hàng")) | D15: =(1-Gia_dinh!$F$108)^MAX(0,10-Gia_dinh!$F$57-1) | E15: =IF(10<=Gia_dinh!$F$57,0,Gia_dinh!$F$58) | F15: =IF(10<=Gia_dinh!$F$57,0,Gia_dinh!$F$59*Gia_dinh!$F$60) | G15: =E15*F15 | H15: =G15*(1-Gia_dinh!$F$61) | I15: =H15*Gia_dinh!$F$62 | J15: =IF(10=0,0,Gia_dinh!$F$63) | K15: =IF(10=0,0,Gia_dinh!$F$64) | L15: =H15*Gia_dinh!$F$65 | M15: =IF(10=0,0,Gia_dinh!$F$66) | N15: =IF(10=0,Gia_dinh!$F$56,0) | O15: =SUM(J15:N15) | P15: =I15-O15 | Q15: =Q14+P15
B16: 11 | C16: =IF(11=0,"Dựng IP AI",IF(11<=Gia_dinh!$F$57,"Ramp","Bán hàng")) | D16: =(1-Gia_dinh!$F$108)^MAX(0,11-Gia_dinh!$F$57-1) | E16: =IF(11<=Gia_dinh!$F$57,0,Gia_dinh!$F$58) | F16: =IF(11<=Gia_dinh!$F$57,0,Gia_dinh!$F$59*Gia_dinh!$F$60) | G16: =E16*F16 | H16: =G16*(1-Gia_dinh!$F$61) | I16: =H16*Gia_dinh!$F$62 | J16: =IF(11=0,0,Gia_dinh!$F$63) | K16: =IF(11=0,0,Gia_dinh!$F$64) | L16: =H16*Gia_dinh!$F$65 | M16: =IF(11=0,0,Gia_dinh!$F$66) | N16: =IF(11=0,Gia_dinh!$F$56,0) | O16: =SUM(J16:N16) | P16: =I16-O16 | Q16: =Q15+P16
B17: 12 | C17: =IF(12=0,"Dựng IP AI",IF(12<=Gia_dinh!$F$57,"Ramp","Bán hàng")) | D17: =(1-Gia_dinh!$F$108)^MAX(0,12-Gia_dinh!$F$57-1) | E17: =IF(12<=Gia_dinh!$F$57,0,Gia_dinh!$F$58) | F17: =IF(12<=Gia_dinh!$F$57,0,Gia_dinh!$F$59*Gia_dinh!$F$60) | G17: =E17*F17 | H17: =G17*(1-Gia_dinh!$F$61) | I17: =H17*Gia_dinh!$F$62 | J17: =IF(12=0,0,Gia_dinh!$F$63) | K17: =IF(12=0,0,Gia_dinh!$F$64) | L17: =H17*Gia_dinh!$F$65 | M17: =IF(12=0,0,Gia_dinh!$F$66) | N17: =IF(12=0,Gia_dinh!$F$56,0) | O17: =SUM(J17:N17) | P17: =I17-O17 | Q17: =Q16+P17
B18: 13 | C18: =IF(13=0,"Dựng IP AI",IF(13<=Gia_dinh!$F$57,"Ramp","Bán hàng")) | D18: =(1-Gia_dinh!$F$108)^MAX(0,13-Gia_dinh!$F$57-1) | E18: =IF(13<=Gia_dinh!$F$57,0,Gia_dinh!$F$58) | F18: =IF(13<=Gia_dinh!$F$57,0,Gia_dinh!$F$59*Gia_dinh!$F$60) | G18: =E18*F18 | H18: =G18*(1-Gia_dinh!$F$61) | I18: =H18*Gia_dinh!$F$62 | J18: =IF(13=0,0,Gia_dinh!$F$63) | K18: =IF(13=0,0,Gia_dinh!$F$64) | L18: =H18*Gia_dinh!$F$65 | M18: =IF(13=0,0,Gia_dinh!$F$66) | N18: =IF(13=0,Gia_dinh!$F$56,0) | O18: =SUM(J18:N18) | P18: =I18-O18 | Q18: =Q17+P18
B19: 14 | C19: =IF(14=0,"Dựng IP AI",IF(14<=Gia_dinh!$F$57,"Ramp","Bán hàng")) | D19: =(1-Gia_dinh!$F$108)^MAX(0,14-Gia_dinh!$F$57-1) | E19: =IF(14<=Gia_dinh!$F$57,0,Gia_dinh!$F$58) | F19: =IF(14<=Gia_dinh!$F$57,0,Gia_dinh!$F$59*Gia_dinh!$F$60) | G19: =E19*F19 | H19: =G19*(1-Gia_dinh!$F$61) | I19: =H19*Gia_dinh!$F$62 | J19: =IF(14=0,0,Gia_dinh!$F$63) | K19: =IF(14=0,0,Gia_dinh!$F$64) | L19: =H19*Gia_dinh!$F$65 | M19: =IF(14=0,0,Gia_dinh!$F$66) | N19: =IF(14=0,Gia_dinh!$F$56,0) | O19: =SUM(J19:N19) | P19: =I19-O19 | Q19: =Q18+P19
B20: 15 | C20: =IF(15=0,"Dựng IP AI",IF(15<=Gia_dinh!$F$57,"Ramp","Bán hàng")) | D20: =(1-Gia_dinh!$F$108)^MAX(0,15-Gia_dinh!$F$57-1) | E20: =IF(15<=Gia_dinh!$F$57,0,Gia_dinh!$F$58) | F20: =IF(15<=Gia_dinh!$F$57,0,Gia_dinh!$F$59*Gia_dinh!$F$60) | G20: =E20*F20 | H20: =G20*(1-Gia_dinh!$F$61) | I20: =H20*Gia_dinh!$F$62 | J20: =IF(15=0,0,Gia_dinh!$F$63) | K20: =IF(15=0,0,Gia_dinh!$F$64) | L20: =H20*Gia_dinh!$F$65 | M20: =IF(15=0,0,Gia_dinh!$F$66) | N20: =IF(15=0,Gia_dinh!$F$56,0) | O20: =SUM(J20:N20) | P20: =I20-O20 | Q20: =Q19+P20
B21: 16 | C21: =IF(16=0,"Dựng IP AI",IF(16<=Gia_dinh!$F$57,"Ramp","Bán hàng")) | D21: =(1-Gia_dinh!$F$108)^MAX(0,16-Gia_dinh!$F$57-1) | E21: =IF(16<=Gia_dinh!$F$57,0,Gia_dinh!$F$58) | F21: =IF(16<=Gia_dinh!$F$57,0,Gia_dinh!$F$59*Gia_dinh!$F$60) | G21: =E21*F21 | H21: =G21*(1-Gia_dinh!$F$61) | I21: =H21*Gia_dinh!$F$62 | J21: =IF(16=0,0,Gia_dinh!$F$63) | K21: =IF(16=0,0,Gia_dinh!$F$64) | L21: =H21*Gia_dinh!$F$65 | M21: =IF(16=0,0,Gia_dinh!$F$66) | N21: =IF(16=0,Gia_dinh!$F$56,0) | O21: =SUM(J21:N21) | P21: =I21-O21 | Q21: =Q20+P21
B22: 17 | C22: =IF(17=0,"Dựng IP AI",IF(17<=Gia_dinh!$F$57,"Ramp","Bán hàng")) | D22: =(1-Gia_dinh!$F$108)^MAX(0,17-Gia_dinh!$F$57-1) | E22: =IF(17<=Gia_dinh!$F$57,0,Gia_dinh!$F$58) | F22: =IF(17<=Gia_dinh!$F$57,0,Gia_dinh!$F$59*Gia_dinh!$F$60) | G22: =E22*F22 | H22: =G22*(1-Gia_dinh!$F$61) | I22: =H22*Gia_dinh!$F$62 | J22: =IF(17=0,0,Gia_dinh!$F$63) | K22: =IF(17=0,0,Gia_dinh!$F$64) | L22: =H22*Gia_dinh!$F$65 | M22: =IF(17=0,0,Gia_dinh!$F$66) | N22: =IF(17=0,Gia_dinh!$F$56,0) | O22: =SUM(J22:N22) | P22: =I22-O22 | Q22: =Q21+P22
B23: 18 | C23: =IF(18=0,"Dựng IP AI",IF(18<=Gia_dinh!$F$57,"Ramp","Bán hàng")) | D23: =(1-Gia_dinh!$F$108)^MAX(0,18-Gia_dinh!$F$57-1) | E23: =IF(18<=Gia_dinh!$F$57,0,Gia_dinh!$F$58) | F23: =IF(18<=Gia_dinh!$F$57,0,Gia_dinh!$F$59*Gia_dinh!$F$60) | G23: =E23*F23 | H23: =G23*(1-Gia_dinh!$F$61) | I23: =H23*Gia_dinh!$F$62 | J23: =IF(18=0,0,Gia_dinh!$F$63) | K23: =IF(18=0,0,Gia_dinh!$F$64) | L23: =H23*Gia_dinh!$F$65 | M23: =IF(18=0,0,Gia_dinh!$F$66) | N23: =IF(18=0,Gia_dinh!$F$56,0) | O23: =SUM(J23:N23) | P23: =I23-O23 | Q23: =Q22+P23
B24: 19 | C24: =IF(19=0,"Dựng IP AI",IF(19<=Gia_dinh!$F$57,"Ramp","Bán hàng")) | D24: =(1-Gia_dinh!$F$108)^MAX(0,19-Gia_dinh!$F$57-1) | E24: =IF(19<=Gia_dinh!$F$57,0,Gia_dinh!$F$58) | F24: =IF(19<=Gia_dinh!$F$57,0,Gia_dinh!$F$59*Gia_dinh!$F$60) | G24: =E24*F24 | H24: =G24*(1-Gia_dinh!$F$61) | I24: =H24*Gia_dinh!$F$62 | J24: =IF(19=0,0,Gia_dinh!$F$63) | K24: =IF(19=0,0,Gia_dinh!$F$64) | L24: =H24*Gia_dinh!$F$65 | M24: =IF(19=0,0,Gia_dinh!$F$66) | N24: =IF(19=0,Gia_dinh!$F$56,0) | O24: =SUM(J24:N24) | P24: =I24-O24 | Q24: =Q23+P24
B25: 20 | C25: =IF(20=0,"Dựng IP AI",IF(20<=Gia_dinh!$F$57,"Ramp","Bán hàng")) | D25: =(1-Gia_dinh!$F$108)^MAX(0,20-Gia_dinh!$F$57-1) | E25: =IF(20<=Gia_dinh!$F$57,0,Gia_dinh!$F$58) | F25: =IF(20<=Gia_dinh!$F$57,0,Gia_dinh!$F$59*Gia_dinh!$F$60) | G25: =E25*F25 | H25: =G25*(1-Gia_dinh!$F$61) | I25: =H25*Gia_dinh!$F$62 | J25: =IF(20=0,0,Gia_dinh!$F$63) | K25: =IF(20=0,0,Gia_dinh!$F$64) | L25: =H25*Gia_dinh!$F$65 | M25: =IF(20=0,0,Gia_dinh!$F$66) | N25: =IF(20=0,Gia_dinh!$F$56,0) | O25: =SUM(J25:N25) | P25: =I25-O25 | Q25: =Q24+P25
B26: 21 | C26: =IF(21=0,"Dựng IP AI",IF(21<=Gia_dinh!$F$57,"Ramp","Bán hàng")) | D26: =(1-Gia_dinh!$F$108)^MAX(0,21-Gia_dinh!$F$57-1) | E26: =IF(21<=Gia_dinh!$F$57,0,Gia_dinh!$F$58) | F26: =IF(21<=Gia_dinh!$F$57,0,Gia_dinh!$F$59*Gia_dinh!$F$60) | G26: =E26*F26 | H26: =G26*(1-Gia_dinh!$F$61) | I26: =H26*Gia_dinh!$F$62 | J26: =IF(21=0,0,Gia_dinh!$F$63) | K26: =IF(21=0,0,Gia_dinh!$F$64) | L26: =H26*Gia_dinh!$F$65 | M26: =IF(21=0,0,Gia_dinh!$F$66) | N26: =IF(21=0,Gia_dinh!$F$56,0) | O26: =SUM(J26:N26) | P26: =I26-O26 | Q26: =Q25+P26
B27: 22 | C27: =IF(22=0,"Dựng IP AI",IF(22<=Gia_dinh!$F$57,"Ramp","Bán hàng")) | D27: =(1-Gia_dinh!$F$108)^MAX(0,22-Gia_dinh!$F$57-1) | E27: =IF(22<=Gia_dinh!$F$57,0,Gia_dinh!$F$58) | F27: =IF(22<=Gia_dinh!$F$57,0,Gia_dinh!$F$59*Gia_dinh!$F$60) | G27: =E27*F27 | H27: =G27*(1-Gia_dinh!$F$61) | I27: =H27*Gia_dinh!$F$62 | J27: =IF(22=0,0,Gia_dinh!$F$63) | K27: =IF(22=0,0,Gia_dinh!$F$64) | L27: =H27*Gia_dinh!$F$65 | M27: =IF(22=0,0,Gia_dinh!$F$66) | N27: =IF(22=0,Gia_dinh!$F$56,0) | O27: =SUM(J27:N27) | P27: =I27-O27 | Q27: =Q26+P27
B28: 23 | C28: =IF(23=0,"Dựng IP AI",IF(23<=Gia_dinh!$F$57,"Ramp","Bán hàng")) | D28: =(1-Gia_dinh!$F$108)^MAX(0,23-Gia_dinh!$F$57-1) | E28: =IF(23<=Gia_dinh!$F$57,0,Gia_dinh!$F$58) | F28: =IF(23<=Gia_dinh!$F$57,0,Gia_dinh!$F$59*Gia_dinh!$F$60) | G28: =E28*F28 | H28: =G28*(1-Gia_dinh!$F$61) | I28: =H28*Gia_dinh!$F$62 | J28: =IF(23=0,0,Gia_dinh!$F$63) | K28: =IF(23=0,0,Gia_dinh!$F$64) | L28: =H28*Gia_dinh!$F$65 | M28: =IF(23=0,0,Gia_dinh!$F$66) | N28: =IF(23=0,Gia_dinh!$F$56,0) | O28: =SUM(J28:N28) | P28: =I28-O28 | Q28: =Q27+P28
B29: 24 | C29: =IF(24=0,"Dựng IP AI",IF(24<=Gia_dinh!$F$57,"Ramp","Bán hàng")) | D29: =(1-Gia_dinh!$F$108)^MAX(0,24-Gia_dinh!$F$57-1) | E29: =IF(24<=Gia_dinh!$F$57,0,Gia_dinh!$F$58) | F29: =IF(24<=Gia_dinh!$F$57,0,Gia_dinh!$F$59*Gia_dinh!$F$60) | G29: =E29*F29 | H29: =G29*(1-Gia_dinh!$F$61) | I29: =H29*Gia_dinh!$F$62 | J29: =IF(24=0,0,Gia_dinh!$F$63) | K29: =IF(24=0,0,Gia_dinh!$F$64) | L29: =H29*Gia_dinh!$F$65 | M29: =IF(24=0,0,Gia_dinh!$F$66) | N29: =IF(24=0,Gia_dinh!$F$56,0) | O29: =SUM(J29:N29) | P29: =I29-O29 | Q29: =Q28+P29
